2025-05-25 22:36:06,551 - root - ERROR - Критична помилка при експорті: cannot reindex on an axis with duplicate labels
Traceback (most recent call last):
  File "D:\Programming\Python\Supp0rtBot\TgBot3.py", line 253, in export_to_excel
    users_df = all_users_df[all_users_df["mute/ban"] == False].copy()
               ~~~~~~~~~~~~^^^^^^^^^^^^^^^^^^^^^^^^^^^^^^^^^^^
  File "D:\Programming\Python\Supp0rtBot\.venv\Lib\site-packages\pandas\core\frame.py", line 4089, in __getitem__
    return self.where(key)
           ^^^^^^^^^^^^^^^
  File "D:\Programming\Python\Supp0rtBot\.venv\Lib\site-packages\pandas\core\generic.py", line 10984, in where
    return self._where(cond, other, inplace, axis, level)
           ^^^^^^^^^^^^^^^^^^^^^^^^^^^^^^^^^^^^^^^^^^^^^^
  File "D:\Programming\Python\Supp0rtBot\.venv\Lib\site-packages\pandas\core\generic.py", line 10685, in _where
    cond = cond.reindex(self._info_axis, axis=self._info_axis_number, copy=False)
           ^^^^^^^^^^^^^^^^^^^^^^^^^^^^^^^^^^^^^^^^^^^^^^^^^^^^^^^^^^^^^^^^^^^^^^
  File "D:\Programming\Python\Supp0rtBot\.venv\Lib\site-packages\pandas\core\frame.py", line 5378, in reindex
    return super().reindex(
           ^^^^^^^^^^^^^^^^
  File "D:\Programming\Python\Supp0rtBot\.venv\Lib\site-packages\pandas\core\generic.py", line 5610, in reindex
    return self._reindex_axes(
           ^^^^^^^^^^^^^^^^^^^
  File "D:\Programming\Python\Supp0rtBot\.venv\Lib\site-packages\pandas\core\generic.py", line 5633, in _reindex_axes
    new_index, indexer = ax.reindex(
                         ^^^^^^^^^^^
  File "D:\Programming\Python\Supp0rtBot\.venv\Lib\site-packages\pandas\core\indexes\base.py", line 4429, in reindex
    raise ValueError("cannot reindex on an axis with duplicate labels")
ValueError: cannot reindex on an axis with duplicate labels
2025-07-03 18:55:18,290 - werkzeug - INFO - [31m[1mWARNING: This is a development server. Do not use it in a production deployment. Use a production WSGI server instead.[0m
 * Running on all addresses (0.0.0.0)
 * Running on http://127.0.0.1:5000
 * Running on http://192.168.31.105:5000
2025-07-03 18:55:18,292 - werkzeug - INFO - [33mPress CTRL+C to quit[0m
2025-07-03 18:55:18,309 - werkzeug - INFO - [31m[1mWARNING: This is a development server. Do not use it in a production deployment. Use a production WSGI server instead.[0m
 * Running on all addresses (0.0.0.0)
 * Running on http://127.0.0.1:5000
 * Running on http://192.168.31.105:5000
2025-07-03 18:55:18,310 - werkzeug - INFO - [33mPress CTRL+C to quit[0m
2025-07-03 18:55:24,643 - telegram.ext.Application - ERROR - No error handlers are registered, logging exception.
Traceback (most recent call last):
  File "D:\Programming\Python\Supp0rtBot\.venv\Lib\site-packages\telegram\ext\_updater.py", line 750, in _network_loop_retry
    if not await do_action():
           ^^^^^^^^^^^^^^^^^
  File "D:\Programming\Python\Supp0rtBot\.venv\Lib\site-packages\telegram\ext\_updater.py", line 744, in do_action
    return action_cb_task.result()
           ^^^^^^^^^^^^^^^^^^^^^^^
  File "C:\Users\38066\AppData\Local\Programs\Python\Python312\Lib\asyncio\futures.py", line 203, in result
    raise self._exception.with_traceback(self._exception_tb)
  File "C:\Users\38066\AppData\Local\Programs\Python\Python312\Lib\asyncio\tasks.py", line 314, in __step_run_and_handle_result
    result = coro.send(None)
             ^^^^^^^^^^^^^^^
  File "D:\Programming\Python\Supp0rtBot\.venv\Lib\site-packages\telegram\ext\_updater.py", line 371, in polling_action_cb
    updates = await self.bot.get_updates(
              ^^^^^^^^^^^^^^^^^^^^^^^^^^^
  File "D:\Programming\Python\Supp0rtBot\.venv\Lib\site-packages\telegram\ext\_extbot.py", line 650, in get_updates
    updates = await super().get_updates(
              ^^^^^^^^^^^^^^^^^^^^^^^^^^
  File "D:\Programming\Python\Supp0rtBot\.venv\Lib\site-packages\telegram\_bot.py", line 4480, in get_updates
    await self._post(
  File "D:\Programming\Python\Supp0rtBot\.venv\Lib\site-packages\telegram\_bot.py", line 619, in _post
    return await self._do_post(
           ^^^^^^^^^^^^^^^^^^^^
  File "D:\Programming\Python\Supp0rtBot\.venv\Lib\site-packages\telegram\ext\_extbot.py", line 354, in _do_post
    return await super()._do_post(
           ^^^^^^^^^^^^^^^^^^^^^^^
  File "D:\Programming\Python\Supp0rtBot\.venv\Lib\site-packages\telegram\_bot.py", line 648, in _do_post
    result = await request.post(
             ^^^^^^^^^^^^^^^^^^^
  File "D:\Programming\Python\Supp0rtBot\.venv\Lib\site-packages\telegram\request\_baserequest.py", line 202, in post
    result = await self._request_wrapper(
             ^^^^^^^^^^^^^^^^^^^^^^^^^^^^
  File "D:\Programming\Python\Supp0rtBot\.venv\Lib\site-packages\telegram\request\_baserequest.py", line 385, in _request_wrapper
    raise Conflict(message)
telegram.error.Conflict: Conflict: terminated by other getUpdates request; make sure that only one bot instance is running
2025-07-03 18:55:28,704 - telegram.ext.Application - ERROR - No error handlers are registered, logging exception.
Traceback (most recent call last):
  File "D:\Programming\Python\Supp0rtBot\.venv\Lib\site-packages\telegram\ext\_updater.py", line 750, in _network_loop_retry
    if not await do_action():
           ^^^^^^^^^^^^^^^^^
  File "D:\Programming\Python\Supp0rtBot\.venv\Lib\site-packages\telegram\ext\_updater.py", line 744, in do_action
    return action_cb_task.result()
           ^^^^^^^^^^^^^^^^^^^^^^^
  File "C:\Users\38066\AppData\Local\Programs\Python\Python312\Lib\asyncio\futures.py", line 203, in result
    raise self._exception.with_traceback(self._exception_tb)
  File "C:\Users\38066\AppData\Local\Programs\Python\Python312\Lib\asyncio\tasks.py", line 314, in __step_run_and_handle_result
    result = coro.send(None)
             ^^^^^^^^^^^^^^^
  File "D:\Programming\Python\Supp0rtBot\.venv\Lib\site-packages\telegram\ext\_updater.py", line 371, in polling_action_cb
    updates = await self.bot.get_updates(
              ^^^^^^^^^^^^^^^^^^^^^^^^^^^
  File "D:\Programming\Python\Supp0rtBot\.venv\Lib\site-packages\telegram\ext\_extbot.py", line 650, in get_updates
    updates = await super().get_updates(
              ^^^^^^^^^^^^^^^^^^^^^^^^^^
  File "D:\Programming\Python\Supp0rtBot\.venv\Lib\site-packages\telegram\_bot.py", line 4480, in get_updates
    await self._post(
  File "D:\Programming\Python\Supp0rtBot\.venv\Lib\site-packages\telegram\_bot.py", line 619, in _post
    return await self._do_post(
           ^^^^^^^^^^^^^^^^^^^^
  File "D:\Programming\Python\Supp0rtBot\.venv\Lib\site-packages\telegram\ext\_extbot.py", line 354, in _do_post
    return await super()._do_post(
           ^^^^^^^^^^^^^^^^^^^^^^^
  File "D:\Programming\Python\Supp0rtBot\.venv\Lib\site-packages\telegram\_bot.py", line 648, in _do_post
    result = await request.post(
             ^^^^^^^^^^^^^^^^^^^
  File "D:\Programming\Python\Supp0rtBot\.venv\Lib\site-packages\telegram\request\_baserequest.py", line 202, in post
    result = await self._request_wrapper(
             ^^^^^^^^^^^^^^^^^^^^^^^^^^^^
  File "D:\Programming\Python\Supp0rtBot\.venv\Lib\site-packages\telegram\request\_baserequest.py", line 385, in _request_wrapper
    raise Conflict(message)
telegram.error.Conflict: Conflict: terminated by other getUpdates request; make sure that only one bot instance is running
2025-07-03 18:55:29,761 - telegram.ext.Application - ERROR - No error handlers are registered, logging exception.
Traceback (most recent call last):
  File "D:\Programming\Python\Supp0rtBot\.venv\Lib\site-packages\telegram\ext\_updater.py", line 750, in _network_loop_retry
    if not await do_action():
           ^^^^^^^^^^^^^^^^^
  File "D:\Programming\Python\Supp0rtBot\.venv\Lib\site-packages\telegram\ext\_updater.py", line 744, in do_action
    return action_cb_task.result()
           ^^^^^^^^^^^^^^^^^^^^^^^
  File "C:\Users\38066\AppData\Local\Programs\Python\Python312\Lib\asyncio\futures.py", line 203, in result
    raise self._exception.with_traceback(self._exception_tb)
  File "C:\Users\38066\AppData\Local\Programs\Python\Python312\Lib\asyncio\tasks.py", line 314, in __step_run_and_handle_result
    result = coro.send(None)
             ^^^^^^^^^^^^^^^
  File "D:\Programming\Python\Supp0rtBot\.venv\Lib\site-packages\telegram\ext\_updater.py", line 371, in polling_action_cb
    updates = await self.bot.get_updates(
              ^^^^^^^^^^^^^^^^^^^^^^^^^^^
  File "D:\Programming\Python\Supp0rtBot\.venv\Lib\site-packages\telegram\ext\_extbot.py", line 650, in get_updates
    updates = await super().get_updates(
              ^^^^^^^^^^^^^^^^^^^^^^^^^^
  File "D:\Programming\Python\Supp0rtBot\.venv\Lib\site-packages\telegram\_bot.py", line 4480, in get_updates
    await self._post(
  File "D:\Programming\Python\Supp0rtBot\.venv\Lib\site-packages\telegram\_bot.py", line 619, in _post
    return await self._do_post(
           ^^^^^^^^^^^^^^^^^^^^
  File "D:\Programming\Python\Supp0rtBot\.venv\Lib\site-packages\telegram\ext\_extbot.py", line 354, in _do_post
    return await super()._do_post(
           ^^^^^^^^^^^^^^^^^^^^^^^
  File "D:\Programming\Python\Supp0rtBot\.venv\Lib\site-packages\telegram\_bot.py", line 648, in _do_post
    result = await request.post(
             ^^^^^^^^^^^^^^^^^^^
  File "D:\Programming\Python\Supp0rtBot\.venv\Lib\site-packages\telegram\request\_baserequest.py", line 202, in post
    result = await self._request_wrapper(
             ^^^^^^^^^^^^^^^^^^^^^^^^^^^^
  File "D:\Programming\Python\Supp0rtBot\.venv\Lib\site-packages\telegram\request\_baserequest.py", line 385, in _request_wrapper
    raise Conflict(message)
telegram.error.Conflict: Conflict: terminated by other getUpdates request; make sure that only one bot instance is running
2025-07-03 18:55:34,315 - telegram.ext.Application - ERROR - No error handlers are registered, logging exception.
Traceback (most recent call last):
  File "D:\Programming\Python\Supp0rtBot\.venv\Lib\site-packages\telegram\ext\_updater.py", line 750, in _network_loop_retry
    if not await do_action():
           ^^^^^^^^^^^^^^^^^
  File "D:\Programming\Python\Supp0rtBot\.venv\Lib\site-packages\telegram\ext\_updater.py", line 744, in do_action
    return action_cb_task.result()
           ^^^^^^^^^^^^^^^^^^^^^^^
  File "C:\Users\38066\AppData\Local\Programs\Python\Python312\Lib\asyncio\futures.py", line 203, in result
    raise self._exception.with_traceback(self._exception_tb)
  File "C:\Users\38066\AppData\Local\Programs\Python\Python312\Lib\asyncio\tasks.py", line 314, in __step_run_and_handle_result
    result = coro.send(None)
             ^^^^^^^^^^^^^^^
  File "D:\Programming\Python\Supp0rtBot\.venv\Lib\site-packages\telegram\ext\_updater.py", line 371, in polling_action_cb
    updates = await self.bot.get_updates(
              ^^^^^^^^^^^^^^^^^^^^^^^^^^^
  File "D:\Programming\Python\Supp0rtBot\.venv\Lib\site-packages\telegram\ext\_extbot.py", line 650, in get_updates
    updates = await super().get_updates(
              ^^^^^^^^^^^^^^^^^^^^^^^^^^
  File "D:\Programming\Python\Supp0rtBot\.venv\Lib\site-packages\telegram\_bot.py", line 4480, in get_updates
    await self._post(
  File "D:\Programming\Python\Supp0rtBot\.venv\Lib\site-packages\telegram\_bot.py", line 619, in _post
    return await self._do_post(
           ^^^^^^^^^^^^^^^^^^^^
  File "D:\Programming\Python\Supp0rtBot\.venv\Lib\site-packages\telegram\ext\_extbot.py", line 354, in _do_post
    return await super()._do_post(
           ^^^^^^^^^^^^^^^^^^^^^^^
  File "D:\Programming\Python\Supp0rtBot\.venv\Lib\site-packages\telegram\_bot.py", line 648, in _do_post
    result = await request.post(
             ^^^^^^^^^^^^^^^^^^^
  File "D:\Programming\Python\Supp0rtBot\.venv\Lib\site-packages\telegram\request\_baserequest.py", line 202, in post
    result = await self._request_wrapper(
             ^^^^^^^^^^^^^^^^^^^^^^^^^^^^
  File "D:\Programming\Python\Supp0rtBot\.venv\Lib\site-packages\telegram\request\_baserequest.py", line 385, in _request_wrapper
    raise Conflict(message)
telegram.error.Conflict: Conflict: terminated by other getUpdates request; make sure that only one bot instance is running
2025-07-03 18:55:35,882 - telegram.ext.Application - ERROR - No error handlers are registered, logging exception.
Traceback (most recent call last):
  File "D:\Programming\Python\Supp0rtBot\.venv\Lib\site-packages\telegram\ext\_updater.py", line 750, in _network_loop_retry
    if not await do_action():
           ^^^^^^^^^^^^^^^^^
  File "D:\Programming\Python\Supp0rtBot\.venv\Lib\site-packages\telegram\ext\_updater.py", line 744, in do_action
    return action_cb_task.result()
           ^^^^^^^^^^^^^^^^^^^^^^^
  File "C:\Users\38066\AppData\Local\Programs\Python\Python312\Lib\asyncio\futures.py", line 203, in result
    raise self._exception.with_traceback(self._exception_tb)
  File "C:\Users\38066\AppData\Local\Programs\Python\Python312\Lib\asyncio\tasks.py", line 314, in __step_run_and_handle_result
    result = coro.send(None)
             ^^^^^^^^^^^^^^^
  File "D:\Programming\Python\Supp0rtBot\.venv\Lib\site-packages\telegram\ext\_updater.py", line 371, in polling_action_cb
    updates = await self.bot.get_updates(
              ^^^^^^^^^^^^^^^^^^^^^^^^^^^
  File "D:\Programming\Python\Supp0rtBot\.venv\Lib\site-packages\telegram\ext\_extbot.py", line 650, in get_updates
    updates = await super().get_updates(
              ^^^^^^^^^^^^^^^^^^^^^^^^^^
  File "D:\Programming\Python\Supp0rtBot\.venv\Lib\site-packages\telegram\_bot.py", line 4480, in get_updates
    await self._post(
  File "D:\Programming\Python\Supp0rtBot\.venv\Lib\site-packages\telegram\_bot.py", line 619, in _post
    return await self._do_post(
           ^^^^^^^^^^^^^^^^^^^^
  File "D:\Programming\Python\Supp0rtBot\.venv\Lib\site-packages\telegram\ext\_extbot.py", line 354, in _do_post
    return await super()._do_post(
           ^^^^^^^^^^^^^^^^^^^^^^^
  File "D:\Programming\Python\Supp0rtBot\.venv\Lib\site-packages\telegram\_bot.py", line 648, in _do_post
    result = await request.post(
             ^^^^^^^^^^^^^^^^^^^
  File "D:\Programming\Python\Supp0rtBot\.venv\Lib\site-packages\telegram\request\_baserequest.py", line 202, in post
    result = await self._request_wrapper(
             ^^^^^^^^^^^^^^^^^^^^^^^^^^^^
  File "D:\Programming\Python\Supp0rtBot\.venv\Lib\site-packages\telegram\request\_baserequest.py", line 385, in _request_wrapper
    raise Conflict(message)
telegram.error.Conflict: Conflict: terminated by other getUpdates request; make sure that only one bot instance is running
2025-07-03 18:55:41,224 - telegram.ext.Application - ERROR - No error handlers are registered, logging exception.
Traceback (most recent call last):
  File "D:\Programming\Python\Supp0rtBot\.venv\Lib\site-packages\telegram\ext\_updater.py", line 750, in _network_loop_retry
    if not await do_action():
           ^^^^^^^^^^^^^^^^^
  File "D:\Programming\Python\Supp0rtBot\.venv\Lib\site-packages\telegram\ext\_updater.py", line 744, in do_action
    return action_cb_task.result()
           ^^^^^^^^^^^^^^^^^^^^^^^
  File "C:\Users\38066\AppData\Local\Programs\Python\Python312\Lib\asyncio\futures.py", line 203, in result
    raise self._exception.with_traceback(self._exception_tb)
  File "C:\Users\38066\AppData\Local\Programs\Python\Python312\Lib\asyncio\tasks.py", line 314, in __step_run_and_handle_result
    result = coro.send(None)
             ^^^^^^^^^^^^^^^
  File "D:\Programming\Python\Supp0rtBot\.venv\Lib\site-packages\telegram\ext\_updater.py", line 371, in polling_action_cb
    updates = await self.bot.get_updates(
              ^^^^^^^^^^^^^^^^^^^^^^^^^^^
  File "D:\Programming\Python\Supp0rtBot\.venv\Lib\site-packages\telegram\ext\_extbot.py", line 650, in get_updates
    updates = await super().get_updates(
              ^^^^^^^^^^^^^^^^^^^^^^^^^^
  File "D:\Programming\Python\Supp0rtBot\.venv\Lib\site-packages\telegram\_bot.py", line 4480, in get_updates
    await self._post(
  File "D:\Programming\Python\Supp0rtBot\.venv\Lib\site-packages\telegram\_bot.py", line 619, in _post
    return await self._do_post(
           ^^^^^^^^^^^^^^^^^^^^
  File "D:\Programming\Python\Supp0rtBot\.venv\Lib\site-packages\telegram\ext\_extbot.py", line 354, in _do_post
    return await super()._do_post(
           ^^^^^^^^^^^^^^^^^^^^^^^
  File "D:\Programming\Python\Supp0rtBot\.venv\Lib\site-packages\telegram\_bot.py", line 648, in _do_post
    result = await request.post(
             ^^^^^^^^^^^^^^^^^^^
  File "D:\Programming\Python\Supp0rtBot\.venv\Lib\site-packages\telegram\request\_baserequest.py", line 202, in post
    result = await self._request_wrapper(
             ^^^^^^^^^^^^^^^^^^^^^^^^^^^^
  File "D:\Programming\Python\Supp0rtBot\.venv\Lib\site-packages\telegram\request\_baserequest.py", line 385, in _request_wrapper
    raise Conflict(message)
telegram.error.Conflict: Conflict: terminated by other getUpdates request; make sure that only one bot instance is running
2025-07-03 18:55:43,534 - telegram.ext.Application - ERROR - No error handlers are registered, logging exception.
Traceback (most recent call last):
  File "D:\Programming\Python\Supp0rtBot\.venv\Lib\site-packages\telegram\ext\_updater.py", line 750, in _network_loop_retry
    if not await do_action():
           ^^^^^^^^^^^^^^^^^
  File "D:\Programming\Python\Supp0rtBot\.venv\Lib\site-packages\telegram\ext\_updater.py", line 744, in do_action
    return action_cb_task.result()
           ^^^^^^^^^^^^^^^^^^^^^^^
  File "C:\Users\38066\AppData\Local\Programs\Python\Python312\Lib\asyncio\futures.py", line 203, in result
    raise self._exception.with_traceback(self._exception_tb)
  File "C:\Users\38066\AppData\Local\Programs\Python\Python312\Lib\asyncio\tasks.py", line 314, in __step_run_and_handle_result
    result = coro.send(None)
             ^^^^^^^^^^^^^^^
  File "D:\Programming\Python\Supp0rtBot\.venv\Lib\site-packages\telegram\ext\_updater.py", line 371, in polling_action_cb
    updates = await self.bot.get_updates(
              ^^^^^^^^^^^^^^^^^^^^^^^^^^^
  File "D:\Programming\Python\Supp0rtBot\.venv\Lib\site-packages\telegram\ext\_extbot.py", line 650, in get_updates
    updates = await super().get_updates(
              ^^^^^^^^^^^^^^^^^^^^^^^^^^
  File "D:\Programming\Python\Supp0rtBot\.venv\Lib\site-packages\telegram\_bot.py", line 4480, in get_updates
    await self._post(
  File "D:\Programming\Python\Supp0rtBot\.venv\Lib\site-packages\telegram\_bot.py", line 619, in _post
    return await self._do_post(
           ^^^^^^^^^^^^^^^^^^^^
  File "D:\Programming\Python\Supp0rtBot\.venv\Lib\site-packages\telegram\ext\_extbot.py", line 354, in _do_post
    return await super()._do_post(
           ^^^^^^^^^^^^^^^^^^^^^^^
  File "D:\Programming\Python\Supp0rtBot\.venv\Lib\site-packages\telegram\_bot.py", line 648, in _do_post
    result = await request.post(
             ^^^^^^^^^^^^^^^^^^^
  File "D:\Programming\Python\Supp0rtBot\.venv\Lib\site-packages\telegram\request\_baserequest.py", line 202, in post
    result = await self._request_wrapper(
             ^^^^^^^^^^^^^^^^^^^^^^^^^^^^
  File "D:\Programming\Python\Supp0rtBot\.venv\Lib\site-packages\telegram\request\_baserequest.py", line 385, in _request_wrapper
    raise Conflict(message)
telegram.error.Conflict: Conflict: terminated by other getUpdates request; make sure that only one bot instance is running
2025-07-03 20:31:41,120 - telegram.ext.Updater - ERROR - Error while calling `get_updates` one more time to mark all fetched updates as read: %s. Suppressing error to ensure graceful shutdown. When polling for updates is restarted, updates may be fetched again. Please adjust timeouts via `ApplicationBuilder` or the parameter `get_updates_request` of `Bot`.
Traceback (most recent call last):
  File "D:\Programming\Python\Supp0rtBot\.venv\Lib\site-packages\httpx\_transports\default.py", line 101, in map_httpcore_exceptions
    yield
  File "D:\Programming\Python\Supp0rtBot\.venv\Lib\site-packages\httpx\_transports\default.py", line 394, in handle_async_request
    resp = await self._pool.handle_async_request(req)
           ^^^^^^^^^^^^^^^^^^^^^^^^^^^^^^^^^^^^^^^^^^
  File "D:\Programming\Python\Supp0rtBot\.venv\Lib\site-packages\httpcore\_async\connection_pool.py", line 256, in handle_async_request
    raise exc from None
  File "D:\Programming\Python\Supp0rtBot\.venv\Lib\site-packages\httpcore\_async\connection_pool.py", line 236, in handle_async_request
    response = await connection.handle_async_request(
               ^^^^^^^^^^^^^^^^^^^^^^^^^^^^^^^^^^^^^^
  File "D:\Programming\Python\Supp0rtBot\.venv\Lib\site-packages\httpcore\_async\connection.py", line 101, in handle_async_request
    raise exc
  File "D:\Programming\Python\Supp0rtBot\.venv\Lib\site-packages\httpcore\_async\connection.py", line 78, in handle_async_request
    stream = await self._connect(request)
             ^^^^^^^^^^^^^^^^^^^^^^^^^^^^
  File "D:\Programming\Python\Supp0rtBot\.venv\Lib\site-packages\httpcore\_async\connection.py", line 124, in _connect
    stream = await self._network_backend.connect_tcp(**kwargs)
             ^^^^^^^^^^^^^^^^^^^^^^^^^^^^^^^^^^^^^^^^^^^^^^^^^
  File "D:\Programming\Python\Supp0rtBot\.venv\Lib\site-packages\httpcore\_backends\auto.py", line 31, in connect_tcp
    return await self._backend.connect_tcp(
           ^^^^^^^^^^^^^^^^^^^^^^^^^^^^^^^^
  File "D:\Programming\Python\Supp0rtBot\.venv\Lib\site-packages\httpcore\_backends\anyio.py", line 113, in connect_tcp
    with map_exceptions(exc_map):
  File "C:\Users\38066\AppData\Local\Programs\Python\Python312\Lib\contextlib.py", line 158, in __exit__
    self.gen.throw(value)
  File "D:\Programming\Python\Supp0rtBot\.venv\Lib\site-packages\httpcore\_exceptions.py", line 14, in map_exceptions
    raise to_exc(exc) from exc
httpcore.ConnectTimeout

The above exception was the direct cause of the following exception:

Traceback (most recent call last):
  File "D:\Programming\Python\Supp0rtBot\.venv\Lib\site-packages\telegram\request\_httpxrequest.py", line 293, in do_request
    res = await self._client.request(
          ^^^^^^^^^^^^^^^^^^^^^^^^^^^
  File "D:\Programming\Python\Supp0rtBot\.venv\Lib\site-packages\httpx\_client.py", line 1540, in request
    return await self.send(request, auth=auth, follow_redirects=follow_redirects)
           ^^^^^^^^^^^^^^^^^^^^^^^^^^^^^^^^^^^^^^^^^^^^^^^^^^^^^^^^^^^^^^^^^^^^^^
  File "D:\Programming\Python\Supp0rtBot\.venv\Lib\site-packages\httpx\_client.py", line 1629, in send
    response = await self._send_handling_auth(
               ^^^^^^^^^^^^^^^^^^^^^^^^^^^^^^^
  File "D:\Programming\Python\Supp0rtBot\.venv\Lib\site-packages\httpx\_client.py", line 1657, in _send_handling_auth
    response = await self._send_handling_redirects(
               ^^^^^^^^^^^^^^^^^^^^^^^^^^^^^^^^^^^^
  File "D:\Programming\Python\Supp0rtBot\.venv\Lib\site-packages\httpx\_client.py", line 1694, in _send_handling_redirects
    response = await self._send_single_request(request)
               ^^^^^^^^^^^^^^^^^^^^^^^^^^^^^^^^^^^^^^^^
  File "D:\Programming\Python\Supp0rtBot\.venv\Lib\site-packages\httpx\_client.py", line 1730, in _send_single_request
    response = await transport.handle_async_request(request)
               ^^^^^^^^^^^^^^^^^^^^^^^^^^^^^^^^^^^^^^^^^^^^^
  File "D:\Programming\Python\Supp0rtBot\.venv\Lib\site-packages\httpx\_transports\default.py", line 393, in handle_async_request
    with map_httpcore_exceptions():
  File "C:\Users\38066\AppData\Local\Programs\Python\Python312\Lib\contextlib.py", line 158, in __exit__
    self.gen.throw(value)
  File "D:\Programming\Python\Supp0rtBot\.venv\Lib\site-packages\httpx\_transports\default.py", line 118, in map_httpcore_exceptions
    raise mapped_exc(message) from exc
httpx.ConnectTimeout

The above exception was the direct cause of the following exception:

Traceback (most recent call last):
  File "D:\Programming\Python\Supp0rtBot\.venv\Lib\site-packages\telegram\ext\_updater.py", line 432, in _get_updates_cleanup
    await self.bot.get_updates(
  File "D:\Programming\Python\Supp0rtBot\.venv\Lib\site-packages\telegram\ext\_extbot.py", line 650, in get_updates
    updates = await super().get_updates(
              ^^^^^^^^^^^^^^^^^^^^^^^^^^
  File "D:\Programming\Python\Supp0rtBot\.venv\Lib\site-packages\telegram\_bot.py", line 4480, in get_updates
    await self._post(
  File "D:\Programming\Python\Supp0rtBot\.venv\Lib\site-packages\telegram\_bot.py", line 619, in _post
    return await self._do_post(
           ^^^^^^^^^^^^^^^^^^^^
  File "D:\Programming\Python\Supp0rtBot\.venv\Lib\site-packages\telegram\ext\_extbot.py", line 354, in _do_post
    return await super()._do_post(
           ^^^^^^^^^^^^^^^^^^^^^^^
  File "D:\Programming\Python\Supp0rtBot\.venv\Lib\site-packages\telegram\_bot.py", line 648, in _do_post
    result = await request.post(
             ^^^^^^^^^^^^^^^^^^^
  File "D:\Programming\Python\Supp0rtBot\.venv\Lib\site-packages\telegram\request\_baserequest.py", line 202, in post
    result = await self._request_wrapper(
             ^^^^^^^^^^^^^^^^^^^^^^^^^^^^
  File "D:\Programming\Python\Supp0rtBot\.venv\Lib\site-packages\telegram\request\_baserequest.py", line 334, in _request_wrapper
    code, payload = await self.do_request(
                    ^^^^^^^^^^^^^^^^^^^^^^
  File "D:\Programming\Python\Supp0rtBot\.venv\Lib\site-packages\telegram\request\_httpxrequest.py", line 310, in do_request
    raise TimedOut from err
telegram.error.TimedOut: Timed out
2025-07-03 20:36:18,096 - werkzeug - INFO - 127.0.0.1 - - [03/Jul/2025 20:36:18] "GET / HTTP/1.1" 200 -
2025-07-03 20:36:21,596 - werkzeug - INFO - 127.0.0.1 - - [03/Jul/2025 20:36:21] "GET / HTTP/1.1" 200 -
2025-07-03 20:37:15,063 - werkzeug - INFO - 127.0.0.1 - - [03/Jul/2025 20:37:15] "GET / HTTP/1.1" 200 -
2025-07-03 20:37:17,343 - werkzeug - INFO - 127.0.0.1 - - [03/Jul/2025 20:37:17] "GET / HTTP/1.1" 200 -
2025-07-03 20:37:26,130 - werkzeug - INFO - 192.168.31.105 - - [03/Jul/2025 20:37:26] "GET / HTTP/1.1" 200 -
2025-07-03 20:37:27,079 - werkzeug - INFO - 192.168.31.105 - - [03/Jul/2025 20:37:27] "[33mGET /favicon.ico HTTP/1.1[0m" 404 -
2025-07-03 20:39:16,322 - werkzeug - INFO - [31m[1mWARNING: This is a development server. Do not use it in a production deployment. Use a production WSGI server instead.[0m
 * Running on all addresses (0.0.0.0)
 * Running on http://127.0.0.1:5000
 * Running on http://192.168.31.105:5000
2025-07-03 20:39:16,323 - werkzeug - INFO - [33mPress CTRL+C to quit[0m
2025-07-03 20:41:37,324 - werkzeug - INFO - 127.0.0.1 - - [03/Jul/2025 20:41:37] "GET / HTTP/1.1" 200 -
2025-07-03 20:42:19,560 - werkzeug - INFO - 127.0.0.1 - - [03/Jul/2025 20:42:19] "GET / HTTP/1.1" 200 -
2025-07-03 20:42:20,662 - werkzeug - INFO - 127.0.0.1 - - [03/Jul/2025 20:42:20] "GET / HTTP/1.1" 200 -
2025-07-03 20:43:56,096 - werkzeug - INFO - 127.0.0.1 - - [03/Jul/2025 20:43:56] "GET / HTTP/1.1" 200 -
2025-07-03 20:45:44,640 - werkzeug - INFO - 127.0.0.1 - - [03/Jul/2025 20:45:44] "GET / HTTP/1.1" 200 -
2025-07-03 20:49:07,224 - werkzeug - INFO - 127.0.0.1 - - [03/Jul/2025 20:49:07] "GET / HTTP/1.1" 200 -
2025-07-03 20:49:31,072 - werkzeug - INFO - [31m[1mWARNING: This is a development server. Do not use it in a production deployment. Use a production WSGI server instead.[0m
 * Running on all addresses (0.0.0.0)
 * Running on http://127.0.0.1:5000
 * Running on http://192.168.31.105:5000
2025-07-03 20:49:31,073 - werkzeug - INFO - [33mPress CTRL+C to quit[0m
2025-07-03 20:50:21,861 - werkzeug - INFO - 192.168.31.105 - - [03/Jul/2025 20:50:21] "GET / HTTP/1.1" 200 -
2025-07-03 20:56:51,310 - werkzeug - INFO - 192.168.31.105 - - [03/Jul/2025 20:56:51] "GET / HTTP/1.1" 200 -
2025-07-03 20:57:12,967 - werkzeug - INFO - [31m[1mWARNING: This is a development server. Do not use it in a production deployment. Use a production WSGI server instead.[0m
 * Running on all addresses (0.0.0.0)
 * Running on http://127.0.0.1:5000
 * Running on http://192.168.31.105:5000
2025-07-03 20:57:12,968 - werkzeug - INFO - [33mPress CTRL+C to quit[0m
2025-07-03 20:57:26,087 - werkzeug - INFO - 192.168.31.105 - - [03/Jul/2025 20:57:26] "GET / HTTP/1.1" 200 -
2025-07-03 20:57:30,052 - werkzeug - INFO - 192.168.31.105 - - [03/Jul/2025 20:57:30] "GET / HTTP/1.1" 200 -
2025-07-03 20:57:42,243 - werkzeug - INFO - 127.0.0.1 - - [03/Jul/2025 20:57:42] "GET / HTTP/1.1" 200 -
2025-07-03 20:57:44,134 - werkzeug - INFO - 127.0.0.1 - - [03/Jul/2025 20:57:44] "GET / HTTP/1.1" 200 -
2025-07-03 20:57:45,115 - werkzeug - INFO - 127.0.0.1 - - [03/Jul/2025 20:57:45] "GET / HTTP/1.1" 200 -
2025-07-03 20:57:46,064 - werkzeug - INFO - 127.0.0.1 - - [03/Jul/2025 20:57:46] "GET / HTTP/1.1" 200 -
2025-07-03 20:57:46,877 - werkzeug - INFO - 127.0.0.1 - - [03/Jul/2025 20:57:46] "GET / HTTP/1.1" 200 -
2025-07-03 20:57:47,686 - werkzeug - INFO - 127.0.0.1 - - [03/Jul/2025 20:57:47] "GET / HTTP/1.1" 200 -
2025-07-03 20:57:50,163 - werkzeug - INFO - 127.0.0.1 - - [03/Jul/2025 20:57:50] "GET / HTTP/1.1" 200 -
2025-07-03 20:58:55,202 - werkzeug - INFO - 127.0.0.1 - - [03/Jul/2025 20:58:55] "GET / HTTP/1.1" 200 -
2025-07-03 21:10:00,040 - werkzeug - INFO - 127.0.0.1 - - [03/Jul/2025 21:10:00] "GET / HTTP/1.1" 200 -
2025-07-03 21:10:07,563 - werkzeug - INFO - 127.0.0.1 - - [03/Jul/2025 21:10:07] "GET / HTTP/1.1" 200 -
2025-07-03 21:11:53,025 - werkzeug - INFO - 127.0.0.1 - - [03/Jul/2025 21:11:53] "GET / HTTP/1.1" 200 -
2025-07-29 16:31:59,812 - werkzeug - INFO - [31m[1mWARNING: This is a development server. Do not use it in a production deployment. Use a production WSGI server instead.[0m
 * Running on all addresses (0.0.0.0)
 * Running on http://127.0.0.1:5000
 * Running on http://192.168.31.10:5000
2025-07-29 16:31:59,812 - werkzeug - INFO - [33mPress CTRL+C to quit[0m
2025-07-29 16:33:30,115 - werkzeug - INFO - [31m[1mWARNING: This is a development server. Do not use it in a production deployment. Use a production WSGI server instead.[0m
 * Running on all addresses (0.0.0.0)
 * Running on http://127.0.0.1:5000
 * Running on http://192.168.31.10:5000
2025-07-29 16:33:30,115 - werkzeug - INFO - [33mPress CTRL+C to quit[0m
2025-07-29 16:35:25,622 - werkzeug - INFO - [31m[1mWARNING: This is a development server. Do not use it in a production deployment. Use a production WSGI server instead.[0m
 * Running on all addresses (0.0.0.0)
 * Running on http://127.0.0.1:5000
 * Running on http://192.168.31.10:5000
2025-07-29 16:35:25,622 - werkzeug - INFO - [33mPress CTRL+C to quit[0m
2025-07-29 16:37:11,634 - werkzeug - INFO - [31m[1mWARNING: This is a development server. Do not use it in a production deployment. Use a production WSGI server instead.[0m
 * Running on all addresses (0.0.0.0)
 * Running on http://127.0.0.1:5000
 * Running on http://192.168.31.10:5000
2025-07-29 16:37:11,634 - werkzeug - INFO - [33mPress CTRL+C to quit[0m
2025-07-29 16:42:12,308 - werkzeug - INFO - [31m[1mWARNING: This is a development server. Do not use it in a production deployment. Use a production WSGI server instead.[0m
 * Running on all addresses (0.0.0.0)
 * Running on http://127.0.0.1:5000
 * Running on http://192.168.31.10:5000
2025-07-29 16:42:12,308 - werkzeug - INFO - [33mPress CTRL+C to quit[0m
2025-07-29 16:42:54,025 - werkzeug - INFO - [31m[1mWARNING: This is a development server. Do not use it in a production deployment. Use a production WSGI server instead.[0m
 * Running on all addresses (0.0.0.0)
 * Running on http://127.0.0.1:5000
 * Running on http://192.168.31.10:5000
2025-07-29 16:42:54,026 - werkzeug - INFO - [33mPress CTRL+C to quit[0m
2025-07-29 16:45:44,661 - werkzeug - INFO - [31m[1mWARNING: This is a development server. Do not use it in a production deployment. Use a production WSGI server instead.[0m
 * Running on all addresses (0.0.0.0)
 * Running on http://127.0.0.1:5000
 * Running on http://192.168.31.10:5000
2025-07-29 16:45:44,661 - werkzeug - INFO - [33mPress CTRL+C to quit[0m
2025-07-29 16:47:21,251 - werkzeug - INFO - [31m[1mWARNING: This is a development server. Do not use it in a production deployment. Use a production WSGI server instead.[0m
 * Running on all addresses (0.0.0.0)
 * Running on http://127.0.0.1:5000
 * Running on http://192.168.31.10:5000
2025-07-29 16:47:21,251 - werkzeug - INFO - [33mPress CTRL+C to quit[0m
2025-07-29 16:49:41,065 - werkzeug - INFO - [31m[1mWARNING: This is a development server. Do not use it in a production deployment. Use a production WSGI server instead.[0m
 * Running on all addresses (0.0.0.0)
 * Running on http://127.0.0.1:5000
 * Running on http://192.168.31.10:5000
2025-07-29 16:49:41,065 - werkzeug - INFO - [33mPress CTRL+C to quit[0m
2025-07-29 16:50:09,676 - werkzeug - INFO - [31m[1mWARNING: This is a development server. Do not use it in a production deployment. Use a production WSGI server instead.[0m
 * Running on all addresses (0.0.0.0)
 * Running on http://127.0.0.1:5000
 * Running on http://192.168.31.10:5000
2025-07-29 16:50:09,677 - werkzeug - INFO - [33mPress CTRL+C to quit[0m
2025-07-29 16:50:12,763 - apscheduler.executors.default - ERROR - Job "send_uptime_message (trigger: interval[0:00:01], next run at: 2025-07-29 16:50:13 EEST)" raised an exception
Traceback (most recent call last):
  File "C:\Users\Skeleton\PycharmProjects\Supp0rtBot\.venv\Lib\site-packages\apscheduler\executors\base.py", line 181, in run_coroutine_job
    retval = await job.func(*job.args, **job.kwargs)
             ^^^^^^^^^^^^^^^^^^^^^^^^^^^^^^^^^^^^^^^
  File "C:\Users\Skeleton\PycharmProjects\Supp0rtBot\TgBot3.py", line 2083, in send_uptime_message
    await context.bot.send_message(
          ~~~~~~~~~~~~~~~~~~~~~~~~^
        chat_id=ACTIVITY_CHECK_CHAT_ID,
        ^^^^^^^^^^^^^^^^^^^^^^^^^^^^^^^
        text=f"Бот активен уже {uptime_hours} часов"
        ^^^^^^^^^^^^^^^^^^^^^^^^^^^^^^^^^^^^^^^^^^^^
    )
    ^
TypeError: User.send_message() got an unexpected keyword argument 'chat_id'
2025-07-29 16:50:13,749 - apscheduler.executors.default - ERROR - Job "send_uptime_message (trigger: interval[0:00:01], next run at: 2025-07-29 16:50:14 EEST)" raised an exception
Traceback (most recent call last):
  File "C:\Users\Skeleton\PycharmProjects\Supp0rtBot\.venv\Lib\site-packages\apscheduler\executors\base.py", line 181, in run_coroutine_job
    retval = await job.func(*job.args, **job.kwargs)
             ^^^^^^^^^^^^^^^^^^^^^^^^^^^^^^^^^^^^^^^
  File "C:\Users\Skeleton\PycharmProjects\Supp0rtBot\TgBot3.py", line 2083, in send_uptime_message
    await context.bot.send_message(
          ~~~~~~~~~~~~~~~~~~~~~~~~^
        chat_id=ACTIVITY_CHECK_CHAT_ID,
        ^^^^^^^^^^^^^^^^^^^^^^^^^^^^^^^
        text=f"Бот активен уже {uptime_hours} часов"
        ^^^^^^^^^^^^^^^^^^^^^^^^^^^^^^^^^^^^^^^^^^^^
    )
    ^
TypeError: User.send_message() got an unexpected keyword argument 'chat_id'
2025-07-29 16:50:14,816 - apscheduler.executors.default - ERROR - Job "send_uptime_message (trigger: interval[0:00:01], next run at: 2025-07-29 16:50:15 EEST)" raised an exception
Traceback (most recent call last):
  File "C:\Users\Skeleton\PycharmProjects\Supp0rtBot\.venv\Lib\site-packages\apscheduler\executors\base.py", line 181, in run_coroutine_job
    retval = await job.func(*job.args, **job.kwargs)
             ^^^^^^^^^^^^^^^^^^^^^^^^^^^^^^^^^^^^^^^
  File "C:\Users\Skeleton\PycharmProjects\Supp0rtBot\TgBot3.py", line 2083, in send_uptime_message
    await context.bot.send_message(
          ~~~~~~~~~~~~~~~~~~~~~~~~^
        chat_id=ACTIVITY_CHECK_CHAT_ID,
        ^^^^^^^^^^^^^^^^^^^^^^^^^^^^^^^
        text=f"Бот активен уже {uptime_hours} часов"
        ^^^^^^^^^^^^^^^^^^^^^^^^^^^^^^^^^^^^^^^^^^^^
    )
    ^
TypeError: User.send_message() got an unexpected keyword argument 'chat_id'
2025-07-29 16:50:15,743 - apscheduler.executors.default - ERROR - Job "send_uptime_message (trigger: interval[0:00:01], next run at: 2025-07-29 16:50:16 EEST)" raised an exception
Traceback (most recent call last):
  File "C:\Users\Skeleton\PycharmProjects\Supp0rtBot\.venv\Lib\site-packages\apscheduler\executors\base.py", line 181, in run_coroutine_job
    retval = await job.func(*job.args, **job.kwargs)
             ^^^^^^^^^^^^^^^^^^^^^^^^^^^^^^^^^^^^^^^
  File "C:\Users\Skeleton\PycharmProjects\Supp0rtBot\TgBot3.py", line 2083, in send_uptime_message
    await context.bot.send_message(
          ~~~~~~~~~~~~~~~~~~~~~~~~^
        chat_id=ACTIVITY_CHECK_CHAT_ID,
        ^^^^^^^^^^^^^^^^^^^^^^^^^^^^^^^
        text=f"Бот активен уже {uptime_hours} часов"
        ^^^^^^^^^^^^^^^^^^^^^^^^^^^^^^^^^^^^^^^^^^^^
    )
    ^
TypeError: User.send_message() got an unexpected keyword argument 'chat_id'
2025-07-29 16:50:16,739 - apscheduler.executors.default - ERROR - Job "send_uptime_message (trigger: interval[0:00:01], next run at: 2025-07-29 16:50:17 EEST)" raised an exception
Traceback (most recent call last):
  File "C:\Users\Skeleton\PycharmProjects\Supp0rtBot\.venv\Lib\site-packages\apscheduler\executors\base.py", line 181, in run_coroutine_job
    retval = await job.func(*job.args, **job.kwargs)
             ^^^^^^^^^^^^^^^^^^^^^^^^^^^^^^^^^^^^^^^
  File "C:\Users\Skeleton\PycharmProjects\Supp0rtBot\TgBot3.py", line 2083, in send_uptime_message
    await context.bot.send_message(
          ~~~~~~~~~~~~~~~~~~~~~~~~^
        chat_id=ACTIVITY_CHECK_CHAT_ID,
        ^^^^^^^^^^^^^^^^^^^^^^^^^^^^^^^
        text=f"Бот активен уже {uptime_hours} часов"
        ^^^^^^^^^^^^^^^^^^^^^^^^^^^^^^^^^^^^^^^^^^^^
    )
    ^
TypeError: User.send_message() got an unexpected keyword argument 'chat_id'
2025-07-29 16:50:17,739 - apscheduler.executors.default - ERROR - Job "send_uptime_message (trigger: interval[0:00:01], next run at: 2025-07-29 16:50:18 EEST)" raised an exception
Traceback (most recent call last):
  File "C:\Users\Skeleton\PycharmProjects\Supp0rtBot\.venv\Lib\site-packages\apscheduler\executors\base.py", line 181, in run_coroutine_job
    retval = await job.func(*job.args, **job.kwargs)
             ^^^^^^^^^^^^^^^^^^^^^^^^^^^^^^^^^^^^^^^
  File "C:\Users\Skeleton\PycharmProjects\Supp0rtBot\TgBot3.py", line 2083, in send_uptime_message
    await context.bot.send_message(
          ~~~~~~~~~~~~~~~~~~~~~~~~^
        chat_id=ACTIVITY_CHECK_CHAT_ID,
        ^^^^^^^^^^^^^^^^^^^^^^^^^^^^^^^
        text=f"Бот активен уже {uptime_hours} часов"
        ^^^^^^^^^^^^^^^^^^^^^^^^^^^^^^^^^^^^^^^^^^^^
    )
    ^
TypeError: User.send_message() got an unexpected keyword argument 'chat_id'
2025-07-29 16:50:18,743 - apscheduler.executors.default - ERROR - Job "send_uptime_message (trigger: interval[0:00:01], next run at: 2025-07-29 16:50:19 EEST)" raised an exception
Traceback (most recent call last):
  File "C:\Users\Skeleton\PycharmProjects\Supp0rtBot\.venv\Lib\site-packages\apscheduler\executors\base.py", line 181, in run_coroutine_job
    retval = await job.func(*job.args, **job.kwargs)
             ^^^^^^^^^^^^^^^^^^^^^^^^^^^^^^^^^^^^^^^
  File "C:\Users\Skeleton\PycharmProjects\Supp0rtBot\TgBot3.py", line 2083, in send_uptime_message
    await context.bot.send_message(
          ~~~~~~~~~~~~~~~~~~~~~~~~^
        chat_id=ACTIVITY_CHECK_CHAT_ID,
        ^^^^^^^^^^^^^^^^^^^^^^^^^^^^^^^
        text=f"Бот активен уже {uptime_hours} часов"
        ^^^^^^^^^^^^^^^^^^^^^^^^^^^^^^^^^^^^^^^^^^^^
    )
    ^
TypeError: User.send_message() got an unexpected keyword argument 'chat_id'
2025-07-29 16:50:19,745 - apscheduler.executors.default - ERROR - Job "send_uptime_message (trigger: interval[0:00:01], next run at: 2025-07-29 16:50:20 EEST)" raised an exception
Traceback (most recent call last):
  File "C:\Users\Skeleton\PycharmProjects\Supp0rtBot\.venv\Lib\site-packages\apscheduler\executors\base.py", line 181, in run_coroutine_job
    retval = await job.func(*job.args, **job.kwargs)
             ^^^^^^^^^^^^^^^^^^^^^^^^^^^^^^^^^^^^^^^
  File "C:\Users\Skeleton\PycharmProjects\Supp0rtBot\TgBot3.py", line 2083, in send_uptime_message
    await context.bot.send_message(
          ~~~~~~~~~~~~~~~~~~~~~~~~^
        chat_id=ACTIVITY_CHECK_CHAT_ID,
        ^^^^^^^^^^^^^^^^^^^^^^^^^^^^^^^
        text=f"Бот активен уже {uptime_hours} часов"
        ^^^^^^^^^^^^^^^^^^^^^^^^^^^^^^^^^^^^^^^^^^^^
    )
    ^
TypeError: User.send_message() got an unexpected keyword argument 'chat_id'
2025-07-29 16:50:20,741 - apscheduler.executors.default - ERROR - Job "send_uptime_message (trigger: interval[0:00:01], next run at: 2025-07-29 16:50:21 EEST)" raised an exception
Traceback (most recent call last):
  File "C:\Users\Skeleton\PycharmProjects\Supp0rtBot\.venv\Lib\site-packages\apscheduler\executors\base.py", line 181, in run_coroutine_job
    retval = await job.func(*job.args, **job.kwargs)
             ^^^^^^^^^^^^^^^^^^^^^^^^^^^^^^^^^^^^^^^
  File "C:\Users\Skeleton\PycharmProjects\Supp0rtBot\TgBot3.py", line 2083, in send_uptime_message
    await context.bot.send_message(
          ~~~~~~~~~~~~~~~~~~~~~~~~^
        chat_id=ACTIVITY_CHECK_CHAT_ID,
        ^^^^^^^^^^^^^^^^^^^^^^^^^^^^^^^
        text=f"Бот активен уже {uptime_hours} часов"
        ^^^^^^^^^^^^^^^^^^^^^^^^^^^^^^^^^^^^^^^^^^^^
    )
    ^
TypeError: User.send_message() got an unexpected keyword argument 'chat_id'
2025-07-29 16:50:21,740 - apscheduler.executors.default - ERROR - Job "send_uptime_message (trigger: interval[0:00:01], next run at: 2025-07-29 16:50:22 EEST)" raised an exception
Traceback (most recent call last):
  File "C:\Users\Skeleton\PycharmProjects\Supp0rtBot\.venv\Lib\site-packages\apscheduler\executors\base.py", line 181, in run_coroutine_job
    retval = await job.func(*job.args, **job.kwargs)
             ^^^^^^^^^^^^^^^^^^^^^^^^^^^^^^^^^^^^^^^
  File "C:\Users\Skeleton\PycharmProjects\Supp0rtBot\TgBot3.py", line 2083, in send_uptime_message
    await context.bot.send_message(
          ~~~~~~~~~~~~~~~~~~~~~~~~^
        chat_id=ACTIVITY_CHECK_CHAT_ID,
        ^^^^^^^^^^^^^^^^^^^^^^^^^^^^^^^
        text=f"Бот активен уже {uptime_hours} часов"
        ^^^^^^^^^^^^^^^^^^^^^^^^^^^^^^^^^^^^^^^^^^^^
    )
    ^
TypeError: User.send_message() got an unexpected keyword argument 'chat_id'
2025-07-29 16:50:22,741 - apscheduler.executors.default - ERROR - Job "send_uptime_message (trigger: interval[0:00:01], next run at: 2025-07-29 16:50:23 EEST)" raised an exception
Traceback (most recent call last):
  File "C:\Users\Skeleton\PycharmProjects\Supp0rtBot\.venv\Lib\site-packages\apscheduler\executors\base.py", line 181, in run_coroutine_job
    retval = await job.func(*job.args, **job.kwargs)
             ^^^^^^^^^^^^^^^^^^^^^^^^^^^^^^^^^^^^^^^
  File "C:\Users\Skeleton\PycharmProjects\Supp0rtBot\TgBot3.py", line 2083, in send_uptime_message
    await context.bot.send_message(
          ~~~~~~~~~~~~~~~~~~~~~~~~^
        chat_id=ACTIVITY_CHECK_CHAT_ID,
        ^^^^^^^^^^^^^^^^^^^^^^^^^^^^^^^
        text=f"Бот активен уже {uptime_hours} часов"
        ^^^^^^^^^^^^^^^^^^^^^^^^^^^^^^^^^^^^^^^^^^^^
    )
    ^
TypeError: User.send_message() got an unexpected keyword argument 'chat_id'
2025-07-29 16:50:23,739 - apscheduler.executors.default - ERROR - Job "send_uptime_message (trigger: interval[0:00:01], next run at: 2025-07-29 16:50:24 EEST)" raised an exception
Traceback (most recent call last):
  File "C:\Users\Skeleton\PycharmProjects\Supp0rtBot\.venv\Lib\site-packages\apscheduler\executors\base.py", line 181, in run_coroutine_job
    retval = await job.func(*job.args, **job.kwargs)
             ^^^^^^^^^^^^^^^^^^^^^^^^^^^^^^^^^^^^^^^
  File "C:\Users\Skeleton\PycharmProjects\Supp0rtBot\TgBot3.py", line 2083, in send_uptime_message
    await context.bot.send_message(
          ~~~~~~~~~~~~~~~~~~~~~~~~^
        chat_id=ACTIVITY_CHECK_CHAT_ID,
        ^^^^^^^^^^^^^^^^^^^^^^^^^^^^^^^
        text=f"Бот активен уже {uptime_hours} часов"
        ^^^^^^^^^^^^^^^^^^^^^^^^^^^^^^^^^^^^^^^^^^^^
    )
    ^
TypeError: User.send_message() got an unexpected keyword argument 'chat_id'
2025-07-29 16:50:24,753 - apscheduler.executors.default - ERROR - Job "send_uptime_message (trigger: interval[0:00:01], next run at: 2025-07-29 16:50:25 EEST)" raised an exception
Traceback (most recent call last):
  File "C:\Users\Skeleton\PycharmProjects\Supp0rtBot\.venv\Lib\site-packages\apscheduler\executors\base.py", line 181, in run_coroutine_job
    retval = await job.func(*job.args, **job.kwargs)
             ^^^^^^^^^^^^^^^^^^^^^^^^^^^^^^^^^^^^^^^
  File "C:\Users\Skeleton\PycharmProjects\Supp0rtBot\TgBot3.py", line 2083, in send_uptime_message
    await context.bot.send_message(
          ~~~~~~~~~~~~~~~~~~~~~~~~^
        chat_id=ACTIVITY_CHECK_CHAT_ID,
        ^^^^^^^^^^^^^^^^^^^^^^^^^^^^^^^
        text=f"Бот активен уже {uptime_hours} часов"
        ^^^^^^^^^^^^^^^^^^^^^^^^^^^^^^^^^^^^^^^^^^^^
    )
    ^
TypeError: User.send_message() got an unexpected keyword argument 'chat_id'
2025-07-29 16:50:25,741 - apscheduler.executors.default - ERROR - Job "send_uptime_message (trigger: interval[0:00:01], next run at: 2025-07-29 16:50:26 EEST)" raised an exception
Traceback (most recent call last):
  File "C:\Users\Skeleton\PycharmProjects\Supp0rtBot\.venv\Lib\site-packages\apscheduler\executors\base.py", line 181, in run_coroutine_job
    retval = await job.func(*job.args, **job.kwargs)
             ^^^^^^^^^^^^^^^^^^^^^^^^^^^^^^^^^^^^^^^
  File "C:\Users\Skeleton\PycharmProjects\Supp0rtBot\TgBot3.py", line 2083, in send_uptime_message
    await context.bot.send_message(
          ~~~~~~~~~~~~~~~~~~~~~~~~^
        chat_id=ACTIVITY_CHECK_CHAT_ID,
        ^^^^^^^^^^^^^^^^^^^^^^^^^^^^^^^
        text=f"Бот активен уже {uptime_hours} часов"
        ^^^^^^^^^^^^^^^^^^^^^^^^^^^^^^^^^^^^^^^^^^^^
    )
    ^
TypeError: User.send_message() got an unexpected keyword argument 'chat_id'
2025-07-29 16:50:26,739 - apscheduler.executors.default - ERROR - Job "send_uptime_message (trigger: interval[0:00:01], next run at: 2025-07-29 16:50:27 EEST)" raised an exception
Traceback (most recent call last):
  File "C:\Users\Skeleton\PycharmProjects\Supp0rtBot\.venv\Lib\site-packages\apscheduler\executors\base.py", line 181, in run_coroutine_job
    retval = await job.func(*job.args, **job.kwargs)
             ^^^^^^^^^^^^^^^^^^^^^^^^^^^^^^^^^^^^^^^
  File "C:\Users\Skeleton\PycharmProjects\Supp0rtBot\TgBot3.py", line 2083, in send_uptime_message
    await context.bot.send_message(
          ~~~~~~~~~~~~~~~~~~~~~~~~^
        chat_id=ACTIVITY_CHECK_CHAT_ID,
        ^^^^^^^^^^^^^^^^^^^^^^^^^^^^^^^
        text=f"Бот активен уже {uptime_hours} часов"
        ^^^^^^^^^^^^^^^^^^^^^^^^^^^^^^^^^^^^^^^^^^^^
    )
    ^
TypeError: User.send_message() got an unexpected keyword argument 'chat_id'
2025-07-29 16:50:27,519 - telegram.ext.Application - ERROR - No error handlers are registered, logging exception.
Traceback (most recent call last):
  File "C:\Users\Skeleton\PycharmProjects\Supp0rtBot\.venv\Lib\site-packages\telegram\ext\_updater.py", line 750, in _network_loop_retry
    if not await do_action():
           ^^^^^^^^^^^^^^^^^
  File "C:\Users\Skeleton\PycharmProjects\Supp0rtBot\.venv\Lib\site-packages\telegram\ext\_updater.py", line 744, in do_action
    return action_cb_task.result()
           ~~~~~~~~~~~~~~~~~~~~~^^
  File "C:\Program Files\Python313\Lib\asyncio\futures.py", line 199, in result
    raise self._exception.with_traceback(self._exception_tb)
  File "C:\Program Files\Python313\Lib\asyncio\tasks.py", line 304, in __step_run_and_handle_result
    result = coro.send(None)
  File "C:\Users\Skeleton\PycharmProjects\Supp0rtBot\.venv\Lib\site-packages\telegram\ext\_updater.py", line 371, in polling_action_cb
    updates = await self.bot.get_updates(
              ^^^^^^^^^^^^^^^^^^^^^^^^^^^
    ...<7 lines>...
    )
    ^
  File "C:\Users\Skeleton\PycharmProjects\Supp0rtBot\.venv\Lib\site-packages\telegram\ext\_extbot.py", line 650, in get_updates
    updates = await super().get_updates(
              ^^^^^^^^^^^^^^^^^^^^^^^^^^
    ...<9 lines>...
    )
    ^
  File "C:\Users\Skeleton\PycharmProjects\Supp0rtBot\.venv\Lib\site-packages\telegram\_bot.py", line 4480, in get_updates
    await self._post(
    ^^^^^^^^^^^^^^^^^
    ...<7 lines>...
    ),
    ^
  File "C:\Users\Skeleton\PycharmProjects\Supp0rtBot\.venv\Lib\site-packages\telegram\_bot.py", line 619, in _post
    return await self._do_post(
           ^^^^^^^^^^^^^^^^^^^^
    ...<6 lines>...
    )
    ^
  File "C:\Users\Skeleton\PycharmProjects\Supp0rtBot\.venv\Lib\site-packages\telegram\ext\_extbot.py", line 354, in _do_post
    return await super()._do_post(
           ^^^^^^^^^^^^^^^^^^^^^^^
    ...<6 lines>...
    )
    ^
  File "C:\Users\Skeleton\PycharmProjects\Supp0rtBot\.venv\Lib\site-packages\telegram\_bot.py", line 648, in _do_post
    result = await request.post(
             ^^^^^^^^^^^^^^^^^^^
    ...<6 lines>...
    )
    ^
  File "C:\Users\Skeleton\PycharmProjects\Supp0rtBot\.venv\Lib\site-packages\telegram\request\_baserequest.py", line 202, in post
    result = await self._request_wrapper(
             ^^^^^^^^^^^^^^^^^^^^^^^^^^^^
    ...<7 lines>...
    )
    ^
  File "C:\Users\Skeleton\PycharmProjects\Supp0rtBot\.venv\Lib\site-packages\telegram\request\_baserequest.py", line 385, in _request_wrapper
    raise Conflict(message)
telegram.error.Conflict: Conflict: terminated by other getUpdates request; make sure that only one bot instance is running
2025-07-29 16:50:27,738 - apscheduler.executors.default - ERROR - Job "send_uptime_message (trigger: interval[0:00:01], next run at: 2025-07-29 16:50:28 EEST)" raised an exception
Traceback (most recent call last):
  File "C:\Users\Skeleton\PycharmProjects\Supp0rtBot\.venv\Lib\site-packages\apscheduler\executors\base.py", line 181, in run_coroutine_job
    retval = await job.func(*job.args, **job.kwargs)
             ^^^^^^^^^^^^^^^^^^^^^^^^^^^^^^^^^^^^^^^
  File "C:\Users\Skeleton\PycharmProjects\Supp0rtBot\TgBot3.py", line 2083, in send_uptime_message
    await context.bot.send_message(
          ~~~~~~~~~~~~~~~~~~~~~~~~^
        chat_id=ACTIVITY_CHECK_CHAT_ID,
        ^^^^^^^^^^^^^^^^^^^^^^^^^^^^^^^
        text=f"Бот активен уже {uptime_hours} часов"
        ^^^^^^^^^^^^^^^^^^^^^^^^^^^^^^^^^^^^^^^^^^^^
    )
    ^
TypeError: User.send_message() got an unexpected keyword argument 'chat_id'
2025-07-29 16:50:28,750 - apscheduler.executors.default - ERROR - Job "send_uptime_message (trigger: interval[0:00:01], next run at: 2025-07-29 16:50:29 EEST)" raised an exception
Traceback (most recent call last):
  File "C:\Users\Skeleton\PycharmProjects\Supp0rtBot\.venv\Lib\site-packages\apscheduler\executors\base.py", line 181, in run_coroutine_job
    retval = await job.func(*job.args, **job.kwargs)
             ^^^^^^^^^^^^^^^^^^^^^^^^^^^^^^^^^^^^^^^
  File "C:\Users\Skeleton\PycharmProjects\Supp0rtBot\TgBot3.py", line 2083, in send_uptime_message
    await context.bot.send_message(
          ~~~~~~~~~~~~~~~~~~~~~~~~^
        chat_id=ACTIVITY_CHECK_CHAT_ID,
        ^^^^^^^^^^^^^^^^^^^^^^^^^^^^^^^
        text=f"Бот активен уже {uptime_hours} часов"
        ^^^^^^^^^^^^^^^^^^^^^^^^^^^^^^^^^^^^^^^^^^^^
    )
    ^
TypeError: User.send_message() got an unexpected keyword argument 'chat_id'
2025-07-29 16:50:29,740 - apscheduler.executors.default - ERROR - Job "send_uptime_message (trigger: interval[0:00:01], next run at: 2025-07-29 16:50:30 EEST)" raised an exception
Traceback (most recent call last):
  File "C:\Users\Skeleton\PycharmProjects\Supp0rtBot\.venv\Lib\site-packages\apscheduler\executors\base.py", line 181, in run_coroutine_job
    retval = await job.func(*job.args, **job.kwargs)
             ^^^^^^^^^^^^^^^^^^^^^^^^^^^^^^^^^^^^^^^
  File "C:\Users\Skeleton\PycharmProjects\Supp0rtBot\TgBot3.py", line 2083, in send_uptime_message
    await context.bot.send_message(
          ~~~~~~~~~~~~~~~~~~~~~~~~^
        chat_id=ACTIVITY_CHECK_CHAT_ID,
        ^^^^^^^^^^^^^^^^^^^^^^^^^^^^^^^
        text=f"Бот активен уже {uptime_hours} часов"
        ^^^^^^^^^^^^^^^^^^^^^^^^^^^^^^^^^^^^^^^^^^^^
    )
    ^
TypeError: User.send_message() got an unexpected keyword argument 'chat_id'
2025-07-29 16:50:30,740 - apscheduler.executors.default - ERROR - Job "send_uptime_message (trigger: interval[0:00:01], next run at: 2025-07-29 16:50:31 EEST)" raised an exception
Traceback (most recent call last):
  File "C:\Users\Skeleton\PycharmProjects\Supp0rtBot\.venv\Lib\site-packages\apscheduler\executors\base.py", line 181, in run_coroutine_job
    retval = await job.func(*job.args, **job.kwargs)
             ^^^^^^^^^^^^^^^^^^^^^^^^^^^^^^^^^^^^^^^
  File "C:\Users\Skeleton\PycharmProjects\Supp0rtBot\TgBot3.py", line 2083, in send_uptime_message
    await context.bot.send_message(
          ~~~~~~~~~~~~~~~~~~~~~~~~^
        chat_id=ACTIVITY_CHECK_CHAT_ID,
        ^^^^^^^^^^^^^^^^^^^^^^^^^^^^^^^
        text=f"Бот активен уже {uptime_hours} часов"
        ^^^^^^^^^^^^^^^^^^^^^^^^^^^^^^^^^^^^^^^^^^^^
    )
    ^
TypeError: User.send_message() got an unexpected keyword argument 'chat_id'
2025-07-29 16:50:31,752 - apscheduler.executors.default - ERROR - Job "send_uptime_message (trigger: interval[0:00:01], next run at: 2025-07-29 16:50:32 EEST)" raised an exception
Traceback (most recent call last):
  File "C:\Users\Skeleton\PycharmProjects\Supp0rtBot\.venv\Lib\site-packages\apscheduler\executors\base.py", line 181, in run_coroutine_job
    retval = await job.func(*job.args, **job.kwargs)
             ^^^^^^^^^^^^^^^^^^^^^^^^^^^^^^^^^^^^^^^
  File "C:\Users\Skeleton\PycharmProjects\Supp0rtBot\TgBot3.py", line 2083, in send_uptime_message
    await context.bot.send_message(
          ~~~~~~~~~~~~~~~~~~~~~~~~^
        chat_id=ACTIVITY_CHECK_CHAT_ID,
        ^^^^^^^^^^^^^^^^^^^^^^^^^^^^^^^
        text=f"Бот активен уже {uptime_hours} часов"
        ^^^^^^^^^^^^^^^^^^^^^^^^^^^^^^^^^^^^^^^^^^^^
    )
    ^
TypeError: User.send_message() got an unexpected keyword argument 'chat_id'
2025-07-29 16:50:32,741 - apscheduler.executors.default - ERROR - Job "send_uptime_message (trigger: interval[0:00:01], next run at: 2025-07-29 16:50:33 EEST)" raised an exception
Traceback (most recent call last):
  File "C:\Users\Skeleton\PycharmProjects\Supp0rtBot\.venv\Lib\site-packages\apscheduler\executors\base.py", line 181, in run_coroutine_job
    retval = await job.func(*job.args, **job.kwargs)
             ^^^^^^^^^^^^^^^^^^^^^^^^^^^^^^^^^^^^^^^
  File "C:\Users\Skeleton\PycharmProjects\Supp0rtBot\TgBot3.py", line 2083, in send_uptime_message
    await context.bot.send_message(
          ~~~~~~~~~~~~~~~~~~~~~~~~^
        chat_id=ACTIVITY_CHECK_CHAT_ID,
        ^^^^^^^^^^^^^^^^^^^^^^^^^^^^^^^
        text=f"Бот активен уже {uptime_hours} часов"
        ^^^^^^^^^^^^^^^^^^^^^^^^^^^^^^^^^^^^^^^^^^^^
    )
    ^
TypeError: User.send_message() got an unexpected keyword argument 'chat_id'
2025-07-29 16:50:32,748 - telegram.ext.Application - ERROR - No error handlers are registered, logging exception.
Traceback (most recent call last):
  File "C:\Users\Skeleton\PycharmProjects\Supp0rtBot\.venv\Lib\site-packages\telegram\ext\_updater.py", line 750, in _network_loop_retry
    if not await do_action():
           ^^^^^^^^^^^^^^^^^
  File "C:\Users\Skeleton\PycharmProjects\Supp0rtBot\.venv\Lib\site-packages\telegram\ext\_updater.py", line 744, in do_action
    return action_cb_task.result()
           ~~~~~~~~~~~~~~~~~~~~~^^
  File "C:\Program Files\Python313\Lib\asyncio\futures.py", line 199, in result
    raise self._exception.with_traceback(self._exception_tb)
  File "C:\Program Files\Python313\Lib\asyncio\tasks.py", line 304, in __step_run_and_handle_result
    result = coro.send(None)
  File "C:\Users\Skeleton\PycharmProjects\Supp0rtBot\.venv\Lib\site-packages\telegram\ext\_updater.py", line 371, in polling_action_cb
    updates = await self.bot.get_updates(
              ^^^^^^^^^^^^^^^^^^^^^^^^^^^
    ...<7 lines>...
    )
    ^
  File "C:\Users\Skeleton\PycharmProjects\Supp0rtBot\.venv\Lib\site-packages\telegram\ext\_extbot.py", line 650, in get_updates
    updates = await super().get_updates(
              ^^^^^^^^^^^^^^^^^^^^^^^^^^
    ...<9 lines>...
    )
    ^
  File "C:\Users\Skeleton\PycharmProjects\Supp0rtBot\.venv\Lib\site-packages\telegram\_bot.py", line 4480, in get_updates
    await self._post(
    ^^^^^^^^^^^^^^^^^
    ...<7 lines>...
    ),
    ^
  File "C:\Users\Skeleton\PycharmProjects\Supp0rtBot\.venv\Lib\site-packages\telegram\_bot.py", line 619, in _post
    return await self._do_post(
           ^^^^^^^^^^^^^^^^^^^^
    ...<6 lines>...
    )
    ^
  File "C:\Users\Skeleton\PycharmProjects\Supp0rtBot\.venv\Lib\site-packages\telegram\ext\_extbot.py", line 354, in _do_post
    return await super()._do_post(
           ^^^^^^^^^^^^^^^^^^^^^^^
    ...<6 lines>...
    )
    ^
  File "C:\Users\Skeleton\PycharmProjects\Supp0rtBot\.venv\Lib\site-packages\telegram\_bot.py", line 648, in _do_post
    result = await request.post(
             ^^^^^^^^^^^^^^^^^^^
    ...<6 lines>...
    )
    ^
  File "C:\Users\Skeleton\PycharmProjects\Supp0rtBot\.venv\Lib\site-packages\telegram\request\_baserequest.py", line 202, in post
    result = await self._request_wrapper(
             ^^^^^^^^^^^^^^^^^^^^^^^^^^^^
    ...<7 lines>...
    )
    ^
  File "C:\Users\Skeleton\PycharmProjects\Supp0rtBot\.venv\Lib\site-packages\telegram\request\_baserequest.py", line 385, in _request_wrapper
    raise Conflict(message)
telegram.error.Conflict: Conflict: terminated by other getUpdates request; make sure that only one bot instance is running
2025-07-29 16:50:33,740 - apscheduler.executors.default - ERROR - Job "send_uptime_message (trigger: interval[0:00:01], next run at: 2025-07-29 16:50:34 EEST)" raised an exception
Traceback (most recent call last):
  File "C:\Users\Skeleton\PycharmProjects\Supp0rtBot\.venv\Lib\site-packages\apscheduler\executors\base.py", line 181, in run_coroutine_job
    retval = await job.func(*job.args, **job.kwargs)
             ^^^^^^^^^^^^^^^^^^^^^^^^^^^^^^^^^^^^^^^
  File "C:\Users\Skeleton\PycharmProjects\Supp0rtBot\TgBot3.py", line 2083, in send_uptime_message
    await context.bot.send_message(
          ~~~~~~~~~~~~~~~~~~~~~~~~^
        chat_id=ACTIVITY_CHECK_CHAT_ID,
        ^^^^^^^^^^^^^^^^^^^^^^^^^^^^^^^
        text=f"Бот активен уже {uptime_hours} часов"
        ^^^^^^^^^^^^^^^^^^^^^^^^^^^^^^^^^^^^^^^^^^^^
    )
    ^
TypeError: User.send_message() got an unexpected keyword argument 'chat_id'
2025-07-29 16:50:34,740 - apscheduler.executors.default - ERROR - Job "send_uptime_message (trigger: interval[0:00:01], next run at: 2025-07-29 16:50:35 EEST)" raised an exception
Traceback (most recent call last):
  File "C:\Users\Skeleton\PycharmProjects\Supp0rtBot\.venv\Lib\site-packages\apscheduler\executors\base.py", line 181, in run_coroutine_job
    retval = await job.func(*job.args, **job.kwargs)
             ^^^^^^^^^^^^^^^^^^^^^^^^^^^^^^^^^^^^^^^
  File "C:\Users\Skeleton\PycharmProjects\Supp0rtBot\TgBot3.py", line 2083, in send_uptime_message
    await context.bot.send_message(
          ~~~~~~~~~~~~~~~~~~~~~~~~^
        chat_id=ACTIVITY_CHECK_CHAT_ID,
        ^^^^^^^^^^^^^^^^^^^^^^^^^^^^^^^
        text=f"Бот активен уже {uptime_hours} часов"
        ^^^^^^^^^^^^^^^^^^^^^^^^^^^^^^^^^^^^^^^^^^^^
    )
    ^
TypeError: User.send_message() got an unexpected keyword argument 'chat_id'
2025-07-29 16:50:35,738 - apscheduler.executors.default - ERROR - Job "send_uptime_message (trigger: interval[0:00:01], next run at: 2025-07-29 16:50:36 EEST)" raised an exception
Traceback (most recent call last):
  File "C:\Users\Skeleton\PycharmProjects\Supp0rtBot\.venv\Lib\site-packages\apscheduler\executors\base.py", line 181, in run_coroutine_job
    retval = await job.func(*job.args, **job.kwargs)
             ^^^^^^^^^^^^^^^^^^^^^^^^^^^^^^^^^^^^^^^
  File "C:\Users\Skeleton\PycharmProjects\Supp0rtBot\TgBot3.py", line 2083, in send_uptime_message
    await context.bot.send_message(
          ~~~~~~~~~~~~~~~~~~~~~~~~^
        chat_id=ACTIVITY_CHECK_CHAT_ID,
        ^^^^^^^^^^^^^^^^^^^^^^^^^^^^^^^
        text=f"Бот активен уже {uptime_hours} часов"
        ^^^^^^^^^^^^^^^^^^^^^^^^^^^^^^^^^^^^^^^^^^^^
    )
    ^
TypeError: User.send_message() got an unexpected keyword argument 'chat_id'
2025-07-29 16:50:36,750 - apscheduler.executors.default - ERROR - Job "send_uptime_message (trigger: interval[0:00:01], next run at: 2025-07-29 16:50:37 EEST)" raised an exception
Traceback (most recent call last):
  File "C:\Users\Skeleton\PycharmProjects\Supp0rtBot\.venv\Lib\site-packages\apscheduler\executors\base.py", line 181, in run_coroutine_job
    retval = await job.func(*job.args, **job.kwargs)
             ^^^^^^^^^^^^^^^^^^^^^^^^^^^^^^^^^^^^^^^
  File "C:\Users\Skeleton\PycharmProjects\Supp0rtBot\TgBot3.py", line 2083, in send_uptime_message
    await context.bot.send_message(
          ~~~~~~~~~~~~~~~~~~~~~~~~^
        chat_id=ACTIVITY_CHECK_CHAT_ID,
        ^^^^^^^^^^^^^^^^^^^^^^^^^^^^^^^
        text=f"Бот активен уже {uptime_hours} часов"
        ^^^^^^^^^^^^^^^^^^^^^^^^^^^^^^^^^^^^^^^^^^^^
    )
    ^
TypeError: User.send_message() got an unexpected keyword argument 'chat_id'
2025-07-29 16:50:37,748 - apscheduler.executors.default - ERROR - Job "send_uptime_message (trigger: interval[0:00:01], next run at: 2025-07-29 16:50:38 EEST)" raised an exception
Traceback (most recent call last):
  File "C:\Users\Skeleton\PycharmProjects\Supp0rtBot\.venv\Lib\site-packages\apscheduler\executors\base.py", line 181, in run_coroutine_job
    retval = await job.func(*job.args, **job.kwargs)
             ^^^^^^^^^^^^^^^^^^^^^^^^^^^^^^^^^^^^^^^
  File "C:\Users\Skeleton\PycharmProjects\Supp0rtBot\TgBot3.py", line 2083, in send_uptime_message
    await context.bot.send_message(
          ~~~~~~~~~~~~~~~~~~~~~~~~^
        chat_id=ACTIVITY_CHECK_CHAT_ID,
        ^^^^^^^^^^^^^^^^^^^^^^^^^^^^^^^
        text=f"Бот активен уже {uptime_hours} часов"
        ^^^^^^^^^^^^^^^^^^^^^^^^^^^^^^^^^^^^^^^^^^^^
    )
    ^
TypeError: User.send_message() got an unexpected keyword argument 'chat_id'
2025-07-29 16:50:38,743 - apscheduler.executors.default - ERROR - Job "send_uptime_message (trigger: interval[0:00:01], next run at: 2025-07-29 16:50:39 EEST)" raised an exception
Traceback (most recent call last):
  File "C:\Users\Skeleton\PycharmProjects\Supp0rtBot\.venv\Lib\site-packages\apscheduler\executors\base.py", line 181, in run_coroutine_job
    retval = await job.func(*job.args, **job.kwargs)
             ^^^^^^^^^^^^^^^^^^^^^^^^^^^^^^^^^^^^^^^
  File "C:\Users\Skeleton\PycharmProjects\Supp0rtBot\TgBot3.py", line 2083, in send_uptime_message
    await context.bot.send_message(
          ~~~~~~~~~~~~~~~~~~~~~~~~^
        chat_id=ACTIVITY_CHECK_CHAT_ID,
        ^^^^^^^^^^^^^^^^^^^^^^^^^^^^^^^
        text=f"Бот активен уже {uptime_hours} часов"
        ^^^^^^^^^^^^^^^^^^^^^^^^^^^^^^^^^^^^^^^^^^^^
    )
    ^
TypeError: User.send_message() got an unexpected keyword argument 'chat_id'
2025-07-29 16:50:38,971 - telegram.ext.Application - ERROR - No error handlers are registered, logging exception.
Traceback (most recent call last):
  File "C:\Users\Skeleton\PycharmProjects\Supp0rtBot\.venv\Lib\site-packages\telegram\ext\_updater.py", line 750, in _network_loop_retry
    if not await do_action():
           ^^^^^^^^^^^^^^^^^
  File "C:\Users\Skeleton\PycharmProjects\Supp0rtBot\.venv\Lib\site-packages\telegram\ext\_updater.py", line 744, in do_action
    return action_cb_task.result()
           ~~~~~~~~~~~~~~~~~~~~~^^
  File "C:\Program Files\Python313\Lib\asyncio\futures.py", line 199, in result
    raise self._exception.with_traceback(self._exception_tb)
  File "C:\Program Files\Python313\Lib\asyncio\tasks.py", line 304, in __step_run_and_handle_result
    result = coro.send(None)
  File "C:\Users\Skeleton\PycharmProjects\Supp0rtBot\.venv\Lib\site-packages\telegram\ext\_updater.py", line 371, in polling_action_cb
    updates = await self.bot.get_updates(
              ^^^^^^^^^^^^^^^^^^^^^^^^^^^
    ...<7 lines>...
    )
    ^
  File "C:\Users\Skeleton\PycharmProjects\Supp0rtBot\.venv\Lib\site-packages\telegram\ext\_extbot.py", line 650, in get_updates
    updates = await super().get_updates(
              ^^^^^^^^^^^^^^^^^^^^^^^^^^
    ...<9 lines>...
    )
    ^
  File "C:\Users\Skeleton\PycharmProjects\Supp0rtBot\.venv\Lib\site-packages\telegram\_bot.py", line 4480, in get_updates
    await self._post(
    ^^^^^^^^^^^^^^^^^
    ...<7 lines>...
    ),
    ^
  File "C:\Users\Skeleton\PycharmProjects\Supp0rtBot\.venv\Lib\site-packages\telegram\_bot.py", line 619, in _post
    return await self._do_post(
           ^^^^^^^^^^^^^^^^^^^^
    ...<6 lines>...
    )
    ^
  File "C:\Users\Skeleton\PycharmProjects\Supp0rtBot\.venv\Lib\site-packages\telegram\ext\_extbot.py", line 354, in _do_post
    return await super()._do_post(
           ^^^^^^^^^^^^^^^^^^^^^^^
    ...<6 lines>...
    )
    ^
  File "C:\Users\Skeleton\PycharmProjects\Supp0rtBot\.venv\Lib\site-packages\telegram\_bot.py", line 648, in _do_post
    result = await request.post(
             ^^^^^^^^^^^^^^^^^^^
    ...<6 lines>...
    )
    ^
  File "C:\Users\Skeleton\PycharmProjects\Supp0rtBot\.venv\Lib\site-packages\telegram\request\_baserequest.py", line 202, in post
    result = await self._request_wrapper(
             ^^^^^^^^^^^^^^^^^^^^^^^^^^^^
    ...<7 lines>...
    )
    ^
  File "C:\Users\Skeleton\PycharmProjects\Supp0rtBot\.venv\Lib\site-packages\telegram\request\_baserequest.py", line 385, in _request_wrapper
    raise Conflict(message)
telegram.error.Conflict: Conflict: terminated by other getUpdates request; make sure that only one bot instance is running
2025-07-29 16:50:39,753 - apscheduler.executors.default - ERROR - Job "send_uptime_message (trigger: interval[0:00:01], next run at: 2025-07-29 16:50:40 EEST)" raised an exception
Traceback (most recent call last):
  File "C:\Users\Skeleton\PycharmProjects\Supp0rtBot\.venv\Lib\site-packages\apscheduler\executors\base.py", line 181, in run_coroutine_job
    retval = await job.func(*job.args, **job.kwargs)
             ^^^^^^^^^^^^^^^^^^^^^^^^^^^^^^^^^^^^^^^
  File "C:\Users\Skeleton\PycharmProjects\Supp0rtBot\TgBot3.py", line 2083, in send_uptime_message
    await context.bot.send_message(
          ~~~~~~~~~~~~~~~~~~~~~~~~^
        chat_id=ACTIVITY_CHECK_CHAT_ID,
        ^^^^^^^^^^^^^^^^^^^^^^^^^^^^^^^
        text=f"Бот активен уже {uptime_hours} часов"
        ^^^^^^^^^^^^^^^^^^^^^^^^^^^^^^^^^^^^^^^^^^^^
    )
    ^
TypeError: User.send_message() got an unexpected keyword argument 'chat_id'
2025-07-29 16:50:40,748 - apscheduler.executors.default - ERROR - Job "send_uptime_message (trigger: interval[0:00:01], next run at: 2025-07-29 16:50:41 EEST)" raised an exception
Traceback (most recent call last):
  File "C:\Users\Skeleton\PycharmProjects\Supp0rtBot\.venv\Lib\site-packages\apscheduler\executors\base.py", line 181, in run_coroutine_job
    retval = await job.func(*job.args, **job.kwargs)
             ^^^^^^^^^^^^^^^^^^^^^^^^^^^^^^^^^^^^^^^
  File "C:\Users\Skeleton\PycharmProjects\Supp0rtBot\TgBot3.py", line 2083, in send_uptime_message
    await context.bot.send_message(
          ~~~~~~~~~~~~~~~~~~~~~~~~^
        chat_id=ACTIVITY_CHECK_CHAT_ID,
        ^^^^^^^^^^^^^^^^^^^^^^^^^^^^^^^
        text=f"Бот активен уже {uptime_hours} часов"
        ^^^^^^^^^^^^^^^^^^^^^^^^^^^^^^^^^^^^^^^^^^^^
    )
    ^
TypeError: User.send_message() got an unexpected keyword argument 'chat_id'
2025-07-29 16:50:41,742 - apscheduler.executors.default - ERROR - Job "send_uptime_message (trigger: interval[0:00:01], next run at: 2025-07-29 16:50:42 EEST)" raised an exception
Traceback (most recent call last):
  File "C:\Users\Skeleton\PycharmProjects\Supp0rtBot\.venv\Lib\site-packages\apscheduler\executors\base.py", line 181, in run_coroutine_job
    retval = await job.func(*job.args, **job.kwargs)
             ^^^^^^^^^^^^^^^^^^^^^^^^^^^^^^^^^^^^^^^
  File "C:\Users\Skeleton\PycharmProjects\Supp0rtBot\TgBot3.py", line 2083, in send_uptime_message
    await context.bot.send_message(
          ~~~~~~~~~~~~~~~~~~~~~~~~^
        chat_id=ACTIVITY_CHECK_CHAT_ID,
        ^^^^^^^^^^^^^^^^^^^^^^^^^^^^^^^
        text=f"Бот активен уже {uptime_hours} часов"
        ^^^^^^^^^^^^^^^^^^^^^^^^^^^^^^^^^^^^^^^^^^^^
    )
    ^
TypeError: User.send_message() got an unexpected keyword argument 'chat_id'
2025-07-29 16:50:42,752 - apscheduler.executors.default - ERROR - Job "send_uptime_message (trigger: interval[0:00:01], next run at: 2025-07-29 16:50:43 EEST)" raised an exception
Traceback (most recent call last):
  File "C:\Users\Skeleton\PycharmProjects\Supp0rtBot\.venv\Lib\site-packages\apscheduler\executors\base.py", line 181, in run_coroutine_job
    retval = await job.func(*job.args, **job.kwargs)
             ^^^^^^^^^^^^^^^^^^^^^^^^^^^^^^^^^^^^^^^
  File "C:\Users\Skeleton\PycharmProjects\Supp0rtBot\TgBot3.py", line 2083, in send_uptime_message
    await context.bot.send_message(
          ~~~~~~~~~~~~~~~~~~~~~~~~^
        chat_id=ACTIVITY_CHECK_CHAT_ID,
        ^^^^^^^^^^^^^^^^^^^^^^^^^^^^^^^
        text=f"Бот активен уже {uptime_hours} часов"
        ^^^^^^^^^^^^^^^^^^^^^^^^^^^^^^^^^^^^^^^^^^^^
    )
    ^
TypeError: User.send_message() got an unexpected keyword argument 'chat_id'
2025-07-29 16:50:43,744 - apscheduler.executors.default - ERROR - Job "send_uptime_message (trigger: interval[0:00:01], next run at: 2025-07-29 16:50:44 EEST)" raised an exception
Traceback (most recent call last):
  File "C:\Users\Skeleton\PycharmProjects\Supp0rtBot\.venv\Lib\site-packages\apscheduler\executors\base.py", line 181, in run_coroutine_job
    retval = await job.func(*job.args, **job.kwargs)
             ^^^^^^^^^^^^^^^^^^^^^^^^^^^^^^^^^^^^^^^
  File "C:\Users\Skeleton\PycharmProjects\Supp0rtBot\TgBot3.py", line 2083, in send_uptime_message
    await context.bot.send_message(
          ~~~~~~~~~~~~~~~~~~~~~~~~^
        chat_id=ACTIVITY_CHECK_CHAT_ID,
        ^^^^^^^^^^^^^^^^^^^^^^^^^^^^^^^
        text=f"Бот активен уже {uptime_hours} часов"
        ^^^^^^^^^^^^^^^^^^^^^^^^^^^^^^^^^^^^^^^^^^^^
    )
    ^
TypeError: User.send_message() got an unexpected keyword argument 'chat_id'
2025-07-29 16:50:44,747 - apscheduler.executors.default - ERROR - Job "send_uptime_message (trigger: interval[0:00:01], next run at: 2025-07-29 16:50:45 EEST)" raised an exception
Traceback (most recent call last):
  File "C:\Users\Skeleton\PycharmProjects\Supp0rtBot\.venv\Lib\site-packages\apscheduler\executors\base.py", line 181, in run_coroutine_job
    retval = await job.func(*job.args, **job.kwargs)
             ^^^^^^^^^^^^^^^^^^^^^^^^^^^^^^^^^^^^^^^
  File "C:\Users\Skeleton\PycharmProjects\Supp0rtBot\TgBot3.py", line 2083, in send_uptime_message
    await context.bot.send_message(
          ~~~~~~~~~~~~~~~~~~~~~~~~^
        chat_id=ACTIVITY_CHECK_CHAT_ID,
        ^^^^^^^^^^^^^^^^^^^^^^^^^^^^^^^
        text=f"Бот активен уже {uptime_hours} часов"
        ^^^^^^^^^^^^^^^^^^^^^^^^^^^^^^^^^^^^^^^^^^^^
    )
    ^
TypeError: User.send_message() got an unexpected keyword argument 'chat_id'
2025-07-29 16:50:45,735 - apscheduler.executors.default - ERROR - Job "send_uptime_message (trigger: interval[0:00:01], next run at: 2025-07-29 16:50:46 EEST)" raised an exception
Traceback (most recent call last):
  File "C:\Users\Skeleton\PycharmProjects\Supp0rtBot\.venv\Lib\site-packages\apscheduler\executors\base.py", line 181, in run_coroutine_job
    retval = await job.func(*job.args, **job.kwargs)
             ^^^^^^^^^^^^^^^^^^^^^^^^^^^^^^^^^^^^^^^
  File "C:\Users\Skeleton\PycharmProjects\Supp0rtBot\TgBot3.py", line 2083, in send_uptime_message
    await context.bot.send_message(
          ~~~~~~~~~~~~~~~~~~~~~~~~^
        chat_id=ACTIVITY_CHECK_CHAT_ID,
        ^^^^^^^^^^^^^^^^^^^^^^^^^^^^^^^
        text=f"Бот активен уже {uptime_hours} часов"
        ^^^^^^^^^^^^^^^^^^^^^^^^^^^^^^^^^^^^^^^^^^^^
    )
    ^
TypeError: User.send_message() got an unexpected keyword argument 'chat_id'
2025-07-29 16:50:46,695 - telegram.ext.Application - ERROR - No error handlers are registered, logging exception.
Traceback (most recent call last):
  File "C:\Users\Skeleton\PycharmProjects\Supp0rtBot\.venv\Lib\site-packages\telegram\ext\_updater.py", line 750, in _network_loop_retry
    if not await do_action():
           ^^^^^^^^^^^^^^^^^
  File "C:\Users\Skeleton\PycharmProjects\Supp0rtBot\.venv\Lib\site-packages\telegram\ext\_updater.py", line 744, in do_action
    return action_cb_task.result()
           ~~~~~~~~~~~~~~~~~~~~~^^
  File "C:\Program Files\Python313\Lib\asyncio\futures.py", line 199, in result
    raise self._exception.with_traceback(self._exception_tb)
  File "C:\Program Files\Python313\Lib\asyncio\tasks.py", line 304, in __step_run_and_handle_result
    result = coro.send(None)
  File "C:\Users\Skeleton\PycharmProjects\Supp0rtBot\.venv\Lib\site-packages\telegram\ext\_updater.py", line 371, in polling_action_cb
    updates = await self.bot.get_updates(
              ^^^^^^^^^^^^^^^^^^^^^^^^^^^
    ...<7 lines>...
    )
    ^
  File "C:\Users\Skeleton\PycharmProjects\Supp0rtBot\.venv\Lib\site-packages\telegram\ext\_extbot.py", line 650, in get_updates
    updates = await super().get_updates(
              ^^^^^^^^^^^^^^^^^^^^^^^^^^
    ...<9 lines>...
    )
    ^
  File "C:\Users\Skeleton\PycharmProjects\Supp0rtBot\.venv\Lib\site-packages\telegram\_bot.py", line 4480, in get_updates
    await self._post(
    ^^^^^^^^^^^^^^^^^
    ...<7 lines>...
    ),
    ^
  File "C:\Users\Skeleton\PycharmProjects\Supp0rtBot\.venv\Lib\site-packages\telegram\_bot.py", line 619, in _post
    return await self._do_post(
           ^^^^^^^^^^^^^^^^^^^^
    ...<6 lines>...
    )
    ^
  File "C:\Users\Skeleton\PycharmProjects\Supp0rtBot\.venv\Lib\site-packages\telegram\ext\_extbot.py", line 354, in _do_post
    return await super()._do_post(
           ^^^^^^^^^^^^^^^^^^^^^^^
    ...<6 lines>...
    )
    ^
  File "C:\Users\Skeleton\PycharmProjects\Supp0rtBot\.venv\Lib\site-packages\telegram\_bot.py", line 648, in _do_post
    result = await request.post(
             ^^^^^^^^^^^^^^^^^^^
    ...<6 lines>...
    )
    ^
  File "C:\Users\Skeleton\PycharmProjects\Supp0rtBot\.venv\Lib\site-packages\telegram\request\_baserequest.py", line 202, in post
    result = await self._request_wrapper(
             ^^^^^^^^^^^^^^^^^^^^^^^^^^^^
    ...<7 lines>...
    )
    ^
  File "C:\Users\Skeleton\PycharmProjects\Supp0rtBot\.venv\Lib\site-packages\telegram\request\_baserequest.py", line 385, in _request_wrapper
    raise Conflict(message)
telegram.error.Conflict: Conflict: terminated by other getUpdates request; make sure that only one bot instance is running
2025-07-29 16:50:46,738 - apscheduler.executors.default - ERROR - Job "send_uptime_message (trigger: interval[0:00:01], next run at: 2025-07-29 16:50:47 EEST)" raised an exception
Traceback (most recent call last):
  File "C:\Users\Skeleton\PycharmProjects\Supp0rtBot\.venv\Lib\site-packages\apscheduler\executors\base.py", line 181, in run_coroutine_job
    retval = await job.func(*job.args, **job.kwargs)
             ^^^^^^^^^^^^^^^^^^^^^^^^^^^^^^^^^^^^^^^
  File "C:\Users\Skeleton\PycharmProjects\Supp0rtBot\TgBot3.py", line 2083, in send_uptime_message
    await context.bot.send_message(
          ~~~~~~~~~~~~~~~~~~~~~~~~^
        chat_id=ACTIVITY_CHECK_CHAT_ID,
        ^^^^^^^^^^^^^^^^^^^^^^^^^^^^^^^
        text=f"Бот активен уже {uptime_hours} часов"
        ^^^^^^^^^^^^^^^^^^^^^^^^^^^^^^^^^^^^^^^^^^^^
    )
    ^
TypeError: User.send_message() got an unexpected keyword argument 'chat_id'
2025-07-29 16:50:47,743 - apscheduler.executors.default - ERROR - Job "send_uptime_message (trigger: interval[0:00:01], next run at: 2025-07-29 16:50:48 EEST)" raised an exception
Traceback (most recent call last):
  File "C:\Users\Skeleton\PycharmProjects\Supp0rtBot\.venv\Lib\site-packages\apscheduler\executors\base.py", line 181, in run_coroutine_job
    retval = await job.func(*job.args, **job.kwargs)
             ^^^^^^^^^^^^^^^^^^^^^^^^^^^^^^^^^^^^^^^
  File "C:\Users\Skeleton\PycharmProjects\Supp0rtBot\TgBot3.py", line 2083, in send_uptime_message
    await context.bot.send_message(
          ~~~~~~~~~~~~~~~~~~~~~~~~^
        chat_id=ACTIVITY_CHECK_CHAT_ID,
        ^^^^^^^^^^^^^^^^^^^^^^^^^^^^^^^
        text=f"Бот активен уже {uptime_hours} часов"
        ^^^^^^^^^^^^^^^^^^^^^^^^^^^^^^^^^^^^^^^^^^^^
    )
    ^
TypeError: User.send_message() got an unexpected keyword argument 'chat_id'
2025-07-29 16:50:48,753 - apscheduler.executors.default - ERROR - Job "send_uptime_message (trigger: interval[0:00:01], next run at: 2025-07-29 16:50:49 EEST)" raised an exception
Traceback (most recent call last):
  File "C:\Users\Skeleton\PycharmProjects\Supp0rtBot\.venv\Lib\site-packages\apscheduler\executors\base.py", line 181, in run_coroutine_job
    retval = await job.func(*job.args, **job.kwargs)
             ^^^^^^^^^^^^^^^^^^^^^^^^^^^^^^^^^^^^^^^
  File "C:\Users\Skeleton\PycharmProjects\Supp0rtBot\TgBot3.py", line 2083, in send_uptime_message
    await context.bot.send_message(
          ~~~~~~~~~~~~~~~~~~~~~~~~^
        chat_id=ACTIVITY_CHECK_CHAT_ID,
        ^^^^^^^^^^^^^^^^^^^^^^^^^^^^^^^
        text=f"Бот активен уже {uptime_hours} часов"
        ^^^^^^^^^^^^^^^^^^^^^^^^^^^^^^^^^^^^^^^^^^^^
    )
    ^
TypeError: User.send_message() got an unexpected keyword argument 'chat_id'
2025-07-29 16:50:49,746 - apscheduler.executors.default - ERROR - Job "send_uptime_message (trigger: interval[0:00:01], next run at: 2025-07-29 16:50:50 EEST)" raised an exception
Traceback (most recent call last):
  File "C:\Users\Skeleton\PycharmProjects\Supp0rtBot\.venv\Lib\site-packages\apscheduler\executors\base.py", line 181, in run_coroutine_job
    retval = await job.func(*job.args, **job.kwargs)
             ^^^^^^^^^^^^^^^^^^^^^^^^^^^^^^^^^^^^^^^
  File "C:\Users\Skeleton\PycharmProjects\Supp0rtBot\TgBot3.py", line 2083, in send_uptime_message
    await context.bot.send_message(
          ~~~~~~~~~~~~~~~~~~~~~~~~^
        chat_id=ACTIVITY_CHECK_CHAT_ID,
        ^^^^^^^^^^^^^^^^^^^^^^^^^^^^^^^
        text=f"Бот активен уже {uptime_hours} часов"
        ^^^^^^^^^^^^^^^^^^^^^^^^^^^^^^^^^^^^^^^^^^^^
    )
    ^
TypeError: User.send_message() got an unexpected keyword argument 'chat_id'
2025-07-29 16:50:50,746 - apscheduler.executors.default - ERROR - Job "send_uptime_message (trigger: interval[0:00:01], next run at: 2025-07-29 16:50:51 EEST)" raised an exception
Traceback (most recent call last):
  File "C:\Users\Skeleton\PycharmProjects\Supp0rtBot\.venv\Lib\site-packages\apscheduler\executors\base.py", line 181, in run_coroutine_job
    retval = await job.func(*job.args, **job.kwargs)
             ^^^^^^^^^^^^^^^^^^^^^^^^^^^^^^^^^^^^^^^
  File "C:\Users\Skeleton\PycharmProjects\Supp0rtBot\TgBot3.py", line 2083, in send_uptime_message
    await context.bot.send_message(
          ~~~~~~~~~~~~~~~~~~~~~~~~^
        chat_id=ACTIVITY_CHECK_CHAT_ID,
        ^^^^^^^^^^^^^^^^^^^^^^^^^^^^^^^
        text=f"Бот активен уже {uptime_hours} часов"
        ^^^^^^^^^^^^^^^^^^^^^^^^^^^^^^^^^^^^^^^^^^^^
    )
    ^
TypeError: User.send_message() got an unexpected keyword argument 'chat_id'
2025-07-29 16:50:51,741 - apscheduler.executors.default - ERROR - Job "send_uptime_message (trigger: interval[0:00:01], next run at: 2025-07-29 16:50:52 EEST)" raised an exception
Traceback (most recent call last):
  File "C:\Users\Skeleton\PycharmProjects\Supp0rtBot\.venv\Lib\site-packages\apscheduler\executors\base.py", line 181, in run_coroutine_job
    retval = await job.func(*job.args, **job.kwargs)
             ^^^^^^^^^^^^^^^^^^^^^^^^^^^^^^^^^^^^^^^
  File "C:\Users\Skeleton\PycharmProjects\Supp0rtBot\TgBot3.py", line 2083, in send_uptime_message
    await context.bot.send_message(
          ~~~~~~~~~~~~~~~~~~~~~~~~^
        chat_id=ACTIVITY_CHECK_CHAT_ID,
        ^^^^^^^^^^^^^^^^^^^^^^^^^^^^^^^
        text=f"Бот активен уже {uptime_hours} часов"
        ^^^^^^^^^^^^^^^^^^^^^^^^^^^^^^^^^^^^^^^^^^^^
    )
    ^
TypeError: User.send_message() got an unexpected keyword argument 'chat_id'
2025-07-29 16:50:52,747 - apscheduler.executors.default - ERROR - Job "send_uptime_message (trigger: interval[0:00:01], next run at: 2025-07-29 16:50:53 EEST)" raised an exception
Traceback (most recent call last):
  File "C:\Users\Skeleton\PycharmProjects\Supp0rtBot\.venv\Lib\site-packages\apscheduler\executors\base.py", line 181, in run_coroutine_job
    retval = await job.func(*job.args, **job.kwargs)
             ^^^^^^^^^^^^^^^^^^^^^^^^^^^^^^^^^^^^^^^
  File "C:\Users\Skeleton\PycharmProjects\Supp0rtBot\TgBot3.py", line 2083, in send_uptime_message
    await context.bot.send_message(
          ~~~~~~~~~~~~~~~~~~~~~~~~^
        chat_id=ACTIVITY_CHECK_CHAT_ID,
        ^^^^^^^^^^^^^^^^^^^^^^^^^^^^^^^
        text=f"Бот активен уже {uptime_hours} часов"
        ^^^^^^^^^^^^^^^^^^^^^^^^^^^^^^^^^^^^^^^^^^^^
    )
    ^
TypeError: User.send_message() got an unexpected keyword argument 'chat_id'
2025-07-29 16:50:53,686 - telegram.ext.Application - ERROR - No error handlers are registered, logging exception.
Traceback (most recent call last):
  File "C:\Users\Skeleton\PycharmProjects\Supp0rtBot\.venv\Lib\site-packages\telegram\ext\_updater.py", line 750, in _network_loop_retry
    if not await do_action():
           ^^^^^^^^^^^^^^^^^
  File "C:\Users\Skeleton\PycharmProjects\Supp0rtBot\.venv\Lib\site-packages\telegram\ext\_updater.py", line 744, in do_action
    return action_cb_task.result()
           ~~~~~~~~~~~~~~~~~~~~~^^
  File "C:\Program Files\Python313\Lib\asyncio\futures.py", line 199, in result
    raise self._exception.with_traceback(self._exception_tb)
  File "C:\Program Files\Python313\Lib\asyncio\tasks.py", line 304, in __step_run_and_handle_result
    result = coro.send(None)
  File "C:\Users\Skeleton\PycharmProjects\Supp0rtBot\.venv\Lib\site-packages\telegram\ext\_updater.py", line 371, in polling_action_cb
    updates = await self.bot.get_updates(
              ^^^^^^^^^^^^^^^^^^^^^^^^^^^
    ...<7 lines>...
    )
    ^
  File "C:\Users\Skeleton\PycharmProjects\Supp0rtBot\.venv\Lib\site-packages\telegram\ext\_extbot.py", line 650, in get_updates
    updates = await super().get_updates(
              ^^^^^^^^^^^^^^^^^^^^^^^^^^
    ...<9 lines>...
    )
    ^
  File "C:\Users\Skeleton\PycharmProjects\Supp0rtBot\.venv\Lib\site-packages\telegram\_bot.py", line 4480, in get_updates
    await self._post(
    ^^^^^^^^^^^^^^^^^
    ...<7 lines>...
    ),
    ^
  File "C:\Users\Skeleton\PycharmProjects\Supp0rtBot\.venv\Lib\site-packages\telegram\_bot.py", line 619, in _post
    return await self._do_post(
           ^^^^^^^^^^^^^^^^^^^^
    ...<6 lines>...
    )
    ^
  File "C:\Users\Skeleton\PycharmProjects\Supp0rtBot\.venv\Lib\site-packages\telegram\ext\_extbot.py", line 354, in _do_post
    return await super()._do_post(
           ^^^^^^^^^^^^^^^^^^^^^^^
    ...<6 lines>...
    )
    ^
  File "C:\Users\Skeleton\PycharmProjects\Supp0rtBot\.venv\Lib\site-packages\telegram\_bot.py", line 648, in _do_post
    result = await request.post(
             ^^^^^^^^^^^^^^^^^^^
    ...<6 lines>...
    )
    ^
  File "C:\Users\Skeleton\PycharmProjects\Supp0rtBot\.venv\Lib\site-packages\telegram\request\_baserequest.py", line 202, in post
    result = await self._request_wrapper(
             ^^^^^^^^^^^^^^^^^^^^^^^^^^^^
    ...<7 lines>...
    )
    ^
  File "C:\Users\Skeleton\PycharmProjects\Supp0rtBot\.venv\Lib\site-packages\telegram\request\_baserequest.py", line 385, in _request_wrapper
    raise Conflict(message)
telegram.error.Conflict: Conflict: terminated by other getUpdates request; make sure that only one bot instance is running
2025-07-29 16:50:53,747 - apscheduler.executors.default - ERROR - Job "send_uptime_message (trigger: interval[0:00:01], next run at: 2025-07-29 16:50:54 EEST)" raised an exception
Traceback (most recent call last):
  File "C:\Users\Skeleton\PycharmProjects\Supp0rtBot\.venv\Lib\site-packages\apscheduler\executors\base.py", line 181, in run_coroutine_job
    retval = await job.func(*job.args, **job.kwargs)
             ^^^^^^^^^^^^^^^^^^^^^^^^^^^^^^^^^^^^^^^
  File "C:\Users\Skeleton\PycharmProjects\Supp0rtBot\TgBot3.py", line 2083, in send_uptime_message
    await context.bot.send_message(
          ~~~~~~~~~~~~~~~~~~~~~~~~^
        chat_id=ACTIVITY_CHECK_CHAT_ID,
        ^^^^^^^^^^^^^^^^^^^^^^^^^^^^^^^
        text=f"Бот активен уже {uptime_hours} часов"
        ^^^^^^^^^^^^^^^^^^^^^^^^^^^^^^^^^^^^^^^^^^^^
    )
    ^
TypeError: User.send_message() got an unexpected keyword argument 'chat_id'
2025-07-29 16:50:54,740 - apscheduler.executors.default - ERROR - Job "send_uptime_message (trigger: interval[0:00:01], next run at: 2025-07-29 16:50:55 EEST)" raised an exception
Traceback (most recent call last):
  File "C:\Users\Skeleton\PycharmProjects\Supp0rtBot\.venv\Lib\site-packages\apscheduler\executors\base.py", line 181, in run_coroutine_job
    retval = await job.func(*job.args, **job.kwargs)
             ^^^^^^^^^^^^^^^^^^^^^^^^^^^^^^^^^^^^^^^
  File "C:\Users\Skeleton\PycharmProjects\Supp0rtBot\TgBot3.py", line 2083, in send_uptime_message
    await context.bot.send_message(
          ~~~~~~~~~~~~~~~~~~~~~~~~^
        chat_id=ACTIVITY_CHECK_CHAT_ID,
        ^^^^^^^^^^^^^^^^^^^^^^^^^^^^^^^
        text=f"Бот активен уже {uptime_hours} часов"
        ^^^^^^^^^^^^^^^^^^^^^^^^^^^^^^^^^^^^^^^^^^^^
    )
    ^
TypeError: User.send_message() got an unexpected keyword argument 'chat_id'
2025-07-29 16:50:55,749 - apscheduler.executors.default - ERROR - Job "send_uptime_message (trigger: interval[0:00:01], next run at: 2025-07-29 16:50:56 EEST)" raised an exception
Traceback (most recent call last):
  File "C:\Users\Skeleton\PycharmProjects\Supp0rtBot\.venv\Lib\site-packages\apscheduler\executors\base.py", line 181, in run_coroutine_job
    retval = await job.func(*job.args, **job.kwargs)
             ^^^^^^^^^^^^^^^^^^^^^^^^^^^^^^^^^^^^^^^
  File "C:\Users\Skeleton\PycharmProjects\Supp0rtBot\TgBot3.py", line 2083, in send_uptime_message
    await context.bot.send_message(
          ~~~~~~~~~~~~~~~~~~~~~~~~^
        chat_id=ACTIVITY_CHECK_CHAT_ID,
        ^^^^^^^^^^^^^^^^^^^^^^^^^^^^^^^
        text=f"Бот активен уже {uptime_hours} часов"
        ^^^^^^^^^^^^^^^^^^^^^^^^^^^^^^^^^^^^^^^^^^^^
    )
    ^
TypeError: User.send_message() got an unexpected keyword argument 'chat_id'
2025-07-29 16:50:56,736 - apscheduler.executors.default - ERROR - Job "send_uptime_message (trigger: interval[0:00:01], next run at: 2025-07-29 16:50:57 EEST)" raised an exception
Traceback (most recent call last):
  File "C:\Users\Skeleton\PycharmProjects\Supp0rtBot\.venv\Lib\site-packages\apscheduler\executors\base.py", line 181, in run_coroutine_job
    retval = await job.func(*job.args, **job.kwargs)
             ^^^^^^^^^^^^^^^^^^^^^^^^^^^^^^^^^^^^^^^
  File "C:\Users\Skeleton\PycharmProjects\Supp0rtBot\TgBot3.py", line 2083, in send_uptime_message
    await context.bot.send_message(
          ~~~~~~~~~~~~~~~~~~~~~~~~^
        chat_id=ACTIVITY_CHECK_CHAT_ID,
        ^^^^^^^^^^^^^^^^^^^^^^^^^^^^^^^
        text=f"Бот активен уже {uptime_hours} часов"
        ^^^^^^^^^^^^^^^^^^^^^^^^^^^^^^^^^^^^^^^^^^^^
    )
    ^
TypeError: User.send_message() got an unexpected keyword argument 'chat_id'
2025-07-29 16:50:57,748 - apscheduler.executors.default - ERROR - Job "send_uptime_message (trigger: interval[0:00:01], next run at: 2025-07-29 16:50:58 EEST)" raised an exception
Traceback (most recent call last):
  File "C:\Users\Skeleton\PycharmProjects\Supp0rtBot\.venv\Lib\site-packages\apscheduler\executors\base.py", line 181, in run_coroutine_job
    retval = await job.func(*job.args, **job.kwargs)
             ^^^^^^^^^^^^^^^^^^^^^^^^^^^^^^^^^^^^^^^
  File "C:\Users\Skeleton\PycharmProjects\Supp0rtBot\TgBot3.py", line 2083, in send_uptime_message
    await context.bot.send_message(
          ~~~~~~~~~~~~~~~~~~~~~~~~^
        chat_id=ACTIVITY_CHECK_CHAT_ID,
        ^^^^^^^^^^^^^^^^^^^^^^^^^^^^^^^
        text=f"Бот активен уже {uptime_hours} часов"
        ^^^^^^^^^^^^^^^^^^^^^^^^^^^^^^^^^^^^^^^^^^^^
    )
    ^
TypeError: User.send_message() got an unexpected keyword argument 'chat_id'
2025-07-29 16:50:58,751 - apscheduler.executors.default - ERROR - Job "send_uptime_message (trigger: interval[0:00:01], next run at: 2025-07-29 16:50:59 EEST)" raised an exception
Traceback (most recent call last):
  File "C:\Users\Skeleton\PycharmProjects\Supp0rtBot\.venv\Lib\site-packages\apscheduler\executors\base.py", line 181, in run_coroutine_job
    retval = await job.func(*job.args, **job.kwargs)
             ^^^^^^^^^^^^^^^^^^^^^^^^^^^^^^^^^^^^^^^
  File "C:\Users\Skeleton\PycharmProjects\Supp0rtBot\TgBot3.py", line 2083, in send_uptime_message
    await context.bot.send_message(
          ~~~~~~~~~~~~~~~~~~~~~~~~^
        chat_id=ACTIVITY_CHECK_CHAT_ID,
        ^^^^^^^^^^^^^^^^^^^^^^^^^^^^^^^
        text=f"Бот активен уже {uptime_hours} часов"
        ^^^^^^^^^^^^^^^^^^^^^^^^^^^^^^^^^^^^^^^^^^^^
    )
    ^
TypeError: User.send_message() got an unexpected keyword argument 'chat_id'
2025-07-29 16:50:59,749 - apscheduler.executors.default - ERROR - Job "send_uptime_message (trigger: interval[0:00:01], next run at: 2025-07-29 16:51:00 EEST)" raised an exception
Traceback (most recent call last):
  File "C:\Users\Skeleton\PycharmProjects\Supp0rtBot\.venv\Lib\site-packages\apscheduler\executors\base.py", line 181, in run_coroutine_job
    retval = await job.func(*job.args, **job.kwargs)
             ^^^^^^^^^^^^^^^^^^^^^^^^^^^^^^^^^^^^^^^
  File "C:\Users\Skeleton\PycharmProjects\Supp0rtBot\TgBot3.py", line 2083, in send_uptime_message
    await context.bot.send_message(
          ~~~~~~~~~~~~~~~~~~~~~~~~^
        chat_id=ACTIVITY_CHECK_CHAT_ID,
        ^^^^^^^^^^^^^^^^^^^^^^^^^^^^^^^
        text=f"Бот активен уже {uptime_hours} часов"
        ^^^^^^^^^^^^^^^^^^^^^^^^^^^^^^^^^^^^^^^^^^^^
    )
    ^
TypeError: User.send_message() got an unexpected keyword argument 'chat_id'
2025-07-29 16:51:00,746 - apscheduler.executors.default - ERROR - Job "send_uptime_message (trigger: interval[0:00:01], next run at: 2025-07-29 16:51:01 EEST)" raised an exception
Traceback (most recent call last):
  File "C:\Users\Skeleton\PycharmProjects\Supp0rtBot\.venv\Lib\site-packages\apscheduler\executors\base.py", line 181, in run_coroutine_job
    retval = await job.func(*job.args, **job.kwargs)
             ^^^^^^^^^^^^^^^^^^^^^^^^^^^^^^^^^^^^^^^
  File "C:\Users\Skeleton\PycharmProjects\Supp0rtBot\TgBot3.py", line 2083, in send_uptime_message
    await context.bot.send_message(
          ~~~~~~~~~~~~~~~~~~~~~~~~^
        chat_id=ACTIVITY_CHECK_CHAT_ID,
        ^^^^^^^^^^^^^^^^^^^^^^^^^^^^^^^
        text=f"Бот активен уже {uptime_hours} часов"
        ^^^^^^^^^^^^^^^^^^^^^^^^^^^^^^^^^^^^^^^^^^^^
    )
    ^
TypeError: User.send_message() got an unexpected keyword argument 'chat_id'
2025-07-29 16:51:01,749 - apscheduler.executors.default - ERROR - Job "send_uptime_message (trigger: interval[0:00:01], next run at: 2025-07-29 16:51:02 EEST)" raised an exception
Traceback (most recent call last):
  File "C:\Users\Skeleton\PycharmProjects\Supp0rtBot\.venv\Lib\site-packages\apscheduler\executors\base.py", line 181, in run_coroutine_job
    retval = await job.func(*job.args, **job.kwargs)
             ^^^^^^^^^^^^^^^^^^^^^^^^^^^^^^^^^^^^^^^
  File "C:\Users\Skeleton\PycharmProjects\Supp0rtBot\TgBot3.py", line 2083, in send_uptime_message
    await context.bot.send_message(
          ~~~~~~~~~~~~~~~~~~~~~~~~^
        chat_id=ACTIVITY_CHECK_CHAT_ID,
        ^^^^^^^^^^^^^^^^^^^^^^^^^^^^^^^
        text=f"Бот активен уже {uptime_hours} часов"
        ^^^^^^^^^^^^^^^^^^^^^^^^^^^^^^^^^^^^^^^^^^^^
    )
    ^
TypeError: User.send_message() got an unexpected keyword argument 'chat_id'
2025-07-29 16:51:02,747 - apscheduler.executors.default - ERROR - Job "send_uptime_message (trigger: interval[0:00:01], next run at: 2025-07-29 16:51:03 EEST)" raised an exception
Traceback (most recent call last):
  File "C:\Users\Skeleton\PycharmProjects\Supp0rtBot\.venv\Lib\site-packages\apscheduler\executors\base.py", line 181, in run_coroutine_job
    retval = await job.func(*job.args, **job.kwargs)
             ^^^^^^^^^^^^^^^^^^^^^^^^^^^^^^^^^^^^^^^
  File "C:\Users\Skeleton\PycharmProjects\Supp0rtBot\TgBot3.py", line 2083, in send_uptime_message
    await context.bot.send_message(
          ~~~~~~~~~~~~~~~~~~~~~~~~^
        chat_id=ACTIVITY_CHECK_CHAT_ID,
        ^^^^^^^^^^^^^^^^^^^^^^^^^^^^^^^
        text=f"Бот активен уже {uptime_hours} часов"
        ^^^^^^^^^^^^^^^^^^^^^^^^^^^^^^^^^^^^^^^^^^^^
    )
    ^
TypeError: User.send_message() got an unexpected keyword argument 'chat_id'
2025-07-29 16:51:03,747 - apscheduler.executors.default - ERROR - Job "send_uptime_message (trigger: interval[0:00:01], next run at: 2025-07-29 16:51:04 EEST)" raised an exception
Traceback (most recent call last):
  File "C:\Users\Skeleton\PycharmProjects\Supp0rtBot\.venv\Lib\site-packages\apscheduler\executors\base.py", line 181, in run_coroutine_job
    retval = await job.func(*job.args, **job.kwargs)
             ^^^^^^^^^^^^^^^^^^^^^^^^^^^^^^^^^^^^^^^
  File "C:\Users\Skeleton\PycharmProjects\Supp0rtBot\TgBot3.py", line 2083, in send_uptime_message
    await context.bot.send_message(
          ~~~~~~~~~~~~~~~~~~~~~~~~^
        chat_id=ACTIVITY_CHECK_CHAT_ID,
        ^^^^^^^^^^^^^^^^^^^^^^^^^^^^^^^
        text=f"Бот активен уже {uptime_hours} часов"
        ^^^^^^^^^^^^^^^^^^^^^^^^^^^^^^^^^^^^^^^^^^^^
    )
    ^
TypeError: User.send_message() got an unexpected keyword argument 'chat_id'
2025-07-29 16:51:04,472 - telegram.ext.Application - ERROR - No error handlers are registered, logging exception.
Traceback (most recent call last):
  File "C:\Users\Skeleton\PycharmProjects\Supp0rtBot\.venv\Lib\site-packages\telegram\ext\_updater.py", line 750, in _network_loop_retry
    if not await do_action():
           ^^^^^^^^^^^^^^^^^
  File "C:\Users\Skeleton\PycharmProjects\Supp0rtBot\.venv\Lib\site-packages\telegram\ext\_updater.py", line 744, in do_action
    return action_cb_task.result()
           ~~~~~~~~~~~~~~~~~~~~~^^
  File "C:\Program Files\Python313\Lib\asyncio\futures.py", line 199, in result
    raise self._exception.with_traceback(self._exception_tb)
  File "C:\Program Files\Python313\Lib\asyncio\tasks.py", line 304, in __step_run_and_handle_result
    result = coro.send(None)
  File "C:\Users\Skeleton\PycharmProjects\Supp0rtBot\.venv\Lib\site-packages\telegram\ext\_updater.py", line 371, in polling_action_cb
    updates = await self.bot.get_updates(
              ^^^^^^^^^^^^^^^^^^^^^^^^^^^
    ...<7 lines>...
    )
    ^
  File "C:\Users\Skeleton\PycharmProjects\Supp0rtBot\.venv\Lib\site-packages\telegram\ext\_extbot.py", line 650, in get_updates
    updates = await super().get_updates(
              ^^^^^^^^^^^^^^^^^^^^^^^^^^
    ...<9 lines>...
    )
    ^
  File "C:\Users\Skeleton\PycharmProjects\Supp0rtBot\.venv\Lib\site-packages\telegram\_bot.py", line 4480, in get_updates
    await self._post(
    ^^^^^^^^^^^^^^^^^
    ...<7 lines>...
    ),
    ^
  File "C:\Users\Skeleton\PycharmProjects\Supp0rtBot\.venv\Lib\site-packages\telegram\_bot.py", line 619, in _post
    return await self._do_post(
           ^^^^^^^^^^^^^^^^^^^^
    ...<6 lines>...
    )
    ^
  File "C:\Users\Skeleton\PycharmProjects\Supp0rtBot\.venv\Lib\site-packages\telegram\ext\_extbot.py", line 354, in _do_post
    return await super()._do_post(
           ^^^^^^^^^^^^^^^^^^^^^^^
    ...<6 lines>...
    )
    ^
  File "C:\Users\Skeleton\PycharmProjects\Supp0rtBot\.venv\Lib\site-packages\telegram\_bot.py", line 648, in _do_post
    result = await request.post(
             ^^^^^^^^^^^^^^^^^^^
    ...<6 lines>...
    )
    ^
  File "C:\Users\Skeleton\PycharmProjects\Supp0rtBot\.venv\Lib\site-packages\telegram\request\_baserequest.py", line 202, in post
    result = await self._request_wrapper(
             ^^^^^^^^^^^^^^^^^^^^^^^^^^^^
    ...<7 lines>...
    )
    ^
  File "C:\Users\Skeleton\PycharmProjects\Supp0rtBot\.venv\Lib\site-packages\telegram\request\_baserequest.py", line 385, in _request_wrapper
    raise Conflict(message)
telegram.error.Conflict: Conflict: terminated by other getUpdates request; make sure that only one bot instance is running
2025-07-29 16:51:04,743 - apscheduler.executors.default - ERROR - Job "send_uptime_message (trigger: interval[0:00:01], next run at: 2025-07-29 16:51:05 EEST)" raised an exception
Traceback (most recent call last):
  File "C:\Users\Skeleton\PycharmProjects\Supp0rtBot\.venv\Lib\site-packages\apscheduler\executors\base.py", line 181, in run_coroutine_job
    retval = await job.func(*job.args, **job.kwargs)
             ^^^^^^^^^^^^^^^^^^^^^^^^^^^^^^^^^^^^^^^
  File "C:\Users\Skeleton\PycharmProjects\Supp0rtBot\TgBot3.py", line 2083, in send_uptime_message
    await context.bot.send_message(
          ~~~~~~~~~~~~~~~~~~~~~~~~^
        chat_id=ACTIVITY_CHECK_CHAT_ID,
        ^^^^^^^^^^^^^^^^^^^^^^^^^^^^^^^
        text=f"Бот активен уже {uptime_hours} часов"
        ^^^^^^^^^^^^^^^^^^^^^^^^^^^^^^^^^^^^^^^^^^^^
    )
    ^
TypeError: User.send_message() got an unexpected keyword argument 'chat_id'
2025-07-29 16:51:05,745 - apscheduler.executors.default - ERROR - Job "send_uptime_message (trigger: interval[0:00:01], next run at: 2025-07-29 16:51:06 EEST)" raised an exception
Traceback (most recent call last):
  File "C:\Users\Skeleton\PycharmProjects\Supp0rtBot\.venv\Lib\site-packages\apscheduler\executors\base.py", line 181, in run_coroutine_job
    retval = await job.func(*job.args, **job.kwargs)
             ^^^^^^^^^^^^^^^^^^^^^^^^^^^^^^^^^^^^^^^
  File "C:\Users\Skeleton\PycharmProjects\Supp0rtBot\TgBot3.py", line 2083, in send_uptime_message
    await context.bot.send_message(
          ~~~~~~~~~~~~~~~~~~~~~~~~^
        chat_id=ACTIVITY_CHECK_CHAT_ID,
        ^^^^^^^^^^^^^^^^^^^^^^^^^^^^^^^
        text=f"Бот активен уже {uptime_hours} часов"
        ^^^^^^^^^^^^^^^^^^^^^^^^^^^^^^^^^^^^^^^^^^^^
    )
    ^
TypeError: User.send_message() got an unexpected keyword argument 'chat_id'
2025-07-29 16:51:06,746 - apscheduler.executors.default - ERROR - Job "send_uptime_message (trigger: interval[0:00:01], next run at: 2025-07-29 16:51:07 EEST)" raised an exception
Traceback (most recent call last):
  File "C:\Users\Skeleton\PycharmProjects\Supp0rtBot\.venv\Lib\site-packages\apscheduler\executors\base.py", line 181, in run_coroutine_job
    retval = await job.func(*job.args, **job.kwargs)
             ^^^^^^^^^^^^^^^^^^^^^^^^^^^^^^^^^^^^^^^
  File "C:\Users\Skeleton\PycharmProjects\Supp0rtBot\TgBot3.py", line 2083, in send_uptime_message
    await context.bot.send_message(
          ~~~~~~~~~~~~~~~~~~~~~~~~^
        chat_id=ACTIVITY_CHECK_CHAT_ID,
        ^^^^^^^^^^^^^^^^^^^^^^^^^^^^^^^
        text=f"Бот активен уже {uptime_hours} часов"
        ^^^^^^^^^^^^^^^^^^^^^^^^^^^^^^^^^^^^^^^^^^^^
    )
    ^
TypeError: User.send_message() got an unexpected keyword argument 'chat_id'
2025-07-29 16:51:07,742 - apscheduler.executors.default - ERROR - Job "send_uptime_message (trigger: interval[0:00:01], next run at: 2025-07-29 16:51:08 EEST)" raised an exception
Traceback (most recent call last):
  File "C:\Users\Skeleton\PycharmProjects\Supp0rtBot\.venv\Lib\site-packages\apscheduler\executors\base.py", line 181, in run_coroutine_job
    retval = await job.func(*job.args, **job.kwargs)
             ^^^^^^^^^^^^^^^^^^^^^^^^^^^^^^^^^^^^^^^
  File "C:\Users\Skeleton\PycharmProjects\Supp0rtBot\TgBot3.py", line 2083, in send_uptime_message
    await context.bot.send_message(
          ~~~~~~~~~~~~~~~~~~~~~~~~^
        chat_id=ACTIVITY_CHECK_CHAT_ID,
        ^^^^^^^^^^^^^^^^^^^^^^^^^^^^^^^
        text=f"Бот активен уже {uptime_hours} часов"
        ^^^^^^^^^^^^^^^^^^^^^^^^^^^^^^^^^^^^^^^^^^^^
    )
    ^
TypeError: User.send_message() got an unexpected keyword argument 'chat_id'
2025-07-29 16:51:08,744 - apscheduler.executors.default - ERROR - Job "send_uptime_message (trigger: interval[0:00:01], next run at: 2025-07-29 16:51:09 EEST)" raised an exception
Traceback (most recent call last):
  File "C:\Users\Skeleton\PycharmProjects\Supp0rtBot\.venv\Lib\site-packages\apscheduler\executors\base.py", line 181, in run_coroutine_job
    retval = await job.func(*job.args, **job.kwargs)
             ^^^^^^^^^^^^^^^^^^^^^^^^^^^^^^^^^^^^^^^
  File "C:\Users\Skeleton\PycharmProjects\Supp0rtBot\TgBot3.py", line 2083, in send_uptime_message
    await context.bot.send_message(
          ~~~~~~~~~~~~~~~~~~~~~~~~^
        chat_id=ACTIVITY_CHECK_CHAT_ID,
        ^^^^^^^^^^^^^^^^^^^^^^^^^^^^^^^
        text=f"Бот активен уже {uptime_hours} часов"
        ^^^^^^^^^^^^^^^^^^^^^^^^^^^^^^^^^^^^^^^^^^^^
    )
    ^
TypeError: User.send_message() got an unexpected keyword argument 'chat_id'
2025-07-29 16:51:09,748 - apscheduler.executors.default - ERROR - Job "send_uptime_message (trigger: interval[0:00:01], next run at: 2025-07-29 16:51:10 EEST)" raised an exception
Traceback (most recent call last):
  File "C:\Users\Skeleton\PycharmProjects\Supp0rtBot\.venv\Lib\site-packages\apscheduler\executors\base.py", line 181, in run_coroutine_job
    retval = await job.func(*job.args, **job.kwargs)
             ^^^^^^^^^^^^^^^^^^^^^^^^^^^^^^^^^^^^^^^
  File "C:\Users\Skeleton\PycharmProjects\Supp0rtBot\TgBot3.py", line 2083, in send_uptime_message
    await context.bot.send_message(
          ~~~~~~~~~~~~~~~~~~~~~~~~^
        chat_id=ACTIVITY_CHECK_CHAT_ID,
        ^^^^^^^^^^^^^^^^^^^^^^^^^^^^^^^
        text=f"Бот активен уже {uptime_hours} часов"
        ^^^^^^^^^^^^^^^^^^^^^^^^^^^^^^^^^^^^^^^^^^^^
    )
    ^
TypeError: User.send_message() got an unexpected keyword argument 'chat_id'
2025-07-29 16:51:10,737 - apscheduler.executors.default - ERROR - Job "send_uptime_message (trigger: interval[0:00:01], next run at: 2025-07-29 16:51:11 EEST)" raised an exception
Traceback (most recent call last):
  File "C:\Users\Skeleton\PycharmProjects\Supp0rtBot\.venv\Lib\site-packages\apscheduler\executors\base.py", line 181, in run_coroutine_job
    retval = await job.func(*job.args, **job.kwargs)
             ^^^^^^^^^^^^^^^^^^^^^^^^^^^^^^^^^^^^^^^
  File "C:\Users\Skeleton\PycharmProjects\Supp0rtBot\TgBot3.py", line 2083, in send_uptime_message
    await context.bot.send_message(
          ~~~~~~~~~~~~~~~~~~~~~~~~^
        chat_id=ACTIVITY_CHECK_CHAT_ID,
        ^^^^^^^^^^^^^^^^^^^^^^^^^^^^^^^
        text=f"Бот активен уже {uptime_hours} часов"
        ^^^^^^^^^^^^^^^^^^^^^^^^^^^^^^^^^^^^^^^^^^^^
    )
    ^
TypeError: User.send_message() got an unexpected keyword argument 'chat_id'
2025-07-29 16:51:12,620 - apscheduler.executors.default - ERROR - Job "send_uptime_message (trigger: interval[0:00:01], next run at: 2025-07-29 16:51:12 EEST)" raised an exception
Traceback (most recent call last):
  File "C:\Users\Skeleton\PycharmProjects\Supp0rtBot\.venv\Lib\site-packages\apscheduler\executors\base.py", line 181, in run_coroutine_job
    retval = await job.func(*job.args, **job.kwargs)
             ^^^^^^^^^^^^^^^^^^^^^^^^^^^^^^^^^^^^^^^
  File "C:\Users\Skeleton\PycharmProjects\Supp0rtBot\TgBot3.py", line 2083, in send_uptime_message
    await context.bot.send_message(
          ~~~~~~~~~~~~~~~~~~~~~~~~^
        chat_id=ACTIVITY_CHECK_CHAT_ID,
        ^^^^^^^^^^^^^^^^^^^^^^^^^^^^^^^
        text=f"Бот активен уже {uptime_hours} часов"
        ^^^^^^^^^^^^^^^^^^^^^^^^^^^^^^^^^^^^^^^^^^^^
    )
    ^
TypeError: User.send_message() got an unexpected keyword argument 'chat_id'
2025-07-29 16:51:12,741 - apscheduler.executors.default - ERROR - Job "send_uptime_message (trigger: interval[0:00:01], next run at: 2025-07-29 16:51:13 EEST)" raised an exception
Traceback (most recent call last):
  File "C:\Users\Skeleton\PycharmProjects\Supp0rtBot\.venv\Lib\site-packages\apscheduler\executors\base.py", line 181, in run_coroutine_job
    retval = await job.func(*job.args, **job.kwargs)
             ^^^^^^^^^^^^^^^^^^^^^^^^^^^^^^^^^^^^^^^
  File "C:\Users\Skeleton\PycharmProjects\Supp0rtBot\TgBot3.py", line 2083, in send_uptime_message
    await context.bot.send_message(
          ~~~~~~~~~~~~~~~~~~~~~~~~^
        chat_id=ACTIVITY_CHECK_CHAT_ID,
        ^^^^^^^^^^^^^^^^^^^^^^^^^^^^^^^
        text=f"Бот активен уже {uptime_hours} часов"
        ^^^^^^^^^^^^^^^^^^^^^^^^^^^^^^^^^^^^^^^^^^^^
    )
    ^
TypeError: User.send_message() got an unexpected keyword argument 'chat_id'
2025-07-29 16:51:13,737 - apscheduler.executors.default - ERROR - Job "send_uptime_message (trigger: interval[0:00:01], next run at: 2025-07-29 16:51:14 EEST)" raised an exception
Traceback (most recent call last):
  File "C:\Users\Skeleton\PycharmProjects\Supp0rtBot\.venv\Lib\site-packages\apscheduler\executors\base.py", line 181, in run_coroutine_job
    retval = await job.func(*job.args, **job.kwargs)
             ^^^^^^^^^^^^^^^^^^^^^^^^^^^^^^^^^^^^^^^
  File "C:\Users\Skeleton\PycharmProjects\Supp0rtBot\TgBot3.py", line 2083, in send_uptime_message
    await context.bot.send_message(
          ~~~~~~~~~~~~~~~~~~~~~~~~^
        chat_id=ACTIVITY_CHECK_CHAT_ID,
        ^^^^^^^^^^^^^^^^^^^^^^^^^^^^^^^
        text=f"Бот активен уже {uptime_hours} часов"
        ^^^^^^^^^^^^^^^^^^^^^^^^^^^^^^^^^^^^^^^^^^^^
    )
    ^
TypeError: User.send_message() got an unexpected keyword argument 'chat_id'
2025-07-29 16:51:14,745 - apscheduler.executors.default - ERROR - Job "send_uptime_message (trigger: interval[0:00:01], next run at: 2025-07-29 16:51:15 EEST)" raised an exception
Traceback (most recent call last):
  File "C:\Users\Skeleton\PycharmProjects\Supp0rtBot\.venv\Lib\site-packages\apscheduler\executors\base.py", line 181, in run_coroutine_job
    retval = await job.func(*job.args, **job.kwargs)
             ^^^^^^^^^^^^^^^^^^^^^^^^^^^^^^^^^^^^^^^
  File "C:\Users\Skeleton\PycharmProjects\Supp0rtBot\TgBot3.py", line 2083, in send_uptime_message
    await context.bot.send_message(
          ~~~~~~~~~~~~~~~~~~~~~~~~^
        chat_id=ACTIVITY_CHECK_CHAT_ID,
        ^^^^^^^^^^^^^^^^^^^^^^^^^^^^^^^
        text=f"Бот активен уже {uptime_hours} часов"
        ^^^^^^^^^^^^^^^^^^^^^^^^^^^^^^^^^^^^^^^^^^^^
    )
    ^
TypeError: User.send_message() got an unexpected keyword argument 'chat_id'
2025-07-29 16:51:15,740 - apscheduler.executors.default - ERROR - Job "send_uptime_message (trigger: interval[0:00:01], next run at: 2025-07-29 16:51:16 EEST)" raised an exception
Traceback (most recent call last):
  File "C:\Users\Skeleton\PycharmProjects\Supp0rtBot\.venv\Lib\site-packages\apscheduler\executors\base.py", line 181, in run_coroutine_job
    retval = await job.func(*job.args, **job.kwargs)
             ^^^^^^^^^^^^^^^^^^^^^^^^^^^^^^^^^^^^^^^
  File "C:\Users\Skeleton\PycharmProjects\Supp0rtBot\TgBot3.py", line 2083, in send_uptime_message
    await context.bot.send_message(
          ~~~~~~~~~~~~~~~~~~~~~~~~^
        chat_id=ACTIVITY_CHECK_CHAT_ID,
        ^^^^^^^^^^^^^^^^^^^^^^^^^^^^^^^
        text=f"Бот активен уже {uptime_hours} часов"
        ^^^^^^^^^^^^^^^^^^^^^^^^^^^^^^^^^^^^^^^^^^^^
    )
    ^
TypeError: User.send_message() got an unexpected keyword argument 'chat_id'
2025-07-29 16:51:16,753 - apscheduler.executors.default - ERROR - Job "send_uptime_message (trigger: interval[0:00:01], next run at: 2025-07-29 16:51:17 EEST)" raised an exception
Traceback (most recent call last):
  File "C:\Users\Skeleton\PycharmProjects\Supp0rtBot\.venv\Lib\site-packages\apscheduler\executors\base.py", line 181, in run_coroutine_job
    retval = await job.func(*job.args, **job.kwargs)
             ^^^^^^^^^^^^^^^^^^^^^^^^^^^^^^^^^^^^^^^
  File "C:\Users\Skeleton\PycharmProjects\Supp0rtBot\TgBot3.py", line 2083, in send_uptime_message
    await context.bot.send_message(
          ~~~~~~~~~~~~~~~~~~~~~~~~^
        chat_id=ACTIVITY_CHECK_CHAT_ID,
        ^^^^^^^^^^^^^^^^^^^^^^^^^^^^^^^
        text=f"Бот активен уже {uptime_hours} часов"
        ^^^^^^^^^^^^^^^^^^^^^^^^^^^^^^^^^^^^^^^^^^^^
    )
    ^
TypeError: User.send_message() got an unexpected keyword argument 'chat_id'
2025-07-29 16:51:17,751 - apscheduler.executors.default - ERROR - Job "send_uptime_message (trigger: interval[0:00:01], next run at: 2025-07-29 16:51:18 EEST)" raised an exception
Traceback (most recent call last):
  File "C:\Users\Skeleton\PycharmProjects\Supp0rtBot\.venv\Lib\site-packages\apscheduler\executors\base.py", line 181, in run_coroutine_job
    retval = await job.func(*job.args, **job.kwargs)
             ^^^^^^^^^^^^^^^^^^^^^^^^^^^^^^^^^^^^^^^
  File "C:\Users\Skeleton\PycharmProjects\Supp0rtBot\TgBot3.py", line 2083, in send_uptime_message
    await context.bot.send_message(
          ~~~~~~~~~~~~~~~~~~~~~~~~^
        chat_id=ACTIVITY_CHECK_CHAT_ID,
        ^^^^^^^^^^^^^^^^^^^^^^^^^^^^^^^
        text=f"Бот активен уже {uptime_hours} часов"
        ^^^^^^^^^^^^^^^^^^^^^^^^^^^^^^^^^^^^^^^^^^^^
    )
    ^
TypeError: User.send_message() got an unexpected keyword argument 'chat_id'
2025-07-29 16:51:18,739 - apscheduler.executors.default - ERROR - Job "send_uptime_message (trigger: interval[0:00:01], next run at: 2025-07-29 16:51:19 EEST)" raised an exception
Traceback (most recent call last):
  File "C:\Users\Skeleton\PycharmProjects\Supp0rtBot\.venv\Lib\site-packages\apscheduler\executors\base.py", line 181, in run_coroutine_job
    retval = await job.func(*job.args, **job.kwargs)
             ^^^^^^^^^^^^^^^^^^^^^^^^^^^^^^^^^^^^^^^
  File "C:\Users\Skeleton\PycharmProjects\Supp0rtBot\TgBot3.py", line 2083, in send_uptime_message
    await context.bot.send_message(
          ~~~~~~~~~~~~~~~~~~~~~~~~^
        chat_id=ACTIVITY_CHECK_CHAT_ID,
        ^^^^^^^^^^^^^^^^^^^^^^^^^^^^^^^
        text=f"Бот активен уже {uptime_hours} часов"
        ^^^^^^^^^^^^^^^^^^^^^^^^^^^^^^^^^^^^^^^^^^^^
    )
    ^
TypeError: User.send_message() got an unexpected keyword argument 'chat_id'
2025-07-29 16:51:19,745 - apscheduler.executors.default - ERROR - Job "send_uptime_message (trigger: interval[0:00:01], next run at: 2025-07-29 16:51:20 EEST)" raised an exception
Traceback (most recent call last):
  File "C:\Users\Skeleton\PycharmProjects\Supp0rtBot\.venv\Lib\site-packages\apscheduler\executors\base.py", line 181, in run_coroutine_job
    retval = await job.func(*job.args, **job.kwargs)
             ^^^^^^^^^^^^^^^^^^^^^^^^^^^^^^^^^^^^^^^
  File "C:\Users\Skeleton\PycharmProjects\Supp0rtBot\TgBot3.py", line 2083, in send_uptime_message
    await context.bot.send_message(
          ~~~~~~~~~~~~~~~~~~~~~~~~^
        chat_id=ACTIVITY_CHECK_CHAT_ID,
        ^^^^^^^^^^^^^^^^^^^^^^^^^^^^^^^
        text=f"Бот активен уже {uptime_hours} часов"
        ^^^^^^^^^^^^^^^^^^^^^^^^^^^^^^^^^^^^^^^^^^^^
    )
    ^
TypeError: User.send_message() got an unexpected keyword argument 'chat_id'
2025-07-29 16:51:20,739 - apscheduler.executors.default - ERROR - Job "send_uptime_message (trigger: interval[0:00:01], next run at: 2025-07-29 16:51:21 EEST)" raised an exception
Traceback (most recent call last):
  File "C:\Users\Skeleton\PycharmProjects\Supp0rtBot\.venv\Lib\site-packages\apscheduler\executors\base.py", line 181, in run_coroutine_job
    retval = await job.func(*job.args, **job.kwargs)
             ^^^^^^^^^^^^^^^^^^^^^^^^^^^^^^^^^^^^^^^
  File "C:\Users\Skeleton\PycharmProjects\Supp0rtBot\TgBot3.py", line 2083, in send_uptime_message
    await context.bot.send_message(
          ~~~~~~~~~~~~~~~~~~~~~~~~^
        chat_id=ACTIVITY_CHECK_CHAT_ID,
        ^^^^^^^^^^^^^^^^^^^^^^^^^^^^^^^
        text=f"Бот активен уже {uptime_hours} часов"
        ^^^^^^^^^^^^^^^^^^^^^^^^^^^^^^^^^^^^^^^^^^^^
    )
    ^
TypeError: User.send_message() got an unexpected keyword argument 'chat_id'
2025-07-29 16:51:20,914 - telegram.ext.Application - ERROR - No error handlers are registered, logging exception.
Traceback (most recent call last):
  File "C:\Users\Skeleton\PycharmProjects\Supp0rtBot\.venv\Lib\site-packages\telegram\ext\_updater.py", line 750, in _network_loop_retry
    if not await do_action():
           ^^^^^^^^^^^^^^^^^
  File "C:\Users\Skeleton\PycharmProjects\Supp0rtBot\.venv\Lib\site-packages\telegram\ext\_updater.py", line 744, in do_action
    return action_cb_task.result()
           ~~~~~~~~~~~~~~~~~~~~~^^
  File "C:\Program Files\Python313\Lib\asyncio\futures.py", line 199, in result
    raise self._exception.with_traceback(self._exception_tb)
  File "C:\Program Files\Python313\Lib\asyncio\tasks.py", line 304, in __step_run_and_handle_result
    result = coro.send(None)
  File "C:\Users\Skeleton\PycharmProjects\Supp0rtBot\.venv\Lib\site-packages\telegram\ext\_updater.py", line 371, in polling_action_cb
    updates = await self.bot.get_updates(
              ^^^^^^^^^^^^^^^^^^^^^^^^^^^
    ...<7 lines>...
    )
    ^
  File "C:\Users\Skeleton\PycharmProjects\Supp0rtBot\.venv\Lib\site-packages\telegram\ext\_extbot.py", line 650, in get_updates
    updates = await super().get_updates(
              ^^^^^^^^^^^^^^^^^^^^^^^^^^
    ...<9 lines>...
    )
    ^
  File "C:\Users\Skeleton\PycharmProjects\Supp0rtBot\.venv\Lib\site-packages\telegram\_bot.py", line 4480, in get_updates
    await self._post(
    ^^^^^^^^^^^^^^^^^
    ...<7 lines>...
    ),
    ^
  File "C:\Users\Skeleton\PycharmProjects\Supp0rtBot\.venv\Lib\site-packages\telegram\_bot.py", line 619, in _post
    return await self._do_post(
           ^^^^^^^^^^^^^^^^^^^^
    ...<6 lines>...
    )
    ^
  File "C:\Users\Skeleton\PycharmProjects\Supp0rtBot\.venv\Lib\site-packages\telegram\ext\_extbot.py", line 354, in _do_post
    return await super()._do_post(
           ^^^^^^^^^^^^^^^^^^^^^^^
    ...<6 lines>...
    )
    ^
  File "C:\Users\Skeleton\PycharmProjects\Supp0rtBot\.venv\Lib\site-packages\telegram\_bot.py", line 648, in _do_post
    result = await request.post(
             ^^^^^^^^^^^^^^^^^^^
    ...<6 lines>...
    )
    ^
  File "C:\Users\Skeleton\PycharmProjects\Supp0rtBot\.venv\Lib\site-packages\telegram\request\_baserequest.py", line 202, in post
    result = await self._request_wrapper(
             ^^^^^^^^^^^^^^^^^^^^^^^^^^^^
    ...<7 lines>...
    )
    ^
  File "C:\Users\Skeleton\PycharmProjects\Supp0rtBot\.venv\Lib\site-packages\telegram\request\_baserequest.py", line 385, in _request_wrapper
    raise Conflict(message)
telegram.error.Conflict: Conflict: terminated by other getUpdates request; make sure that only one bot instance is running
2025-07-29 16:51:21,738 - apscheduler.executors.default - ERROR - Job "send_uptime_message (trigger: interval[0:00:01], next run at: 2025-07-29 16:51:22 EEST)" raised an exception
Traceback (most recent call last):
  File "C:\Users\Skeleton\PycharmProjects\Supp0rtBot\.venv\Lib\site-packages\apscheduler\executors\base.py", line 181, in run_coroutine_job
    retval = await job.func(*job.args, **job.kwargs)
             ^^^^^^^^^^^^^^^^^^^^^^^^^^^^^^^^^^^^^^^
  File "C:\Users\Skeleton\PycharmProjects\Supp0rtBot\TgBot3.py", line 2083, in send_uptime_message
    await context.bot.send_message(
          ~~~~~~~~~~~~~~~~~~~~~~~~^
        chat_id=ACTIVITY_CHECK_CHAT_ID,
        ^^^^^^^^^^^^^^^^^^^^^^^^^^^^^^^
        text=f"Бот активен уже {uptime_hours} часов"
        ^^^^^^^^^^^^^^^^^^^^^^^^^^^^^^^^^^^^^^^^^^^^
    )
    ^
TypeError: User.send_message() got an unexpected keyword argument 'chat_id'
2025-07-29 16:51:22,747 - apscheduler.executors.default - ERROR - Job "send_uptime_message (trigger: interval[0:00:01], next run at: 2025-07-29 16:51:23 EEST)" raised an exception
Traceback (most recent call last):
  File "C:\Users\Skeleton\PycharmProjects\Supp0rtBot\.venv\Lib\site-packages\apscheduler\executors\base.py", line 181, in run_coroutine_job
    retval = await job.func(*job.args, **job.kwargs)
             ^^^^^^^^^^^^^^^^^^^^^^^^^^^^^^^^^^^^^^^
  File "C:\Users\Skeleton\PycharmProjects\Supp0rtBot\TgBot3.py", line 2083, in send_uptime_message
    await context.bot.send_message(
          ~~~~~~~~~~~~~~~~~~~~~~~~^
        chat_id=ACTIVITY_CHECK_CHAT_ID,
        ^^^^^^^^^^^^^^^^^^^^^^^^^^^^^^^
        text=f"Бот активен уже {uptime_hours} часов"
        ^^^^^^^^^^^^^^^^^^^^^^^^^^^^^^^^^^^^^^^^^^^^
    )
    ^
TypeError: User.send_message() got an unexpected keyword argument 'chat_id'
2025-07-29 16:51:23,741 - apscheduler.executors.default - ERROR - Job "send_uptime_message (trigger: interval[0:00:01], next run at: 2025-07-29 16:51:24 EEST)" raised an exception
Traceback (most recent call last):
  File "C:\Users\Skeleton\PycharmProjects\Supp0rtBot\.venv\Lib\site-packages\apscheduler\executors\base.py", line 181, in run_coroutine_job
    retval = await job.func(*job.args, **job.kwargs)
             ^^^^^^^^^^^^^^^^^^^^^^^^^^^^^^^^^^^^^^^
  File "C:\Users\Skeleton\PycharmProjects\Supp0rtBot\TgBot3.py", line 2083, in send_uptime_message
    await context.bot.send_message(
          ~~~~~~~~~~~~~~~~~~~~~~~~^
        chat_id=ACTIVITY_CHECK_CHAT_ID,
        ^^^^^^^^^^^^^^^^^^^^^^^^^^^^^^^
        text=f"Бот активен уже {uptime_hours} часов"
        ^^^^^^^^^^^^^^^^^^^^^^^^^^^^^^^^^^^^^^^^^^^^
    )
    ^
TypeError: User.send_message() got an unexpected keyword argument 'chat_id'
2025-07-29 16:51:24,741 - apscheduler.executors.default - ERROR - Job "send_uptime_message (trigger: interval[0:00:01], next run at: 2025-07-29 16:51:25 EEST)" raised an exception
Traceback (most recent call last):
  File "C:\Users\Skeleton\PycharmProjects\Supp0rtBot\.venv\Lib\site-packages\apscheduler\executors\base.py", line 181, in run_coroutine_job
    retval = await job.func(*job.args, **job.kwargs)
             ^^^^^^^^^^^^^^^^^^^^^^^^^^^^^^^^^^^^^^^
  File "C:\Users\Skeleton\PycharmProjects\Supp0rtBot\TgBot3.py", line 2083, in send_uptime_message
    await context.bot.send_message(
          ~~~~~~~~~~~~~~~~~~~~~~~~^
        chat_id=ACTIVITY_CHECK_CHAT_ID,
        ^^^^^^^^^^^^^^^^^^^^^^^^^^^^^^^
        text=f"Бот активен уже {uptime_hours} часов"
        ^^^^^^^^^^^^^^^^^^^^^^^^^^^^^^^^^^^^^^^^^^^^
    )
    ^
TypeError: User.send_message() got an unexpected keyword argument 'chat_id'
2025-07-29 16:51:25,752 - apscheduler.executors.default - ERROR - Job "send_uptime_message (trigger: interval[0:00:01], next run at: 2025-07-29 16:51:26 EEST)" raised an exception
Traceback (most recent call last):
  File "C:\Users\Skeleton\PycharmProjects\Supp0rtBot\.venv\Lib\site-packages\apscheduler\executors\base.py", line 181, in run_coroutine_job
    retval = await job.func(*job.args, **job.kwargs)
             ^^^^^^^^^^^^^^^^^^^^^^^^^^^^^^^^^^^^^^^
  File "C:\Users\Skeleton\PycharmProjects\Supp0rtBot\TgBot3.py", line 2083, in send_uptime_message
    await context.bot.send_message(
          ~~~~~~~~~~~~~~~~~~~~~~~~^
        chat_id=ACTIVITY_CHECK_CHAT_ID,
        ^^^^^^^^^^^^^^^^^^^^^^^^^^^^^^^
        text=f"Бот активен уже {uptime_hours} часов"
        ^^^^^^^^^^^^^^^^^^^^^^^^^^^^^^^^^^^^^^^^^^^^
    )
    ^
TypeError: User.send_message() got an unexpected keyword argument 'chat_id'
2025-07-29 16:51:26,747 - apscheduler.executors.default - ERROR - Job "send_uptime_message (trigger: interval[0:00:01], next run at: 2025-07-29 16:51:27 EEST)" raised an exception
Traceback (most recent call last):
  File "C:\Users\Skeleton\PycharmProjects\Supp0rtBot\.venv\Lib\site-packages\apscheduler\executors\base.py", line 181, in run_coroutine_job
    retval = await job.func(*job.args, **job.kwargs)
             ^^^^^^^^^^^^^^^^^^^^^^^^^^^^^^^^^^^^^^^
  File "C:\Users\Skeleton\PycharmProjects\Supp0rtBot\TgBot3.py", line 2083, in send_uptime_message
    await context.bot.send_message(
          ~~~~~~~~~~~~~~~~~~~~~~~~^
        chat_id=ACTIVITY_CHECK_CHAT_ID,
        ^^^^^^^^^^^^^^^^^^^^^^^^^^^^^^^
        text=f"Бот активен уже {uptime_hours} часов"
        ^^^^^^^^^^^^^^^^^^^^^^^^^^^^^^^^^^^^^^^^^^^^
    )
    ^
TypeError: User.send_message() got an unexpected keyword argument 'chat_id'
2025-07-29 16:51:27,741 - apscheduler.executors.default - ERROR - Job "send_uptime_message (trigger: interval[0:00:01], next run at: 2025-07-29 16:51:28 EEST)" raised an exception
Traceback (most recent call last):
  File "C:\Users\Skeleton\PycharmProjects\Supp0rtBot\.venv\Lib\site-packages\apscheduler\executors\base.py", line 181, in run_coroutine_job
    retval = await job.func(*job.args, **job.kwargs)
             ^^^^^^^^^^^^^^^^^^^^^^^^^^^^^^^^^^^^^^^
  File "C:\Users\Skeleton\PycharmProjects\Supp0rtBot\TgBot3.py", line 2083, in send_uptime_message
    await context.bot.send_message(
          ~~~~~~~~~~~~~~~~~~~~~~~~^
        chat_id=ACTIVITY_CHECK_CHAT_ID,
        ^^^^^^^^^^^^^^^^^^^^^^^^^^^^^^^
        text=f"Бот активен уже {uptime_hours} часов"
        ^^^^^^^^^^^^^^^^^^^^^^^^^^^^^^^^^^^^^^^^^^^^
    )
    ^
TypeError: User.send_message() got an unexpected keyword argument 'chat_id'
2025-07-29 16:51:28,742 - apscheduler.executors.default - ERROR - Job "send_uptime_message (trigger: interval[0:00:01], next run at: 2025-07-29 16:51:29 EEST)" raised an exception
Traceback (most recent call last):
  File "C:\Users\Skeleton\PycharmProjects\Supp0rtBot\.venv\Lib\site-packages\apscheduler\executors\base.py", line 181, in run_coroutine_job
    retval = await job.func(*job.args, **job.kwargs)
             ^^^^^^^^^^^^^^^^^^^^^^^^^^^^^^^^^^^^^^^
  File "C:\Users\Skeleton\PycharmProjects\Supp0rtBot\TgBot3.py", line 2083, in send_uptime_message
    await context.bot.send_message(
          ~~~~~~~~~~~~~~~~~~~~~~~~^
        chat_id=ACTIVITY_CHECK_CHAT_ID,
        ^^^^^^^^^^^^^^^^^^^^^^^^^^^^^^^
        text=f"Бот активен уже {uptime_hours} часов"
        ^^^^^^^^^^^^^^^^^^^^^^^^^^^^^^^^^^^^^^^^^^^^
    )
    ^
TypeError: User.send_message() got an unexpected keyword argument 'chat_id'
2025-07-29 16:51:29,749 - apscheduler.executors.default - ERROR - Job "send_uptime_message (trigger: interval[0:00:01], next run at: 2025-07-29 16:51:30 EEST)" raised an exception
Traceback (most recent call last):
  File "C:\Users\Skeleton\PycharmProjects\Supp0rtBot\.venv\Lib\site-packages\apscheduler\executors\base.py", line 181, in run_coroutine_job
    retval = await job.func(*job.args, **job.kwargs)
             ^^^^^^^^^^^^^^^^^^^^^^^^^^^^^^^^^^^^^^^
  File "C:\Users\Skeleton\PycharmProjects\Supp0rtBot\TgBot3.py", line 2083, in send_uptime_message
    await context.bot.send_message(
          ~~~~~~~~~~~~~~~~~~~~~~~~^
        chat_id=ACTIVITY_CHECK_CHAT_ID,
        ^^^^^^^^^^^^^^^^^^^^^^^^^^^^^^^
        text=f"Бот активен уже {uptime_hours} часов"
        ^^^^^^^^^^^^^^^^^^^^^^^^^^^^^^^^^^^^^^^^^^^^
    )
    ^
TypeError: User.send_message() got an unexpected keyword argument 'chat_id'
2025-07-29 16:51:30,737 - apscheduler.executors.default - ERROR - Job "send_uptime_message (trigger: interval[0:00:01], next run at: 2025-07-29 16:51:31 EEST)" raised an exception
Traceback (most recent call last):
  File "C:\Users\Skeleton\PycharmProjects\Supp0rtBot\.venv\Lib\site-packages\apscheduler\executors\base.py", line 181, in run_coroutine_job
    retval = await job.func(*job.args, **job.kwargs)
             ^^^^^^^^^^^^^^^^^^^^^^^^^^^^^^^^^^^^^^^
  File "C:\Users\Skeleton\PycharmProjects\Supp0rtBot\TgBot3.py", line 2083, in send_uptime_message
    await context.bot.send_message(
          ~~~~~~~~~~~~~~~~~~~~~~~~^
        chat_id=ACTIVITY_CHECK_CHAT_ID,
        ^^^^^^^^^^^^^^^^^^^^^^^^^^^^^^^
        text=f"Бот активен уже {uptime_hours} часов"
        ^^^^^^^^^^^^^^^^^^^^^^^^^^^^^^^^^^^^^^^^^^^^
    )
    ^
TypeError: User.send_message() got an unexpected keyword argument 'chat_id'
2025-07-29 16:51:31,753 - apscheduler.executors.default - ERROR - Job "send_uptime_message (trigger: interval[0:00:01], next run at: 2025-07-29 16:51:32 EEST)" raised an exception
Traceback (most recent call last):
  File "C:\Users\Skeleton\PycharmProjects\Supp0rtBot\.venv\Lib\site-packages\apscheduler\executors\base.py", line 181, in run_coroutine_job
    retval = await job.func(*job.args, **job.kwargs)
             ^^^^^^^^^^^^^^^^^^^^^^^^^^^^^^^^^^^^^^^
  File "C:\Users\Skeleton\PycharmProjects\Supp0rtBot\TgBot3.py", line 2083, in send_uptime_message
    await context.bot.send_message(
          ~~~~~~~~~~~~~~~~~~~~~~~~^
        chat_id=ACTIVITY_CHECK_CHAT_ID,
        ^^^^^^^^^^^^^^^^^^^^^^^^^^^^^^^
        text=f"Бот активен уже {uptime_hours} часов"
        ^^^^^^^^^^^^^^^^^^^^^^^^^^^^^^^^^^^^^^^^^^^^
    )
    ^
TypeError: User.send_message() got an unexpected keyword argument 'chat_id'
2025-07-29 16:51:32,745 - apscheduler.executors.default - ERROR - Job "send_uptime_message (trigger: interval[0:00:01], next run at: 2025-07-29 16:51:33 EEST)" raised an exception
Traceback (most recent call last):
  File "C:\Users\Skeleton\PycharmProjects\Supp0rtBot\.venv\Lib\site-packages\apscheduler\executors\base.py", line 181, in run_coroutine_job
    retval = await job.func(*job.args, **job.kwargs)
             ^^^^^^^^^^^^^^^^^^^^^^^^^^^^^^^^^^^^^^^
  File "C:\Users\Skeleton\PycharmProjects\Supp0rtBot\TgBot3.py", line 2083, in send_uptime_message
    await context.bot.send_message(
          ~~~~~~~~~~~~~~~~~~~~~~~~^
        chat_id=ACTIVITY_CHECK_CHAT_ID,
        ^^^^^^^^^^^^^^^^^^^^^^^^^^^^^^^
        text=f"Бот активен уже {uptime_hours} часов"
        ^^^^^^^^^^^^^^^^^^^^^^^^^^^^^^^^^^^^^^^^^^^^
    )
    ^
TypeError: User.send_message() got an unexpected keyword argument 'chat_id'
2025-07-29 16:51:33,736 - apscheduler.executors.default - ERROR - Job "send_uptime_message (trigger: interval[0:00:01], next run at: 2025-07-29 16:51:34 EEST)" raised an exception
Traceback (most recent call last):
  File "C:\Users\Skeleton\PycharmProjects\Supp0rtBot\.venv\Lib\site-packages\apscheduler\executors\base.py", line 181, in run_coroutine_job
    retval = await job.func(*job.args, **job.kwargs)
             ^^^^^^^^^^^^^^^^^^^^^^^^^^^^^^^^^^^^^^^
  File "C:\Users\Skeleton\PycharmProjects\Supp0rtBot\TgBot3.py", line 2083, in send_uptime_message
    await context.bot.send_message(
          ~~~~~~~~~~~~~~~~~~~~~~~~^
        chat_id=ACTIVITY_CHECK_CHAT_ID,
        ^^^^^^^^^^^^^^^^^^^^^^^^^^^^^^^
        text=f"Бот активен уже {uptime_hours} часов"
        ^^^^^^^^^^^^^^^^^^^^^^^^^^^^^^^^^^^^^^^^^^^^
    )
    ^
TypeError: User.send_message() got an unexpected keyword argument 'chat_id'
2025-07-29 16:51:34,749 - apscheduler.executors.default - ERROR - Job "send_uptime_message (trigger: interval[0:00:01], next run at: 2025-07-29 16:51:35 EEST)" raised an exception
Traceback (most recent call last):
  File "C:\Users\Skeleton\PycharmProjects\Supp0rtBot\.venv\Lib\site-packages\apscheduler\executors\base.py", line 181, in run_coroutine_job
    retval = await job.func(*job.args, **job.kwargs)
             ^^^^^^^^^^^^^^^^^^^^^^^^^^^^^^^^^^^^^^^
  File "C:\Users\Skeleton\PycharmProjects\Supp0rtBot\TgBot3.py", line 2083, in send_uptime_message
    await context.bot.send_message(
          ~~~~~~~~~~~~~~~~~~~~~~~~^
        chat_id=ACTIVITY_CHECK_CHAT_ID,
        ^^^^^^^^^^^^^^^^^^^^^^^^^^^^^^^
        text=f"Бот активен уже {uptime_hours} часов"
        ^^^^^^^^^^^^^^^^^^^^^^^^^^^^^^^^^^^^^^^^^^^^
    )
    ^
TypeError: User.send_message() got an unexpected keyword argument 'chat_id'
2025-07-29 16:51:36,398 - apscheduler.executors.default - ERROR - Job "send_uptime_message (trigger: interval[0:00:01], next run at: 2025-07-29 16:51:36 EEST)" raised an exception
Traceback (most recent call last):
  File "C:\Users\Skeleton\PycharmProjects\Supp0rtBot\.venv\Lib\site-packages\apscheduler\executors\base.py", line 181, in run_coroutine_job
    retval = await job.func(*job.args, **job.kwargs)
             ^^^^^^^^^^^^^^^^^^^^^^^^^^^^^^^^^^^^^^^
  File "C:\Users\Skeleton\PycharmProjects\Supp0rtBot\TgBot3.py", line 2083, in send_uptime_message
    await context.bot.send_message(
          ~~~~~~~~~~~~~~~~~~~~~~~~^
        chat_id=ACTIVITY_CHECK_CHAT_ID,
        ^^^^^^^^^^^^^^^^^^^^^^^^^^^^^^^
        text=f"Бот активен уже {uptime_hours} часов"
        ^^^^^^^^^^^^^^^^^^^^^^^^^^^^^^^^^^^^^^^^^^^^
    )
    ^
TypeError: User.send_message() got an unexpected keyword argument 'chat_id'
2025-07-29 16:51:36,722 - telegram.ext.Application - ERROR - No error handlers are registered, logging exception.
Traceback (most recent call last):
  File "C:\Users\Skeleton\PycharmProjects\Supp0rtBot\.venv\Lib\site-packages\telegram\ext\_updater.py", line 750, in _network_loop_retry
    if not await do_action():
           ^^^^^^^^^^^^^^^^^
  File "C:\Users\Skeleton\PycharmProjects\Supp0rtBot\.venv\Lib\site-packages\telegram\ext\_updater.py", line 744, in do_action
    return action_cb_task.result()
           ~~~~~~~~~~~~~~~~~~~~~^^
  File "C:\Program Files\Python313\Lib\asyncio\futures.py", line 199, in result
    raise self._exception.with_traceback(self._exception_tb)
  File "C:\Program Files\Python313\Lib\asyncio\tasks.py", line 304, in __step_run_and_handle_result
    result = coro.send(None)
  File "C:\Users\Skeleton\PycharmProjects\Supp0rtBot\.venv\Lib\site-packages\telegram\ext\_updater.py", line 371, in polling_action_cb
    updates = await self.bot.get_updates(
              ^^^^^^^^^^^^^^^^^^^^^^^^^^^
    ...<7 lines>...
    )
    ^
  File "C:\Users\Skeleton\PycharmProjects\Supp0rtBot\.venv\Lib\site-packages\telegram\ext\_extbot.py", line 650, in get_updates
    updates = await super().get_updates(
              ^^^^^^^^^^^^^^^^^^^^^^^^^^
    ...<9 lines>...
    )
    ^
  File "C:\Users\Skeleton\PycharmProjects\Supp0rtBot\.venv\Lib\site-packages\telegram\_bot.py", line 4480, in get_updates
    await self._post(
    ^^^^^^^^^^^^^^^^^
    ...<7 lines>...
    ),
    ^
  File "C:\Users\Skeleton\PycharmProjects\Supp0rtBot\.venv\Lib\site-packages\telegram\_bot.py", line 619, in _post
    return await self._do_post(
           ^^^^^^^^^^^^^^^^^^^^
    ...<6 lines>...
    )
    ^
  File "C:\Users\Skeleton\PycharmProjects\Supp0rtBot\.venv\Lib\site-packages\telegram\ext\_extbot.py", line 354, in _do_post
    return await super()._do_post(
           ^^^^^^^^^^^^^^^^^^^^^^^
    ...<6 lines>...
    )
    ^
  File "C:\Users\Skeleton\PycharmProjects\Supp0rtBot\.venv\Lib\site-packages\telegram\_bot.py", line 648, in _do_post
    result = await request.post(
             ^^^^^^^^^^^^^^^^^^^
    ...<6 lines>...
    )
    ^
  File "C:\Users\Skeleton\PycharmProjects\Supp0rtBot\.venv\Lib\site-packages\telegram\request\_baserequest.py", line 202, in post
    result = await self._request_wrapper(
             ^^^^^^^^^^^^^^^^^^^^^^^^^^^^
    ...<7 lines>...
    )
    ^
  File "C:\Users\Skeleton\PycharmProjects\Supp0rtBot\.venv\Lib\site-packages\telegram\request\_baserequest.py", line 385, in _request_wrapper
    raise Conflict(message)
telegram.error.Conflict: Conflict: terminated by other getUpdates request; make sure that only one bot instance is running
2025-07-29 16:51:36,753 - apscheduler.executors.default - ERROR - Job "send_uptime_message (trigger: interval[0:00:01], next run at: 2025-07-29 16:51:37 EEST)" raised an exception
Traceback (most recent call last):
  File "C:\Users\Skeleton\PycharmProjects\Supp0rtBot\.venv\Lib\site-packages\apscheduler\executors\base.py", line 181, in run_coroutine_job
    retval = await job.func(*job.args, **job.kwargs)
             ^^^^^^^^^^^^^^^^^^^^^^^^^^^^^^^^^^^^^^^
  File "C:\Users\Skeleton\PycharmProjects\Supp0rtBot\TgBot3.py", line 2083, in send_uptime_message
    await context.bot.send_message(
          ~~~~~~~~~~~~~~~~~~~~~~~~^
        chat_id=ACTIVITY_CHECK_CHAT_ID,
        ^^^^^^^^^^^^^^^^^^^^^^^^^^^^^^^
        text=f"Бот активен уже {uptime_hours} часов"
        ^^^^^^^^^^^^^^^^^^^^^^^^^^^^^^^^^^^^^^^^^^^^
    )
    ^
TypeError: User.send_message() got an unexpected keyword argument 'chat_id'
2025-07-29 16:51:43,939 - werkzeug - INFO - [31m[1mWARNING: This is a development server. Do not use it in a production deployment. Use a production WSGI server instead.[0m
 * Running on all addresses (0.0.0.0)
 * Running on http://127.0.0.1:5000
 * Running on http://192.168.31.10:5000
2025-07-29 16:51:43,940 - werkzeug - INFO - [33mPress CTRL+C to quit[0m
2025-07-29 16:51:47,052 - apscheduler.executors.default - ERROR - Job "send_uptime_message (trigger: interval[0:00:01], next run at: 2025-07-29 16:51:48 EEST)" raised an exception
Traceback (most recent call last):
  File "C:\Users\Skeleton\PycharmProjects\Supp0rtBot\.venv\Lib\site-packages\apscheduler\executors\base.py", line 181, in run_coroutine_job
    retval = await job.func(*job.args, **job.kwargs)
             ^^^^^^^^^^^^^^^^^^^^^^^^^^^^^^^^^^^^^^^
  File "C:\Users\Skeleton\PycharmProjects\Supp0rtBot\TgBot3.py", line 2084, in send_uptime_message
    await context.bot.send_message(
          ~~~~~~~~~~~~~~~~~~~~~~~~^
        chat_id=ACTIVITY_CHECK_CHAT_ID,
        ^^^^^^^^^^^^^^^^^^^^^^^^^^^^^^^
        text=f"Бот активен уже {uptime_hours} часов"
        ^^^^^^^^^^^^^^^^^^^^^^^^^^^^^^^^^^^^^^^^^^^^
    )
    ^
TypeError: User.send_message() got an unexpected keyword argument 'chat_id'
2025-07-29 16:51:48,049 - apscheduler.executors.default - ERROR - Job "send_uptime_message (trigger: interval[0:00:01], next run at: 2025-07-29 16:51:49 EEST)" raised an exception
Traceback (most recent call last):
  File "C:\Users\Skeleton\PycharmProjects\Supp0rtBot\.venv\Lib\site-packages\apscheduler\executors\base.py", line 181, in run_coroutine_job
    retval = await job.func(*job.args, **job.kwargs)
             ^^^^^^^^^^^^^^^^^^^^^^^^^^^^^^^^^^^^^^^
  File "C:\Users\Skeleton\PycharmProjects\Supp0rtBot\TgBot3.py", line 2084, in send_uptime_message
    await context.bot.send_message(
          ~~~~~~~~~~~~~~~~~~~~~~~~^
        chat_id=ACTIVITY_CHECK_CHAT_ID,
        ^^^^^^^^^^^^^^^^^^^^^^^^^^^^^^^
        text=f"Бот активен уже {uptime_hours} часов"
        ^^^^^^^^^^^^^^^^^^^^^^^^^^^^^^^^^^^^^^^^^^^^
    )
    ^
TypeError: User.send_message() got an unexpected keyword argument 'chat_id'
2025-07-29 16:51:49,044 - apscheduler.executors.default - ERROR - Job "send_uptime_message (trigger: interval[0:00:01], next run at: 2025-07-29 16:51:50 EEST)" raised an exception
Traceback (most recent call last):
  File "C:\Users\Skeleton\PycharmProjects\Supp0rtBot\.venv\Lib\site-packages\apscheduler\executors\base.py", line 181, in run_coroutine_job
    retval = await job.func(*job.args, **job.kwargs)
             ^^^^^^^^^^^^^^^^^^^^^^^^^^^^^^^^^^^^^^^
  File "C:\Users\Skeleton\PycharmProjects\Supp0rtBot\TgBot3.py", line 2084, in send_uptime_message
    await context.bot.send_message(
          ~~~~~~~~~~~~~~~~~~~~~~~~^
        chat_id=ACTIVITY_CHECK_CHAT_ID,
        ^^^^^^^^^^^^^^^^^^^^^^^^^^^^^^^
        text=f"Бот активен уже {uptime_hours} часов"
        ^^^^^^^^^^^^^^^^^^^^^^^^^^^^^^^^^^^^^^^^^^^^
    )
    ^
TypeError: User.send_message() got an unexpected keyword argument 'chat_id'
2025-07-29 16:51:50,044 - apscheduler.executors.default - ERROR - Job "send_uptime_message (trigger: interval[0:00:01], next run at: 2025-07-29 16:51:51 EEST)" raised an exception
Traceback (most recent call last):
  File "C:\Users\Skeleton\PycharmProjects\Supp0rtBot\.venv\Lib\site-packages\apscheduler\executors\base.py", line 181, in run_coroutine_job
    retval = await job.func(*job.args, **job.kwargs)
             ^^^^^^^^^^^^^^^^^^^^^^^^^^^^^^^^^^^^^^^
  File "C:\Users\Skeleton\PycharmProjects\Supp0rtBot\TgBot3.py", line 2084, in send_uptime_message
    await context.bot.send_message(
          ~~~~~~~~~~~~~~~~~~~~~~~~^
        chat_id=ACTIVITY_CHECK_CHAT_ID,
        ^^^^^^^^^^^^^^^^^^^^^^^^^^^^^^^
        text=f"Бот активен уже {uptime_hours} часов"
        ^^^^^^^^^^^^^^^^^^^^^^^^^^^^^^^^^^^^^^^^^^^^
    )
    ^
TypeError: User.send_message() got an unexpected keyword argument 'chat_id'
2025-07-29 16:51:50,839 - telegram.ext.Application - ERROR - No error handlers are registered, logging exception.
Traceback (most recent call last):
  File "C:\Users\Skeleton\PycharmProjects\Supp0rtBot\.venv\Lib\site-packages\telegram\ext\_updater.py", line 750, in _network_loop_retry
    if not await do_action():
           ^^^^^^^^^^^^^^^^^
  File "C:\Users\Skeleton\PycharmProjects\Supp0rtBot\.venv\Lib\site-packages\telegram\ext\_updater.py", line 744, in do_action
    return action_cb_task.result()
           ~~~~~~~~~~~~~~~~~~~~~^^
  File "C:\Program Files\Python313\Lib\asyncio\futures.py", line 199, in result
    raise self._exception.with_traceback(self._exception_tb)
  File "C:\Program Files\Python313\Lib\asyncio\tasks.py", line 304, in __step_run_and_handle_result
    result = coro.send(None)
  File "C:\Users\Skeleton\PycharmProjects\Supp0rtBot\.venv\Lib\site-packages\telegram\ext\_updater.py", line 371, in polling_action_cb
    updates = await self.bot.get_updates(
              ^^^^^^^^^^^^^^^^^^^^^^^^^^^
    ...<7 lines>...
    )
    ^
  File "C:\Users\Skeleton\PycharmProjects\Supp0rtBot\.venv\Lib\site-packages\telegram\ext\_extbot.py", line 650, in get_updates
    updates = await super().get_updates(
              ^^^^^^^^^^^^^^^^^^^^^^^^^^
    ...<9 lines>...
    )
    ^
  File "C:\Users\Skeleton\PycharmProjects\Supp0rtBot\.venv\Lib\site-packages\telegram\_bot.py", line 4480, in get_updates
    await self._post(
    ^^^^^^^^^^^^^^^^^
    ...<7 lines>...
    ),
    ^
  File "C:\Users\Skeleton\PycharmProjects\Supp0rtBot\.venv\Lib\site-packages\telegram\_bot.py", line 619, in _post
    return await self._do_post(
           ^^^^^^^^^^^^^^^^^^^^
    ...<6 lines>...
    )
    ^
  File "C:\Users\Skeleton\PycharmProjects\Supp0rtBot\.venv\Lib\site-packages\telegram\ext\_extbot.py", line 354, in _do_post
    return await super()._do_post(
           ^^^^^^^^^^^^^^^^^^^^^^^
    ...<6 lines>...
    )
    ^
  File "C:\Users\Skeleton\PycharmProjects\Supp0rtBot\.venv\Lib\site-packages\telegram\_bot.py", line 648, in _do_post
    result = await request.post(
             ^^^^^^^^^^^^^^^^^^^
    ...<6 lines>...
    )
    ^
  File "C:\Users\Skeleton\PycharmProjects\Supp0rtBot\.venv\Lib\site-packages\telegram\request\_baserequest.py", line 202, in post
    result = await self._request_wrapper(
             ^^^^^^^^^^^^^^^^^^^^^^^^^^^^
    ...<7 lines>...
    )
    ^
  File "C:\Users\Skeleton\PycharmProjects\Supp0rtBot\.venv\Lib\site-packages\telegram\request\_baserequest.py", line 385, in _request_wrapper
    raise Conflict(message)
telegram.error.Conflict: Conflict: terminated by other getUpdates request; make sure that only one bot instance is running
2025-07-29 16:51:51,043 - apscheduler.executors.default - ERROR - Job "send_uptime_message (trigger: interval[0:00:01], next run at: 2025-07-29 16:51:52 EEST)" raised an exception
Traceback (most recent call last):
  File "C:\Users\Skeleton\PycharmProjects\Supp0rtBot\.venv\Lib\site-packages\apscheduler\executors\base.py", line 181, in run_coroutine_job
    retval = await job.func(*job.args, **job.kwargs)
             ^^^^^^^^^^^^^^^^^^^^^^^^^^^^^^^^^^^^^^^
  File "C:\Users\Skeleton\PycharmProjects\Supp0rtBot\TgBot3.py", line 2084, in send_uptime_message
    await context.bot.send_message(
          ~~~~~~~~~~~~~~~~~~~~~~~~^
        chat_id=ACTIVITY_CHECK_CHAT_ID,
        ^^^^^^^^^^^^^^^^^^^^^^^^^^^^^^^
        text=f"Бот активен уже {uptime_hours} часов"
        ^^^^^^^^^^^^^^^^^^^^^^^^^^^^^^^^^^^^^^^^^^^^
    )
    ^
TypeError: User.send_message() got an unexpected keyword argument 'chat_id'
2025-07-29 16:51:52,051 - apscheduler.executors.default - ERROR - Job "send_uptime_message (trigger: interval[0:00:01], next run at: 2025-07-29 16:51:53 EEST)" raised an exception
Traceback (most recent call last):
  File "C:\Users\Skeleton\PycharmProjects\Supp0rtBot\.venv\Lib\site-packages\apscheduler\executors\base.py", line 181, in run_coroutine_job
    retval = await job.func(*job.args, **job.kwargs)
             ^^^^^^^^^^^^^^^^^^^^^^^^^^^^^^^^^^^^^^^
  File "C:\Users\Skeleton\PycharmProjects\Supp0rtBot\TgBot3.py", line 2084, in send_uptime_message
    await context.bot.send_message(
          ~~~~~~~~~~~~~~~~~~~~~~~~^
        chat_id=ACTIVITY_CHECK_CHAT_ID,
        ^^^^^^^^^^^^^^^^^^^^^^^^^^^^^^^
        text=f"Бот активен уже {uptime_hours} часов"
        ^^^^^^^^^^^^^^^^^^^^^^^^^^^^^^^^^^^^^^^^^^^^
    )
    ^
TypeError: User.send_message() got an unexpected keyword argument 'chat_id'
2025-07-29 16:51:53,045 - apscheduler.executors.default - ERROR - Job "send_uptime_message (trigger: interval[0:00:01], next run at: 2025-07-29 16:51:54 EEST)" raised an exception
Traceback (most recent call last):
  File "C:\Users\Skeleton\PycharmProjects\Supp0rtBot\.venv\Lib\site-packages\apscheduler\executors\base.py", line 181, in run_coroutine_job
    retval = await job.func(*job.args, **job.kwargs)
             ^^^^^^^^^^^^^^^^^^^^^^^^^^^^^^^^^^^^^^^
  File "C:\Users\Skeleton\PycharmProjects\Supp0rtBot\TgBot3.py", line 2084, in send_uptime_message
    await context.bot.send_message(
          ~~~~~~~~~~~~~~~~~~~~~~~~^
        chat_id=ACTIVITY_CHECK_CHAT_ID,
        ^^^^^^^^^^^^^^^^^^^^^^^^^^^^^^^
        text=f"Бот активен уже {uptime_hours} часов"
        ^^^^^^^^^^^^^^^^^^^^^^^^^^^^^^^^^^^^^^^^^^^^
    )
    ^
TypeError: User.send_message() got an unexpected keyword argument 'chat_id'
2025-07-29 16:51:54,053 - apscheduler.executors.default - ERROR - Job "send_uptime_message (trigger: interval[0:00:01], next run at: 2025-07-29 16:51:55 EEST)" raised an exception
Traceback (most recent call last):
  File "C:\Users\Skeleton\PycharmProjects\Supp0rtBot\.venv\Lib\site-packages\apscheduler\executors\base.py", line 181, in run_coroutine_job
    retval = await job.func(*job.args, **job.kwargs)
             ^^^^^^^^^^^^^^^^^^^^^^^^^^^^^^^^^^^^^^^
  File "C:\Users\Skeleton\PycharmProjects\Supp0rtBot\TgBot3.py", line 2084, in send_uptime_message
    await context.bot.send_message(
          ~~~~~~~~~~~~~~~~~~~~~~~~^
        chat_id=ACTIVITY_CHECK_CHAT_ID,
        ^^^^^^^^^^^^^^^^^^^^^^^^^^^^^^^
        text=f"Бот активен уже {uptime_hours} часов"
        ^^^^^^^^^^^^^^^^^^^^^^^^^^^^^^^^^^^^^^^^^^^^
    )
    ^
TypeError: User.send_message() got an unexpected keyword argument 'chat_id'
2025-07-29 16:51:55,052 - apscheduler.executors.default - ERROR - Job "send_uptime_message (trigger: interval[0:00:01], next run at: 2025-07-29 16:51:56 EEST)" raised an exception
Traceback (most recent call last):
  File "C:\Users\Skeleton\PycharmProjects\Supp0rtBot\.venv\Lib\site-packages\apscheduler\executors\base.py", line 181, in run_coroutine_job
    retval = await job.func(*job.args, **job.kwargs)
             ^^^^^^^^^^^^^^^^^^^^^^^^^^^^^^^^^^^^^^^
  File "C:\Users\Skeleton\PycharmProjects\Supp0rtBot\TgBot3.py", line 2084, in send_uptime_message
    await context.bot.send_message(
          ~~~~~~~~~~~~~~~~~~~~~~~~^
        chat_id=ACTIVITY_CHECK_CHAT_ID,
        ^^^^^^^^^^^^^^^^^^^^^^^^^^^^^^^
        text=f"Бот активен уже {uptime_hours} часов"
        ^^^^^^^^^^^^^^^^^^^^^^^^^^^^^^^^^^^^^^^^^^^^
    )
    ^
TypeError: User.send_message() got an unexpected keyword argument 'chat_id'
2025-07-29 16:51:56,045 - apscheduler.executors.default - ERROR - Job "send_uptime_message (trigger: interval[0:00:01], next run at: 2025-07-29 16:51:57 EEST)" raised an exception
Traceback (most recent call last):
  File "C:\Users\Skeleton\PycharmProjects\Supp0rtBot\.venv\Lib\site-packages\apscheduler\executors\base.py", line 181, in run_coroutine_job
    retval = await job.func(*job.args, **job.kwargs)
             ^^^^^^^^^^^^^^^^^^^^^^^^^^^^^^^^^^^^^^^
  File "C:\Users\Skeleton\PycharmProjects\Supp0rtBot\TgBot3.py", line 2084, in send_uptime_message
    await context.bot.send_message(
          ~~~~~~~~~~~~~~~~~~~~~~~~^
        chat_id=ACTIVITY_CHECK_CHAT_ID,
        ^^^^^^^^^^^^^^^^^^^^^^^^^^^^^^^
        text=f"Бот активен уже {uptime_hours} часов"
        ^^^^^^^^^^^^^^^^^^^^^^^^^^^^^^^^^^^^^^^^^^^^
    )
    ^
TypeError: User.send_message() got an unexpected keyword argument 'chat_id'
2025-07-29 16:51:56,564 - telegram.ext.Application - ERROR - No error handlers are registered, logging exception.
Traceback (most recent call last):
  File "C:\Users\Skeleton\PycharmProjects\Supp0rtBot\.venv\Lib\site-packages\telegram\ext\_updater.py", line 750, in _network_loop_retry
    if not await do_action():
           ^^^^^^^^^^^^^^^^^
  File "C:\Users\Skeleton\PycharmProjects\Supp0rtBot\.venv\Lib\site-packages\telegram\ext\_updater.py", line 744, in do_action
    return action_cb_task.result()
           ~~~~~~~~~~~~~~~~~~~~~^^
  File "C:\Program Files\Python313\Lib\asyncio\futures.py", line 199, in result
    raise self._exception.with_traceback(self._exception_tb)
  File "C:\Program Files\Python313\Lib\asyncio\tasks.py", line 304, in __step_run_and_handle_result
    result = coro.send(None)
  File "C:\Users\Skeleton\PycharmProjects\Supp0rtBot\.venv\Lib\site-packages\telegram\ext\_updater.py", line 371, in polling_action_cb
    updates = await self.bot.get_updates(
              ^^^^^^^^^^^^^^^^^^^^^^^^^^^
    ...<7 lines>...
    )
    ^
  File "C:\Users\Skeleton\PycharmProjects\Supp0rtBot\.venv\Lib\site-packages\telegram\ext\_extbot.py", line 650, in get_updates
    updates = await super().get_updates(
              ^^^^^^^^^^^^^^^^^^^^^^^^^^
    ...<9 lines>...
    )
    ^
  File "C:\Users\Skeleton\PycharmProjects\Supp0rtBot\.venv\Lib\site-packages\telegram\_bot.py", line 4480, in get_updates
    await self._post(
    ^^^^^^^^^^^^^^^^^
    ...<7 lines>...
    ),
    ^
  File "C:\Users\Skeleton\PycharmProjects\Supp0rtBot\.venv\Lib\site-packages\telegram\_bot.py", line 619, in _post
    return await self._do_post(
           ^^^^^^^^^^^^^^^^^^^^
    ...<6 lines>...
    )
    ^
  File "C:\Users\Skeleton\PycharmProjects\Supp0rtBot\.venv\Lib\site-packages\telegram\ext\_extbot.py", line 354, in _do_post
    return await super()._do_post(
           ^^^^^^^^^^^^^^^^^^^^^^^
    ...<6 lines>...
    )
    ^
  File "C:\Users\Skeleton\PycharmProjects\Supp0rtBot\.venv\Lib\site-packages\telegram\_bot.py", line 648, in _do_post
    result = await request.post(
             ^^^^^^^^^^^^^^^^^^^
    ...<6 lines>...
    )
    ^
  File "C:\Users\Skeleton\PycharmProjects\Supp0rtBot\.venv\Lib\site-packages\telegram\request\_baserequest.py", line 202, in post
    result = await self._request_wrapper(
             ^^^^^^^^^^^^^^^^^^^^^^^^^^^^
    ...<7 lines>...
    )
    ^
  File "C:\Users\Skeleton\PycharmProjects\Supp0rtBot\.venv\Lib\site-packages\telegram\request\_baserequest.py", line 385, in _request_wrapper
    raise Conflict(message)
telegram.error.Conflict: Conflict: terminated by other getUpdates request; make sure that only one bot instance is running
2025-07-29 16:51:57,044 - apscheduler.executors.default - ERROR - Job "send_uptime_message (trigger: interval[0:00:01], next run at: 2025-07-29 16:51:58 EEST)" raised an exception
Traceback (most recent call last):
  File "C:\Users\Skeleton\PycharmProjects\Supp0rtBot\.venv\Lib\site-packages\apscheduler\executors\base.py", line 181, in run_coroutine_job
    retval = await job.func(*job.args, **job.kwargs)
             ^^^^^^^^^^^^^^^^^^^^^^^^^^^^^^^^^^^^^^^
  File "C:\Users\Skeleton\PycharmProjects\Supp0rtBot\TgBot3.py", line 2084, in send_uptime_message
    await context.bot.send_message(
          ~~~~~~~~~~~~~~~~~~~~~~~~^
        chat_id=ACTIVITY_CHECK_CHAT_ID,
        ^^^^^^^^^^^^^^^^^^^^^^^^^^^^^^^
        text=f"Бот активен уже {uptime_hours} часов"
        ^^^^^^^^^^^^^^^^^^^^^^^^^^^^^^^^^^^^^^^^^^^^
    )
    ^
TypeError: User.send_message() got an unexpected keyword argument 'chat_id'
2025-07-29 16:51:58,042 - apscheduler.executors.default - ERROR - Job "send_uptime_message (trigger: interval[0:00:01], next run at: 2025-07-29 16:51:59 EEST)" raised an exception
Traceback (most recent call last):
  File "C:\Users\Skeleton\PycharmProjects\Supp0rtBot\.venv\Lib\site-packages\apscheduler\executors\base.py", line 181, in run_coroutine_job
    retval = await job.func(*job.args, **job.kwargs)
             ^^^^^^^^^^^^^^^^^^^^^^^^^^^^^^^^^^^^^^^
  File "C:\Users\Skeleton\PycharmProjects\Supp0rtBot\TgBot3.py", line 2084, in send_uptime_message
    await context.bot.send_message(
          ~~~~~~~~~~~~~~~~~~~~~~~~^
        chat_id=ACTIVITY_CHECK_CHAT_ID,
        ^^^^^^^^^^^^^^^^^^^^^^^^^^^^^^^
        text=f"Бот активен уже {uptime_hours} часов"
        ^^^^^^^^^^^^^^^^^^^^^^^^^^^^^^^^^^^^^^^^^^^^
    )
    ^
TypeError: User.send_message() got an unexpected keyword argument 'chat_id'
2025-07-29 16:51:59,054 - apscheduler.executors.default - ERROR - Job "send_uptime_message (trigger: interval[0:00:01], next run at: 2025-07-29 16:52:00 EEST)" raised an exception
Traceback (most recent call last):
  File "C:\Users\Skeleton\PycharmProjects\Supp0rtBot\.venv\Lib\site-packages\apscheduler\executors\base.py", line 181, in run_coroutine_job
    retval = await job.func(*job.args, **job.kwargs)
             ^^^^^^^^^^^^^^^^^^^^^^^^^^^^^^^^^^^^^^^
  File "C:\Users\Skeleton\PycharmProjects\Supp0rtBot\TgBot3.py", line 2084, in send_uptime_message
    await context.bot.send_message(
          ~~~~~~~~~~~~~~~~~~~~~~~~^
        chat_id=ACTIVITY_CHECK_CHAT_ID,
        ^^^^^^^^^^^^^^^^^^^^^^^^^^^^^^^
        text=f"Бот активен уже {uptime_hours} часов"
        ^^^^^^^^^^^^^^^^^^^^^^^^^^^^^^^^^^^^^^^^^^^^
    )
    ^
TypeError: User.send_message() got an unexpected keyword argument 'chat_id'
2025-07-29 16:52:00,052 - apscheduler.executors.default - ERROR - Job "send_uptime_message (trigger: interval[0:00:01], next run at: 2025-07-29 16:52:01 EEST)" raised an exception
Traceback (most recent call last):
  File "C:\Users\Skeleton\PycharmProjects\Supp0rtBot\.venv\Lib\site-packages\apscheduler\executors\base.py", line 181, in run_coroutine_job
    retval = await job.func(*job.args, **job.kwargs)
             ^^^^^^^^^^^^^^^^^^^^^^^^^^^^^^^^^^^^^^^
  File "C:\Users\Skeleton\PycharmProjects\Supp0rtBot\TgBot3.py", line 2084, in send_uptime_message
    await context.bot.send_message(
          ~~~~~~~~~~~~~~~~~~~~~~~~^
        chat_id=ACTIVITY_CHECK_CHAT_ID,
        ^^^^^^^^^^^^^^^^^^^^^^^^^^^^^^^
        text=f"Бот активен уже {uptime_hours} часов"
        ^^^^^^^^^^^^^^^^^^^^^^^^^^^^^^^^^^^^^^^^^^^^
    )
    ^
TypeError: User.send_message() got an unexpected keyword argument 'chat_id'
2025-07-29 16:52:01,046 - apscheduler.executors.default - ERROR - Job "send_uptime_message (trigger: interval[0:00:01], next run at: 2025-07-29 16:52:02 EEST)" raised an exception
Traceback (most recent call last):
  File "C:\Users\Skeleton\PycharmProjects\Supp0rtBot\.venv\Lib\site-packages\apscheduler\executors\base.py", line 181, in run_coroutine_job
    retval = await job.func(*job.args, **job.kwargs)
             ^^^^^^^^^^^^^^^^^^^^^^^^^^^^^^^^^^^^^^^
  File "C:\Users\Skeleton\PycharmProjects\Supp0rtBot\TgBot3.py", line 2084, in send_uptime_message
    await context.bot.send_message(
          ~~~~~~~~~~~~~~~~~~~~~~~~^
        chat_id=ACTIVITY_CHECK_CHAT_ID,
        ^^^^^^^^^^^^^^^^^^^^^^^^^^^^^^^
        text=f"Бот активен уже {uptime_hours} часов"
        ^^^^^^^^^^^^^^^^^^^^^^^^^^^^^^^^^^^^^^^^^^^^
    )
    ^
TypeError: User.send_message() got an unexpected keyword argument 'chat_id'
2025-07-29 16:52:02,042 - apscheduler.executors.default - ERROR - Job "send_uptime_message (trigger: interval[0:00:01], next run at: 2025-07-29 16:52:03 EEST)" raised an exception
Traceback (most recent call last):
  File "C:\Users\Skeleton\PycharmProjects\Supp0rtBot\.venv\Lib\site-packages\apscheduler\executors\base.py", line 181, in run_coroutine_job
    retval = await job.func(*job.args, **job.kwargs)
             ^^^^^^^^^^^^^^^^^^^^^^^^^^^^^^^^^^^^^^^
  File "C:\Users\Skeleton\PycharmProjects\Supp0rtBot\TgBot3.py", line 2084, in send_uptime_message
    await context.bot.send_message(
          ~~~~~~~~~~~~~~~~~~~~~~~~^
        chat_id=ACTIVITY_CHECK_CHAT_ID,
        ^^^^^^^^^^^^^^^^^^^^^^^^^^^^^^^
        text=f"Бот активен уже {uptime_hours} часов"
        ^^^^^^^^^^^^^^^^^^^^^^^^^^^^^^^^^^^^^^^^^^^^
    )
    ^
TypeError: User.send_message() got an unexpected keyword argument 'chat_id'
2025-07-29 16:52:03,045 - apscheduler.executors.default - ERROR - Job "send_uptime_message (trigger: interval[0:00:01], next run at: 2025-07-29 16:52:04 EEST)" raised an exception
Traceback (most recent call last):
  File "C:\Users\Skeleton\PycharmProjects\Supp0rtBot\.venv\Lib\site-packages\apscheduler\executors\base.py", line 181, in run_coroutine_job
    retval = await job.func(*job.args, **job.kwargs)
             ^^^^^^^^^^^^^^^^^^^^^^^^^^^^^^^^^^^^^^^
  File "C:\Users\Skeleton\PycharmProjects\Supp0rtBot\TgBot3.py", line 2084, in send_uptime_message
    await context.bot.send_message(
          ~~~~~~~~~~~~~~~~~~~~~~~~^
        chat_id=ACTIVITY_CHECK_CHAT_ID,
        ^^^^^^^^^^^^^^^^^^^^^^^^^^^^^^^
        text=f"Бот активен уже {uptime_hours} часов"
        ^^^^^^^^^^^^^^^^^^^^^^^^^^^^^^^^^^^^^^^^^^^^
    )
    ^
TypeError: User.send_message() got an unexpected keyword argument 'chat_id'
2025-07-29 16:52:03,537 - telegram.ext.Application - ERROR - No error handlers are registered, logging exception.
Traceback (most recent call last):
  File "C:\Users\Skeleton\PycharmProjects\Supp0rtBot\.venv\Lib\site-packages\telegram\ext\_updater.py", line 750, in _network_loop_retry
    if not await do_action():
           ^^^^^^^^^^^^^^^^^
  File "C:\Users\Skeleton\PycharmProjects\Supp0rtBot\.venv\Lib\site-packages\telegram\ext\_updater.py", line 744, in do_action
    return action_cb_task.result()
           ~~~~~~~~~~~~~~~~~~~~~^^
  File "C:\Program Files\Python313\Lib\asyncio\futures.py", line 199, in result
    raise self._exception.with_traceback(self._exception_tb)
  File "C:\Program Files\Python313\Lib\asyncio\tasks.py", line 304, in __step_run_and_handle_result
    result = coro.send(None)
  File "C:\Users\Skeleton\PycharmProjects\Supp0rtBot\.venv\Lib\site-packages\telegram\ext\_updater.py", line 371, in polling_action_cb
    updates = await self.bot.get_updates(
              ^^^^^^^^^^^^^^^^^^^^^^^^^^^
    ...<7 lines>...
    )
    ^
  File "C:\Users\Skeleton\PycharmProjects\Supp0rtBot\.venv\Lib\site-packages\telegram\ext\_extbot.py", line 650, in get_updates
    updates = await super().get_updates(
              ^^^^^^^^^^^^^^^^^^^^^^^^^^
    ...<9 lines>...
    )
    ^
  File "C:\Users\Skeleton\PycharmProjects\Supp0rtBot\.venv\Lib\site-packages\telegram\_bot.py", line 4480, in get_updates
    await self._post(
    ^^^^^^^^^^^^^^^^^
    ...<7 lines>...
    ),
    ^
  File "C:\Users\Skeleton\PycharmProjects\Supp0rtBot\.venv\Lib\site-packages\telegram\_bot.py", line 619, in _post
    return await self._do_post(
           ^^^^^^^^^^^^^^^^^^^^
    ...<6 lines>...
    )
    ^
  File "C:\Users\Skeleton\PycharmProjects\Supp0rtBot\.venv\Lib\site-packages\telegram\ext\_extbot.py", line 354, in _do_post
    return await super()._do_post(
           ^^^^^^^^^^^^^^^^^^^^^^^
    ...<6 lines>...
    )
    ^
  File "C:\Users\Skeleton\PycharmProjects\Supp0rtBot\.venv\Lib\site-packages\telegram\_bot.py", line 648, in _do_post
    result = await request.post(
             ^^^^^^^^^^^^^^^^^^^
    ...<6 lines>...
    )
    ^
  File "C:\Users\Skeleton\PycharmProjects\Supp0rtBot\.venv\Lib\site-packages\telegram\request\_baserequest.py", line 202, in post
    result = await self._request_wrapper(
             ^^^^^^^^^^^^^^^^^^^^^^^^^^^^
    ...<7 lines>...
    )
    ^
  File "C:\Users\Skeleton\PycharmProjects\Supp0rtBot\.venv\Lib\site-packages\telegram\request\_baserequest.py", line 385, in _request_wrapper
    raise Conflict(message)
telegram.error.Conflict: Conflict: terminated by other getUpdates request; make sure that only one bot instance is running
2025-07-29 16:52:04,042 - apscheduler.executors.default - ERROR - Job "send_uptime_message (trigger: interval[0:00:01], next run at: 2025-07-29 16:52:05 EEST)" raised an exception
Traceback (most recent call last):
  File "C:\Users\Skeleton\PycharmProjects\Supp0rtBot\.venv\Lib\site-packages\apscheduler\executors\base.py", line 181, in run_coroutine_job
    retval = await job.func(*job.args, **job.kwargs)
             ^^^^^^^^^^^^^^^^^^^^^^^^^^^^^^^^^^^^^^^
  File "C:\Users\Skeleton\PycharmProjects\Supp0rtBot\TgBot3.py", line 2084, in send_uptime_message
    await context.bot.send_message(
          ~~~~~~~~~~~~~~~~~~~~~~~~^
        chat_id=ACTIVITY_CHECK_CHAT_ID,
        ^^^^^^^^^^^^^^^^^^^^^^^^^^^^^^^
        text=f"Бот активен уже {uptime_hours} часов"
        ^^^^^^^^^^^^^^^^^^^^^^^^^^^^^^^^^^^^^^^^^^^^
    )
    ^
TypeError: User.send_message() got an unexpected keyword argument 'chat_id'
2025-07-29 16:52:05,048 - apscheduler.executors.default - ERROR - Job "send_uptime_message (trigger: interval[0:00:01], next run at: 2025-07-29 16:52:06 EEST)" raised an exception
Traceback (most recent call last):
  File "C:\Users\Skeleton\PycharmProjects\Supp0rtBot\.venv\Lib\site-packages\apscheduler\executors\base.py", line 181, in run_coroutine_job
    retval = await job.func(*job.args, **job.kwargs)
             ^^^^^^^^^^^^^^^^^^^^^^^^^^^^^^^^^^^^^^^
  File "C:\Users\Skeleton\PycharmProjects\Supp0rtBot\TgBot3.py", line 2084, in send_uptime_message
    await context.bot.send_message(
          ~~~~~~~~~~~~~~~~~~~~~~~~^
        chat_id=ACTIVITY_CHECK_CHAT_ID,
        ^^^^^^^^^^^^^^^^^^^^^^^^^^^^^^^
        text=f"Бот активен уже {uptime_hours} часов"
        ^^^^^^^^^^^^^^^^^^^^^^^^^^^^^^^^^^^^^^^^^^^^
    )
    ^
TypeError: User.send_message() got an unexpected keyword argument 'chat_id'
2025-07-29 16:52:06,043 - apscheduler.executors.default - ERROR - Job "send_uptime_message (trigger: interval[0:00:01], next run at: 2025-07-29 16:52:07 EEST)" raised an exception
Traceback (most recent call last):
  File "C:\Users\Skeleton\PycharmProjects\Supp0rtBot\.venv\Lib\site-packages\apscheduler\executors\base.py", line 181, in run_coroutine_job
    retval = await job.func(*job.args, **job.kwargs)
             ^^^^^^^^^^^^^^^^^^^^^^^^^^^^^^^^^^^^^^^
  File "C:\Users\Skeleton\PycharmProjects\Supp0rtBot\TgBot3.py", line 2084, in send_uptime_message
    await context.bot.send_message(
          ~~~~~~~~~~~~~~~~~~~~~~~~^
        chat_id=ACTIVITY_CHECK_CHAT_ID,
        ^^^^^^^^^^^^^^^^^^^^^^^^^^^^^^^
        text=f"Бот активен уже {uptime_hours} часов"
        ^^^^^^^^^^^^^^^^^^^^^^^^^^^^^^^^^^^^^^^^^^^^
    )
    ^
TypeError: User.send_message() got an unexpected keyword argument 'chat_id'
2025-07-29 16:52:07,044 - apscheduler.executors.default - ERROR - Job "send_uptime_message (trigger: interval[0:00:01], next run at: 2025-07-29 16:52:08 EEST)" raised an exception
Traceback (most recent call last):
  File "C:\Users\Skeleton\PycharmProjects\Supp0rtBot\.venv\Lib\site-packages\apscheduler\executors\base.py", line 181, in run_coroutine_job
    retval = await job.func(*job.args, **job.kwargs)
             ^^^^^^^^^^^^^^^^^^^^^^^^^^^^^^^^^^^^^^^
  File "C:\Users\Skeleton\PycharmProjects\Supp0rtBot\TgBot3.py", line 2084, in send_uptime_message
    await context.bot.send_message(
          ~~~~~~~~~~~~~~~~~~~~~~~~^
        chat_id=ACTIVITY_CHECK_CHAT_ID,
        ^^^^^^^^^^^^^^^^^^^^^^^^^^^^^^^
        text=f"Бот активен уже {uptime_hours} часов"
        ^^^^^^^^^^^^^^^^^^^^^^^^^^^^^^^^^^^^^^^^^^^^
    )
    ^
TypeError: User.send_message() got an unexpected keyword argument 'chat_id'
2025-07-29 16:52:08,043 - apscheduler.executors.default - ERROR - Job "send_uptime_message (trigger: interval[0:00:01], next run at: 2025-07-29 16:52:09 EEST)" raised an exception
Traceback (most recent call last):
  File "C:\Users\Skeleton\PycharmProjects\Supp0rtBot\.venv\Lib\site-packages\apscheduler\executors\base.py", line 181, in run_coroutine_job
    retval = await job.func(*job.args, **job.kwargs)
             ^^^^^^^^^^^^^^^^^^^^^^^^^^^^^^^^^^^^^^^
  File "C:\Users\Skeleton\PycharmProjects\Supp0rtBot\TgBot3.py", line 2084, in send_uptime_message
    await context.bot.send_message(
          ~~~~~~~~~~~~~~~~~~~~~~~~^
        chat_id=ACTIVITY_CHECK_CHAT_ID,
        ^^^^^^^^^^^^^^^^^^^^^^^^^^^^^^^
        text=f"Бот активен уже {uptime_hours} часов"
        ^^^^^^^^^^^^^^^^^^^^^^^^^^^^^^^^^^^^^^^^^^^^
    )
    ^
TypeError: User.send_message() got an unexpected keyword argument 'chat_id'
2025-07-29 16:52:09,054 - apscheduler.executors.default - ERROR - Job "send_uptime_message (trigger: interval[0:00:01], next run at: 2025-07-29 16:52:10 EEST)" raised an exception
Traceback (most recent call last):
  File "C:\Users\Skeleton\PycharmProjects\Supp0rtBot\.venv\Lib\site-packages\apscheduler\executors\base.py", line 181, in run_coroutine_job
    retval = await job.func(*job.args, **job.kwargs)
             ^^^^^^^^^^^^^^^^^^^^^^^^^^^^^^^^^^^^^^^
  File "C:\Users\Skeleton\PycharmProjects\Supp0rtBot\TgBot3.py", line 2084, in send_uptime_message
    await context.bot.send_message(
          ~~~~~~~~~~~~~~~~~~~~~~~~^
        chat_id=ACTIVITY_CHECK_CHAT_ID,
        ^^^^^^^^^^^^^^^^^^^^^^^^^^^^^^^
        text=f"Бот активен уже {uptime_hours} часов"
        ^^^^^^^^^^^^^^^^^^^^^^^^^^^^^^^^^^^^^^^^^^^^
    )
    ^
TypeError: User.send_message() got an unexpected keyword argument 'chat_id'
2025-07-29 16:52:09,384 - telegram.ext.Application - ERROR - No error handlers are registered, logging exception.
Traceback (most recent call last):
  File "C:\Users\Skeleton\PycharmProjects\Supp0rtBot\.venv\Lib\site-packages\telegram\ext\_updater.py", line 750, in _network_loop_retry
    if not await do_action():
           ^^^^^^^^^^^^^^^^^
  File "C:\Users\Skeleton\PycharmProjects\Supp0rtBot\.venv\Lib\site-packages\telegram\ext\_updater.py", line 744, in do_action
    return action_cb_task.result()
           ~~~~~~~~~~~~~~~~~~~~~^^
  File "C:\Program Files\Python313\Lib\asyncio\futures.py", line 199, in result
    raise self._exception.with_traceback(self._exception_tb)
  File "C:\Program Files\Python313\Lib\asyncio\tasks.py", line 304, in __step_run_and_handle_result
    result = coro.send(None)
  File "C:\Users\Skeleton\PycharmProjects\Supp0rtBot\.venv\Lib\site-packages\telegram\ext\_updater.py", line 371, in polling_action_cb
    updates = await self.bot.get_updates(
              ^^^^^^^^^^^^^^^^^^^^^^^^^^^
    ...<7 lines>...
    )
    ^
  File "C:\Users\Skeleton\PycharmProjects\Supp0rtBot\.venv\Lib\site-packages\telegram\ext\_extbot.py", line 650, in get_updates
    updates = await super().get_updates(
              ^^^^^^^^^^^^^^^^^^^^^^^^^^
    ...<9 lines>...
    )
    ^
  File "C:\Users\Skeleton\PycharmProjects\Supp0rtBot\.venv\Lib\site-packages\telegram\_bot.py", line 4480, in get_updates
    await self._post(
    ^^^^^^^^^^^^^^^^^
    ...<7 lines>...
    ),
    ^
  File "C:\Users\Skeleton\PycharmProjects\Supp0rtBot\.venv\Lib\site-packages\telegram\_bot.py", line 619, in _post
    return await self._do_post(
           ^^^^^^^^^^^^^^^^^^^^
    ...<6 lines>...
    )
    ^
  File "C:\Users\Skeleton\PycharmProjects\Supp0rtBot\.venv\Lib\site-packages\telegram\ext\_extbot.py", line 354, in _do_post
    return await super()._do_post(
           ^^^^^^^^^^^^^^^^^^^^^^^
    ...<6 lines>...
    )
    ^
  File "C:\Users\Skeleton\PycharmProjects\Supp0rtBot\.venv\Lib\site-packages\telegram\_bot.py", line 648, in _do_post
    result = await request.post(
             ^^^^^^^^^^^^^^^^^^^
    ...<6 lines>...
    )
    ^
  File "C:\Users\Skeleton\PycharmProjects\Supp0rtBot\.venv\Lib\site-packages\telegram\request\_baserequest.py", line 202, in post
    result = await self._request_wrapper(
             ^^^^^^^^^^^^^^^^^^^^^^^^^^^^
    ...<7 lines>...
    )
    ^
  File "C:\Users\Skeleton\PycharmProjects\Supp0rtBot\.venv\Lib\site-packages\telegram\request\_baserequest.py", line 385, in _request_wrapper
    raise Conflict(message)
telegram.error.Conflict: Conflict: terminated by other getUpdates request; make sure that only one bot instance is running
2025-07-29 16:52:10,054 - apscheduler.executors.default - ERROR - Job "send_uptime_message (trigger: interval[0:00:01], next run at: 2025-07-29 16:52:11 EEST)" raised an exception
Traceback (most recent call last):
  File "C:\Users\Skeleton\PycharmProjects\Supp0rtBot\.venv\Lib\site-packages\apscheduler\executors\base.py", line 181, in run_coroutine_job
    retval = await job.func(*job.args, **job.kwargs)
             ^^^^^^^^^^^^^^^^^^^^^^^^^^^^^^^^^^^^^^^
  File "C:\Users\Skeleton\PycharmProjects\Supp0rtBot\TgBot3.py", line 2084, in send_uptime_message
    await context.bot.send_message(
          ~~~~~~~~~~~~~~~~~~~~~~~~^
        chat_id=ACTIVITY_CHECK_CHAT_ID,
        ^^^^^^^^^^^^^^^^^^^^^^^^^^^^^^^
        text=f"Бот активен уже {uptime_hours} часов"
        ^^^^^^^^^^^^^^^^^^^^^^^^^^^^^^^^^^^^^^^^^^^^
    )
    ^
TypeError: User.send_message() got an unexpected keyword argument 'chat_id'
2025-07-29 16:52:11,053 - apscheduler.executors.default - ERROR - Job "send_uptime_message (trigger: interval[0:00:01], next run at: 2025-07-29 16:52:12 EEST)" raised an exception
Traceback (most recent call last):
  File "C:\Users\Skeleton\PycharmProjects\Supp0rtBot\.venv\Lib\site-packages\apscheduler\executors\base.py", line 181, in run_coroutine_job
    retval = await job.func(*job.args, **job.kwargs)
             ^^^^^^^^^^^^^^^^^^^^^^^^^^^^^^^^^^^^^^^
  File "C:\Users\Skeleton\PycharmProjects\Supp0rtBot\TgBot3.py", line 2084, in send_uptime_message
    await context.bot.send_message(
          ~~~~~~~~~~~~~~~~~~~~~~~~^
        chat_id=ACTIVITY_CHECK_CHAT_ID,
        ^^^^^^^^^^^^^^^^^^^^^^^^^^^^^^^
        text=f"Бот активен уже {uptime_hours} часов"
        ^^^^^^^^^^^^^^^^^^^^^^^^^^^^^^^^^^^^^^^^^^^^
    )
    ^
TypeError: User.send_message() got an unexpected keyword argument 'chat_id'
2025-07-29 16:52:12,044 - apscheduler.executors.default - ERROR - Job "send_uptime_message (trigger: interval[0:00:01], next run at: 2025-07-29 16:52:13 EEST)" raised an exception
Traceback (most recent call last):
  File "C:\Users\Skeleton\PycharmProjects\Supp0rtBot\.venv\Lib\site-packages\apscheduler\executors\base.py", line 181, in run_coroutine_job
    retval = await job.func(*job.args, **job.kwargs)
             ^^^^^^^^^^^^^^^^^^^^^^^^^^^^^^^^^^^^^^^
  File "C:\Users\Skeleton\PycharmProjects\Supp0rtBot\TgBot3.py", line 2084, in send_uptime_message
    await context.bot.send_message(
          ~~~~~~~~~~~~~~~~~~~~~~~~^
        chat_id=ACTIVITY_CHECK_CHAT_ID,
        ^^^^^^^^^^^^^^^^^^^^^^^^^^^^^^^
        text=f"Бот активен уже {uptime_hours} часов"
        ^^^^^^^^^^^^^^^^^^^^^^^^^^^^^^^^^^^^^^^^^^^^
    )
    ^
TypeError: User.send_message() got an unexpected keyword argument 'chat_id'
2025-07-29 16:52:13,059 - apscheduler.executors.default - ERROR - Job "send_uptime_message (trigger: interval[0:00:01], next run at: 2025-07-29 16:52:14 EEST)" raised an exception
Traceback (most recent call last):
  File "C:\Users\Skeleton\PycharmProjects\Supp0rtBot\.venv\Lib\site-packages\apscheduler\executors\base.py", line 181, in run_coroutine_job
    retval = await job.func(*job.args, **job.kwargs)
             ^^^^^^^^^^^^^^^^^^^^^^^^^^^^^^^^^^^^^^^
  File "C:\Users\Skeleton\PycharmProjects\Supp0rtBot\TgBot3.py", line 2084, in send_uptime_message
    await context.bot.send_message(
          ~~~~~~~~~~~~~~~~~~~~~~~~^
        chat_id=ACTIVITY_CHECK_CHAT_ID,
        ^^^^^^^^^^^^^^^^^^^^^^^^^^^^^^^
        text=f"Бот активен уже {uptime_hours} часов"
        ^^^^^^^^^^^^^^^^^^^^^^^^^^^^^^^^^^^^^^^^^^^^
    )
    ^
TypeError: User.send_message() got an unexpected keyword argument 'chat_id'
2025-07-29 16:52:14,049 - apscheduler.executors.default - ERROR - Job "send_uptime_message (trigger: interval[0:00:01], next run at: 2025-07-29 16:52:15 EEST)" raised an exception
Traceback (most recent call last):
  File "C:\Users\Skeleton\PycharmProjects\Supp0rtBot\.venv\Lib\site-packages\apscheduler\executors\base.py", line 181, in run_coroutine_job
    retval = await job.func(*job.args, **job.kwargs)
             ^^^^^^^^^^^^^^^^^^^^^^^^^^^^^^^^^^^^^^^
  File "C:\Users\Skeleton\PycharmProjects\Supp0rtBot\TgBot3.py", line 2084, in send_uptime_message
    await context.bot.send_message(
          ~~~~~~~~~~~~~~~~~~~~~~~~^
        chat_id=ACTIVITY_CHECK_CHAT_ID,
        ^^^^^^^^^^^^^^^^^^^^^^^^^^^^^^^
        text=f"Бот активен уже {uptime_hours} часов"
        ^^^^^^^^^^^^^^^^^^^^^^^^^^^^^^^^^^^^^^^^^^^^
    )
    ^
TypeError: User.send_message() got an unexpected keyword argument 'chat_id'
2025-07-29 16:52:15,053 - apscheduler.executors.default - ERROR - Job "send_uptime_message (trigger: interval[0:00:01], next run at: 2025-07-29 16:52:16 EEST)" raised an exception
Traceback (most recent call last):
  File "C:\Users\Skeleton\PycharmProjects\Supp0rtBot\.venv\Lib\site-packages\apscheduler\executors\base.py", line 181, in run_coroutine_job
    retval = await job.func(*job.args, **job.kwargs)
             ^^^^^^^^^^^^^^^^^^^^^^^^^^^^^^^^^^^^^^^
  File "C:\Users\Skeleton\PycharmProjects\Supp0rtBot\TgBot3.py", line 2084, in send_uptime_message
    await context.bot.send_message(
          ~~~~~~~~~~~~~~~~~~~~~~~~^
        chat_id=ACTIVITY_CHECK_CHAT_ID,
        ^^^^^^^^^^^^^^^^^^^^^^^^^^^^^^^
        text=f"Бот активен уже {uptime_hours} часов"
        ^^^^^^^^^^^^^^^^^^^^^^^^^^^^^^^^^^^^^^^^^^^^
    )
    ^
TypeError: User.send_message() got an unexpected keyword argument 'chat_id'
2025-07-29 16:52:16,052 - apscheduler.executors.default - ERROR - Job "send_uptime_message (trigger: interval[0:00:01], next run at: 2025-07-29 16:52:17 EEST)" raised an exception
Traceback (most recent call last):
  File "C:\Users\Skeleton\PycharmProjects\Supp0rtBot\.venv\Lib\site-packages\apscheduler\executors\base.py", line 181, in run_coroutine_job
    retval = await job.func(*job.args, **job.kwargs)
             ^^^^^^^^^^^^^^^^^^^^^^^^^^^^^^^^^^^^^^^
  File "C:\Users\Skeleton\PycharmProjects\Supp0rtBot\TgBot3.py", line 2084, in send_uptime_message
    await context.bot.send_message(
          ~~~~~~~~~~~~~~~~~~~~~~~~^
        chat_id=ACTIVITY_CHECK_CHAT_ID,
        ^^^^^^^^^^^^^^^^^^^^^^^^^^^^^^^
        text=f"Бот активен уже {uptime_hours} часов"
        ^^^^^^^^^^^^^^^^^^^^^^^^^^^^^^^^^^^^^^^^^^^^
    )
    ^
TypeError: User.send_message() got an unexpected keyword argument 'chat_id'
2025-07-29 16:52:17,047 - apscheduler.executors.default - ERROR - Job "send_uptime_message (trigger: interval[0:00:01], next run at: 2025-07-29 16:52:18 EEST)" raised an exception
Traceback (most recent call last):
  File "C:\Users\Skeleton\PycharmProjects\Supp0rtBot\.venv\Lib\site-packages\apscheduler\executors\base.py", line 181, in run_coroutine_job
    retval = await job.func(*job.args, **job.kwargs)
             ^^^^^^^^^^^^^^^^^^^^^^^^^^^^^^^^^^^^^^^
  File "C:\Users\Skeleton\PycharmProjects\Supp0rtBot\TgBot3.py", line 2084, in send_uptime_message
    await context.bot.send_message(
          ~~~~~~~~~~~~~~~~~~~~~~~~^
        chat_id=ACTIVITY_CHECK_CHAT_ID,
        ^^^^^^^^^^^^^^^^^^^^^^^^^^^^^^^
        text=f"Бот активен уже {uptime_hours} часов"
        ^^^^^^^^^^^^^^^^^^^^^^^^^^^^^^^^^^^^^^^^^^^^
    )
    ^
TypeError: User.send_message() got an unexpected keyword argument 'chat_id'
2025-07-29 16:52:18,055 - apscheduler.executors.default - ERROR - Job "send_uptime_message (trigger: interval[0:00:01], next run at: 2025-07-29 16:52:19 EEST)" raised an exception
Traceback (most recent call last):
  File "C:\Users\Skeleton\PycharmProjects\Supp0rtBot\.venv\Lib\site-packages\apscheduler\executors\base.py", line 181, in run_coroutine_job
    retval = await job.func(*job.args, **job.kwargs)
             ^^^^^^^^^^^^^^^^^^^^^^^^^^^^^^^^^^^^^^^
  File "C:\Users\Skeleton\PycharmProjects\Supp0rtBot\TgBot3.py", line 2084, in send_uptime_message
    await context.bot.send_message(
          ~~~~~~~~~~~~~~~~~~~~~~~~^
        chat_id=ACTIVITY_CHECK_CHAT_ID,
        ^^^^^^^^^^^^^^^^^^^^^^^^^^^^^^^
        text=f"Бот активен уже {uptime_hours} часов"
        ^^^^^^^^^^^^^^^^^^^^^^^^^^^^^^^^^^^^^^^^^^^^
    )
    ^
TypeError: User.send_message() got an unexpected keyword argument 'chat_id'
2025-07-29 16:52:18,393 - telegram.ext.Application - ERROR - No error handlers are registered, logging exception.
Traceback (most recent call last):
  File "C:\Users\Skeleton\PycharmProjects\Supp0rtBot\.venv\Lib\site-packages\telegram\ext\_updater.py", line 750, in _network_loop_retry
    if not await do_action():
           ^^^^^^^^^^^^^^^^^
  File "C:\Users\Skeleton\PycharmProjects\Supp0rtBot\.venv\Lib\site-packages\telegram\ext\_updater.py", line 744, in do_action
    return action_cb_task.result()
           ~~~~~~~~~~~~~~~~~~~~~^^
  File "C:\Program Files\Python313\Lib\asyncio\futures.py", line 199, in result
    raise self._exception.with_traceback(self._exception_tb)
  File "C:\Program Files\Python313\Lib\asyncio\tasks.py", line 304, in __step_run_and_handle_result
    result = coro.send(None)
  File "C:\Users\Skeleton\PycharmProjects\Supp0rtBot\.venv\Lib\site-packages\telegram\ext\_updater.py", line 371, in polling_action_cb
    updates = await self.bot.get_updates(
              ^^^^^^^^^^^^^^^^^^^^^^^^^^^
    ...<7 lines>...
    )
    ^
  File "C:\Users\Skeleton\PycharmProjects\Supp0rtBot\.venv\Lib\site-packages\telegram\ext\_extbot.py", line 650, in get_updates
    updates = await super().get_updates(
              ^^^^^^^^^^^^^^^^^^^^^^^^^^
    ...<9 lines>...
    )
    ^
  File "C:\Users\Skeleton\PycharmProjects\Supp0rtBot\.venv\Lib\site-packages\telegram\_bot.py", line 4480, in get_updates
    await self._post(
    ^^^^^^^^^^^^^^^^^
    ...<7 lines>...
    ),
    ^
  File "C:\Users\Skeleton\PycharmProjects\Supp0rtBot\.venv\Lib\site-packages\telegram\_bot.py", line 619, in _post
    return await self._do_post(
           ^^^^^^^^^^^^^^^^^^^^
    ...<6 lines>...
    )
    ^
  File "C:\Users\Skeleton\PycharmProjects\Supp0rtBot\.venv\Lib\site-packages\telegram\ext\_extbot.py", line 354, in _do_post
    return await super()._do_post(
           ^^^^^^^^^^^^^^^^^^^^^^^
    ...<6 lines>...
    )
    ^
  File "C:\Users\Skeleton\PycharmProjects\Supp0rtBot\.venv\Lib\site-packages\telegram\_bot.py", line 648, in _do_post
    result = await request.post(
             ^^^^^^^^^^^^^^^^^^^
    ...<6 lines>...
    )
    ^
  File "C:\Users\Skeleton\PycharmProjects\Supp0rtBot\.venv\Lib\site-packages\telegram\request\_baserequest.py", line 202, in post
    result = await self._request_wrapper(
             ^^^^^^^^^^^^^^^^^^^^^^^^^^^^
    ...<7 lines>...
    )
    ^
  File "C:\Users\Skeleton\PycharmProjects\Supp0rtBot\.venv\Lib\site-packages\telegram\request\_baserequest.py", line 385, in _request_wrapper
    raise Conflict(message)
telegram.error.Conflict: Conflict: terminated by other getUpdates request; make sure that only one bot instance is running
2025-07-29 16:52:19,050 - apscheduler.executors.default - ERROR - Job "send_uptime_message (trigger: interval[0:00:01], next run at: 2025-07-29 16:52:20 EEST)" raised an exception
Traceback (most recent call last):
  File "C:\Users\Skeleton\PycharmProjects\Supp0rtBot\.venv\Lib\site-packages\apscheduler\executors\base.py", line 181, in run_coroutine_job
    retval = await job.func(*job.args, **job.kwargs)
             ^^^^^^^^^^^^^^^^^^^^^^^^^^^^^^^^^^^^^^^
  File "C:\Users\Skeleton\PycharmProjects\Supp0rtBot\TgBot3.py", line 2084, in send_uptime_message
    await context.bot.send_message(
          ~~~~~~~~~~~~~~~~~~~~~~~~^
        chat_id=ACTIVITY_CHECK_CHAT_ID,
        ^^^^^^^^^^^^^^^^^^^^^^^^^^^^^^^
        text=f"Бот активен уже {uptime_hours} часов"
        ^^^^^^^^^^^^^^^^^^^^^^^^^^^^^^^^^^^^^^^^^^^^
    )
    ^
TypeError: User.send_message() got an unexpected keyword argument 'chat_id'
2025-07-29 16:52:20,056 - apscheduler.executors.default - ERROR - Job "send_uptime_message (trigger: interval[0:00:01], next run at: 2025-07-29 16:52:21 EEST)" raised an exception
Traceback (most recent call last):
  File "C:\Users\Skeleton\PycharmProjects\Supp0rtBot\.venv\Lib\site-packages\apscheduler\executors\base.py", line 181, in run_coroutine_job
    retval = await job.func(*job.args, **job.kwargs)
             ^^^^^^^^^^^^^^^^^^^^^^^^^^^^^^^^^^^^^^^
  File "C:\Users\Skeleton\PycharmProjects\Supp0rtBot\TgBot3.py", line 2084, in send_uptime_message
    await context.bot.send_message(
          ~~~~~~~~~~~~~~~~~~~~~~~~^
        chat_id=ACTIVITY_CHECK_CHAT_ID,
        ^^^^^^^^^^^^^^^^^^^^^^^^^^^^^^^
        text=f"Бот активен уже {uptime_hours} часов"
        ^^^^^^^^^^^^^^^^^^^^^^^^^^^^^^^^^^^^^^^^^^^^
    )
    ^
TypeError: User.send_message() got an unexpected keyword argument 'chat_id'
2025-07-29 16:52:21,052 - apscheduler.executors.default - ERROR - Job "send_uptime_message (trigger: interval[0:00:01], next run at: 2025-07-29 16:52:22 EEST)" raised an exception
Traceback (most recent call last):
  File "C:\Users\Skeleton\PycharmProjects\Supp0rtBot\.venv\Lib\site-packages\apscheduler\executors\base.py", line 181, in run_coroutine_job
    retval = await job.func(*job.args, **job.kwargs)
             ^^^^^^^^^^^^^^^^^^^^^^^^^^^^^^^^^^^^^^^
  File "C:\Users\Skeleton\PycharmProjects\Supp0rtBot\TgBot3.py", line 2084, in send_uptime_message
    await context.bot.send_message(
          ~~~~~~~~~~~~~~~~~~~~~~~~^
        chat_id=ACTIVITY_CHECK_CHAT_ID,
        ^^^^^^^^^^^^^^^^^^^^^^^^^^^^^^^
        text=f"Бот активен уже {uptime_hours} часов"
        ^^^^^^^^^^^^^^^^^^^^^^^^^^^^^^^^^^^^^^^^^^^^
    )
    ^
TypeError: User.send_message() got an unexpected keyword argument 'chat_id'
2025-07-29 16:52:22,047 - apscheduler.executors.default - ERROR - Job "send_uptime_message (trigger: interval[0:00:01], next run at: 2025-07-29 16:52:23 EEST)" raised an exception
Traceback (most recent call last):
  File "C:\Users\Skeleton\PycharmProjects\Supp0rtBot\.venv\Lib\site-packages\apscheduler\executors\base.py", line 181, in run_coroutine_job
    retval = await job.func(*job.args, **job.kwargs)
             ^^^^^^^^^^^^^^^^^^^^^^^^^^^^^^^^^^^^^^^
  File "C:\Users\Skeleton\PycharmProjects\Supp0rtBot\TgBot3.py", line 2084, in send_uptime_message
    await context.bot.send_message(
          ~~~~~~~~~~~~~~~~~~~~~~~~^
        chat_id=ACTIVITY_CHECK_CHAT_ID,
        ^^^^^^^^^^^^^^^^^^^^^^^^^^^^^^^
        text=f"Бот активен уже {uptime_hours} часов"
        ^^^^^^^^^^^^^^^^^^^^^^^^^^^^^^^^^^^^^^^^^^^^
    )
    ^
TypeError: User.send_message() got an unexpected keyword argument 'chat_id'
2025-07-29 16:52:23,042 - apscheduler.executors.default - ERROR - Job "send_uptime_message (trigger: interval[0:00:01], next run at: 2025-07-29 16:52:24 EEST)" raised an exception
Traceback (most recent call last):
  File "C:\Users\Skeleton\PycharmProjects\Supp0rtBot\.venv\Lib\site-packages\apscheduler\executors\base.py", line 181, in run_coroutine_job
    retval = await job.func(*job.args, **job.kwargs)
             ^^^^^^^^^^^^^^^^^^^^^^^^^^^^^^^^^^^^^^^
  File "C:\Users\Skeleton\PycharmProjects\Supp0rtBot\TgBot3.py", line 2084, in send_uptime_message
    await context.bot.send_message(
          ~~~~~~~~~~~~~~~~~~~~~~~~^
        chat_id=ACTIVITY_CHECK_CHAT_ID,
        ^^^^^^^^^^^^^^^^^^^^^^^^^^^^^^^
        text=f"Бот активен уже {uptime_hours} часов"
        ^^^^^^^^^^^^^^^^^^^^^^^^^^^^^^^^^^^^^^^^^^^^
    )
    ^
TypeError: User.send_message() got an unexpected keyword argument 'chat_id'
2025-07-29 16:52:24,053 - apscheduler.executors.default - ERROR - Job "send_uptime_message (trigger: interval[0:00:01], next run at: 2025-07-29 16:52:25 EEST)" raised an exception
Traceback (most recent call last):
  File "C:\Users\Skeleton\PycharmProjects\Supp0rtBot\.venv\Lib\site-packages\apscheduler\executors\base.py", line 181, in run_coroutine_job
    retval = await job.func(*job.args, **job.kwargs)
             ^^^^^^^^^^^^^^^^^^^^^^^^^^^^^^^^^^^^^^^
  File "C:\Users\Skeleton\PycharmProjects\Supp0rtBot\TgBot3.py", line 2084, in send_uptime_message
    await context.bot.send_message(
          ~~~~~~~~~~~~~~~~~~~~~~~~^
        chat_id=ACTIVITY_CHECK_CHAT_ID,
        ^^^^^^^^^^^^^^^^^^^^^^^^^^^^^^^
        text=f"Бот активен уже {uptime_hours} часов"
        ^^^^^^^^^^^^^^^^^^^^^^^^^^^^^^^^^^^^^^^^^^^^
    )
    ^
TypeError: User.send_message() got an unexpected keyword argument 'chat_id'
2025-07-29 16:52:25,047 - apscheduler.executors.default - ERROR - Job "send_uptime_message (trigger: interval[0:00:01], next run at: 2025-07-29 16:52:26 EEST)" raised an exception
Traceback (most recent call last):
  File "C:\Users\Skeleton\PycharmProjects\Supp0rtBot\.venv\Lib\site-packages\apscheduler\executors\base.py", line 181, in run_coroutine_job
    retval = await job.func(*job.args, **job.kwargs)
             ^^^^^^^^^^^^^^^^^^^^^^^^^^^^^^^^^^^^^^^
  File "C:\Users\Skeleton\PycharmProjects\Supp0rtBot\TgBot3.py", line 2084, in send_uptime_message
    await context.bot.send_message(
          ~~~~~~~~~~~~~~~~~~~~~~~~^
        chat_id=ACTIVITY_CHECK_CHAT_ID,
        ^^^^^^^^^^^^^^^^^^^^^^^^^^^^^^^
        text=f"Бот активен уже {uptime_hours} часов"
        ^^^^^^^^^^^^^^^^^^^^^^^^^^^^^^^^^^^^^^^^^^^^
    )
    ^
TypeError: User.send_message() got an unexpected keyword argument 'chat_id'
2025-07-29 16:52:26,053 - apscheduler.executors.default - ERROR - Job "send_uptime_message (trigger: interval[0:00:01], next run at: 2025-07-29 16:52:27 EEST)" raised an exception
Traceback (most recent call last):
  File "C:\Users\Skeleton\PycharmProjects\Supp0rtBot\.venv\Lib\site-packages\apscheduler\executors\base.py", line 181, in run_coroutine_job
    retval = await job.func(*job.args, **job.kwargs)
             ^^^^^^^^^^^^^^^^^^^^^^^^^^^^^^^^^^^^^^^
  File "C:\Users\Skeleton\PycharmProjects\Supp0rtBot\TgBot3.py", line 2084, in send_uptime_message
    await context.bot.send_message(
          ~~~~~~~~~~~~~~~~~~~~~~~~^
        chat_id=ACTIVITY_CHECK_CHAT_ID,
        ^^^^^^^^^^^^^^^^^^^^^^^^^^^^^^^
        text=f"Бот активен уже {uptime_hours} часов"
        ^^^^^^^^^^^^^^^^^^^^^^^^^^^^^^^^^^^^^^^^^^^^
    )
    ^
TypeError: User.send_message() got an unexpected keyword argument 'chat_id'
2025-07-29 16:52:27,055 - apscheduler.executors.default - ERROR - Job "send_uptime_message (trigger: interval[0:00:01], next run at: 2025-07-29 16:52:28 EEST)" raised an exception
Traceback (most recent call last):
  File "C:\Users\Skeleton\PycharmProjects\Supp0rtBot\.venv\Lib\site-packages\apscheduler\executors\base.py", line 181, in run_coroutine_job
    retval = await job.func(*job.args, **job.kwargs)
             ^^^^^^^^^^^^^^^^^^^^^^^^^^^^^^^^^^^^^^^
  File "C:\Users\Skeleton\PycharmProjects\Supp0rtBot\TgBot3.py", line 2084, in send_uptime_message
    await context.bot.send_message(
          ~~~~~~~~~~~~~~~~~~~~~~~~^
        chat_id=ACTIVITY_CHECK_CHAT_ID,
        ^^^^^^^^^^^^^^^^^^^^^^^^^^^^^^^
        text=f"Бот активен уже {uptime_hours} часов"
        ^^^^^^^^^^^^^^^^^^^^^^^^^^^^^^^^^^^^^^^^^^^^
    )
    ^
TypeError: User.send_message() got an unexpected keyword argument 'chat_id'
2025-07-29 16:52:28,053 - apscheduler.executors.default - ERROR - Job "send_uptime_message (trigger: interval[0:00:01], next run at: 2025-07-29 16:52:29 EEST)" raised an exception
Traceback (most recent call last):
  File "C:\Users\Skeleton\PycharmProjects\Supp0rtBot\.venv\Lib\site-packages\apscheduler\executors\base.py", line 181, in run_coroutine_job
    retval = await job.func(*job.args, **job.kwargs)
             ^^^^^^^^^^^^^^^^^^^^^^^^^^^^^^^^^^^^^^^
  File "C:\Users\Skeleton\PycharmProjects\Supp0rtBot\TgBot3.py", line 2084, in send_uptime_message
    await context.bot.send_message(
          ~~~~~~~~~~~~~~~~~~~~~~~~^
        chat_id=ACTIVITY_CHECK_CHAT_ID,
        ^^^^^^^^^^^^^^^^^^^^^^^^^^^^^^^
        text=f"Бот активен уже {uptime_hours} часов"
        ^^^^^^^^^^^^^^^^^^^^^^^^^^^^^^^^^^^^^^^^^^^^
    )
    ^
TypeError: User.send_message() got an unexpected keyword argument 'chat_id'
2025-07-29 16:52:29,048 - apscheduler.executors.default - ERROR - Job "send_uptime_message (trigger: interval[0:00:01], next run at: 2025-07-29 16:52:30 EEST)" raised an exception
Traceback (most recent call last):
  File "C:\Users\Skeleton\PycharmProjects\Supp0rtBot\.venv\Lib\site-packages\apscheduler\executors\base.py", line 181, in run_coroutine_job
    retval = await job.func(*job.args, **job.kwargs)
             ^^^^^^^^^^^^^^^^^^^^^^^^^^^^^^^^^^^^^^^
  File "C:\Users\Skeleton\PycharmProjects\Supp0rtBot\TgBot3.py", line 2084, in send_uptime_message
    await context.bot.send_message(
          ~~~~~~~~~~~~~~~~~~~~~~~~^
        chat_id=ACTIVITY_CHECK_CHAT_ID,
        ^^^^^^^^^^^^^^^^^^^^^^^^^^^^^^^
        text=f"Бот активен уже {uptime_hours} часов"
        ^^^^^^^^^^^^^^^^^^^^^^^^^^^^^^^^^^^^^^^^^^^^
    )
    ^
TypeError: User.send_message() got an unexpected keyword argument 'chat_id'
2025-07-29 16:52:30,041 - apscheduler.executors.default - ERROR - Job "send_uptime_message (trigger: interval[0:00:01], next run at: 2025-07-29 16:52:31 EEST)" raised an exception
Traceback (most recent call last):
  File "C:\Users\Skeleton\PycharmProjects\Supp0rtBot\.venv\Lib\site-packages\apscheduler\executors\base.py", line 181, in run_coroutine_job
    retval = await job.func(*job.args, **job.kwargs)
             ^^^^^^^^^^^^^^^^^^^^^^^^^^^^^^^^^^^^^^^
  File "C:\Users\Skeleton\PycharmProjects\Supp0rtBot\TgBot3.py", line 2084, in send_uptime_message
    await context.bot.send_message(
          ~~~~~~~~~~~~~~~~~~~~~~~~^
        chat_id=ACTIVITY_CHECK_CHAT_ID,
        ^^^^^^^^^^^^^^^^^^^^^^^^^^^^^^^
        text=f"Бот активен уже {uptime_hours} часов"
        ^^^^^^^^^^^^^^^^^^^^^^^^^^^^^^^^^^^^^^^^^^^^
    )
    ^
TypeError: User.send_message() got an unexpected keyword argument 'chat_id'
2025-07-29 16:54:20,606 - werkzeug - INFO - [31m[1mWARNING: This is a development server. Do not use it in a production deployment. Use a production WSGI server instead.[0m
 * Running on all addresses (0.0.0.0)
 * Running on http://127.0.0.1:5000
 * Running on http://192.168.31.10:5000
2025-07-29 16:54:20,607 - werkzeug - INFO - [33mPress CTRL+C to quit[0m
2025-07-29 16:56:11,146 - werkzeug - INFO - [31m[1mWARNING: This is a development server. Do not use it in a production deployment. Use a production WSGI server instead.[0m
 * Running on all addresses (0.0.0.0)
 * Running on http://127.0.0.1:5000
 * Running on http://192.168.31.10:5000
2025-07-29 16:56:11,146 - werkzeug - INFO - [33mPress CTRL+C to quit[0m
2025-07-29 16:57:04,842 - werkzeug - INFO - [31m[1mWARNING: This is a development server. Do not use it in a production deployment. Use a production WSGI server instead.[0m
 * Running on all addresses (0.0.0.0)
 * Running on http://127.0.0.1:5000
 * Running on http://192.168.31.10:5000
2025-07-29 16:57:04,843 - werkzeug - INFO - [33mPress CTRL+C to quit[0m
2025-07-29 16:57:49,837 - werkzeug - INFO - [31m[1mWARNING: This is a development server. Do not use it in a production deployment. Use a production WSGI server instead.[0m
 * Running on all addresses (0.0.0.0)
 * Running on http://127.0.0.1:5000
 * Running on http://192.168.31.10:5000
2025-07-29 16:57:49,837 - werkzeug - INFO - [33mPress CTRL+C to quit[0m
2025-07-29 16:57:56,912 - telegram.ext.Application - ERROR - No error handlers are registered, logging exception.
Traceback (most recent call last):
  File "C:\Users\Skeleton\PycharmProjects\Supp0rtBot\.venv\Lib\site-packages\telegram\ext\_updater.py", line 750, in _network_loop_retry
    if not await do_action():
           ^^^^^^^^^^^^^^^^^
  File "C:\Users\Skeleton\PycharmProjects\Supp0rtBot\.venv\Lib\site-packages\telegram\ext\_updater.py", line 744, in do_action
    return action_cb_task.result()
           ~~~~~~~~~~~~~~~~~~~~~^^
  File "C:\Program Files\Python313\Lib\asyncio\futures.py", line 199, in result
    raise self._exception.with_traceback(self._exception_tb)
  File "C:\Program Files\Python313\Lib\asyncio\tasks.py", line 304, in __step_run_and_handle_result
    result = coro.send(None)
  File "C:\Users\Skeleton\PycharmProjects\Supp0rtBot\.venv\Lib\site-packages\telegram\ext\_updater.py", line 371, in polling_action_cb
    updates = await self.bot.get_updates(
              ^^^^^^^^^^^^^^^^^^^^^^^^^^^
    ...<7 lines>...
    )
    ^
  File "C:\Users\Skeleton\PycharmProjects\Supp0rtBot\.venv\Lib\site-packages\telegram\ext\_extbot.py", line 650, in get_updates
    updates = await super().get_updates(
              ^^^^^^^^^^^^^^^^^^^^^^^^^^
    ...<9 lines>...
    )
    ^
  File "C:\Users\Skeleton\PycharmProjects\Supp0rtBot\.venv\Lib\site-packages\telegram\_bot.py", line 4480, in get_updates
    await self._post(
    ^^^^^^^^^^^^^^^^^
    ...<7 lines>...
    ),
    ^
  File "C:\Users\Skeleton\PycharmProjects\Supp0rtBot\.venv\Lib\site-packages\telegram\_bot.py", line 619, in _post
    return await self._do_post(
           ^^^^^^^^^^^^^^^^^^^^
    ...<6 lines>...
    )
    ^
  File "C:\Users\Skeleton\PycharmProjects\Supp0rtBot\.venv\Lib\site-packages\telegram\ext\_extbot.py", line 354, in _do_post
    return await super()._do_post(
           ^^^^^^^^^^^^^^^^^^^^^^^
    ...<6 lines>...
    )
    ^
  File "C:\Users\Skeleton\PycharmProjects\Supp0rtBot\.venv\Lib\site-packages\telegram\_bot.py", line 648, in _do_post
    result = await request.post(
             ^^^^^^^^^^^^^^^^^^^
    ...<6 lines>...
    )
    ^
  File "C:\Users\Skeleton\PycharmProjects\Supp0rtBot\.venv\Lib\site-packages\telegram\request\_baserequest.py", line 202, in post
    result = await self._request_wrapper(
             ^^^^^^^^^^^^^^^^^^^^^^^^^^^^
    ...<7 lines>...
    )
    ^
  File "C:\Users\Skeleton\PycharmProjects\Supp0rtBot\.venv\Lib\site-packages\telegram\request\_baserequest.py", line 385, in _request_wrapper
    raise Conflict(message)
telegram.error.Conflict: Conflict: terminated by other getUpdates request; make sure that only one bot instance is running
2025-08-01 08:10:15,874 - werkzeug - INFO - [31m[1mWARNING: This is a development server. Do not use it in a production deployment. Use a production WSGI server instead.[0m
 * Running on all addresses (0.0.0.0)
 * Running on http://127.0.0.1:5000
 * Running on http://192.168.31.10:5000
2025-08-01 08:10:15,874 - werkzeug - INFO - [33mPress CTRL+C to quit[0m
2025-08-01 08:11:43,386 - werkzeug - INFO - [31m[1mWARNING: This is a development server. Do not use it in a production deployment. Use a production WSGI server instead.[0m
 * Running on all addresses (0.0.0.0)
 * Running on http://127.0.0.1:5000
 * Running on http://192.168.31.10:5000
2025-08-01 08:11:43,386 - werkzeug - INFO - [33mPress CTRL+C to quit[0m
2025-08-01 08:12:49,377 - werkzeug - INFO - [31m[1mWARNING: This is a development server. Do not use it in a production deployment. Use a production WSGI server instead.[0m
 * Running on all addresses (0.0.0.0)
 * Running on http://127.0.0.1:5000
 * Running on http://192.168.31.10:5000
2025-08-01 08:12:49,378 - werkzeug - INFO - [33mPress CTRL+C to quit[0m
2025-08-01 08:35:11,483 - werkzeug - INFO - [31m[1mWARNING: This is a development server. Do not use it in a production deployment. Use a production WSGI server instead.[0m
 * Running on all addresses (0.0.0.0)
 * Running on http://127.0.0.1:5000
 * Running on http://192.168.31.10:5000
2025-08-01 08:35:11,483 - werkzeug - INFO - [33mPress CTRL+C to quit[0m
2025-08-01 08:38:07,432 - werkzeug - INFO - [31m[1mWARNING: This is a development server. Do not use it in a production deployment. Use a production WSGI server instead.[0m
 * Running on all addresses (0.0.0.0)
 * Running on http://127.0.0.1:5000
 * Running on http://192.168.31.10:5000
2025-08-01 08:38:07,432 - werkzeug - INFO - [33mPress CTRL+C to quit[0m
2025-08-01 08:39:50,701 - werkzeug - INFO - [31m[1mWARNING: This is a development server. Do not use it in a production deployment. Use a production WSGI server instead.[0m
 * Running on all addresses (0.0.0.0)
 * Running on http://127.0.0.1:5000
 * Running on http://192.168.31.10:5000
2025-08-01 08:39:50,701 - werkzeug - INFO - [33mPress CTRL+C to quit[0m
2025-08-01 19:10:27,080 - werkzeug - INFO - [31m[1mWARNING: This is a development server. Do not use it in a production deployment. Use a production WSGI server instead.[0m
 * Running on all addresses (0.0.0.0)
 * Running on http://127.0.0.1:5000
 * Running on http://192.168.31.10:5000
2025-08-01 19:10:27,080 - werkzeug - INFO - [33mPress CTRL+C to quit[0m
2025-08-01 23:00:13,971 - werkzeug - INFO - [31m[1mWARNING: This is a development server. Do not use it in a production deployment. Use a production WSGI server instead.[0m
 * Running on all addresses (0.0.0.0)
 * Running on http://127.0.0.1:5000
 * Running on http://192.168.31.10:5000
2025-08-01 23:00:13,971 - werkzeug - INFO - [33mPress CTRL+C to quit[0m
2025-08-01 23:04:41,081 - werkzeug - INFO - [31m[1mWARNING: This is a development server. Do not use it in a production deployment. Use a production WSGI server instead.[0m
 * Running on all addresses (0.0.0.0)
 * Running on http://127.0.0.1:5000
 * Running on http://192.168.31.10:5000
2025-08-01 23:04:41,081 - werkzeug - INFO - [33mPress CTRL+C to quit[0m
2025-08-01 23:08:36,488 - werkzeug - INFO - [31m[1mWARNING: This is a development server. Do not use it in a production deployment. Use a production WSGI server instead.[0m
 * Running on all addresses (0.0.0.0)
 * Running on http://127.0.0.1:5000
 * Running on http://192.168.31.10:5000
2025-08-01 23:08:36,488 - werkzeug - INFO - [33mPress CTRL+C to quit[0m
2025-08-01 23:15:53,975 - werkzeug - INFO - [31m[1mWARNING: This is a development server. Do not use it in a production deployment. Use a production WSGI server instead.[0m
 * Running on all addresses (0.0.0.0)
 * Running on http://127.0.0.1:5000
 * Running on http://192.168.31.10:5000
2025-08-01 23:15:53,976 - werkzeug - INFO - [33mPress CTRL+C to quit[0m
2025-08-01 23:20:37,692 - werkzeug - INFO - [31m[1mWARNING: This is a development server. Do not use it in a production deployment. Use a production WSGI server instead.[0m
 * Running on all addresses (0.0.0.0)
 * Running on http://127.0.0.1:5000
 * Running on http://192.168.31.10:5000
2025-08-01 23:20:37,692 - werkzeug - INFO - [33mPress CTRL+C to quit[0m
2025-08-01 23:27:38,295 - werkzeug - INFO - [31m[1mWARNING: This is a development server. Do not use it in a production deployment. Use a production WSGI server instead.[0m
 * Running on all addresses (0.0.0.0)
 * Running on http://127.0.0.1:5000
 * Running on http://192.168.31.10:5000
2025-08-01 23:27:38,295 - werkzeug - INFO - [33mPress CTRL+C to quit[0m
2025-08-01 23:29:15,985 - werkzeug - INFO - [31m[1mWARNING: This is a development server. Do not use it in a production deployment. Use a production WSGI server instead.[0m
 * Running on all addresses (0.0.0.0)
 * Running on http://127.0.0.1:5000
 * Running on http://192.168.31.10:5000
2025-08-01 23:29:15,986 - werkzeug - INFO - [33mPress CTRL+C to quit[0m
2025-08-01 23:42:02,642 - werkzeug - INFO - [31m[1mWARNING: This is a development server. Do not use it in a production deployment. Use a production WSGI server instead.[0m
 * Running on all addresses (0.0.0.0)
 * Running on http://127.0.0.1:5000
 * Running on http://192.168.31.10:5000
2025-08-01 23:42:02,643 - werkzeug - INFO - [33mPress CTRL+C to quit[0m
